package com.bafomdad.zenscape.worldgen;

import java.util.Random;

import com.bafomdad.zenscape.ZenScape;

import net.minecraft.world.World;
import net.minecraft.world.gen.feature.WorldGenerator;

public class WorldGenUnderground extends WorldGenerator {
	
	private boolean canSpawn(World world, int x, int y, int z) {
		
		if ((world.isAirBlock(x, y + 4, z + 6) && world.isAirBlock(x, y + 5, z + 6)) || (world.isAirBlock(x, y + 4, z - 6) && world.isAirBlock(x, y + 5, z - 6)))
			return true;
		return false;
	}

	public boolean generate(World world, Random rand, int x, int y, int z) {

		if (canSpawn(world, x, y, z))
		{
			world.setBlock(x, y, z, ZenScape.blockZenBricks, 12, 3); // Center block
			
			world.setBlock(x - 6, y, z - 2, ZenScape.blockZenBricks, 12, 3);
			world.setBlock(x - 6, y, z - 1, ZenScape.blockZenBricks, 12, 3);
			world.setBlock(x - 6, y, z, ZenScape.blockZenBricks, 12, 3);
			world.setBlock(x - 6, y, z + 1, ZenScape.blockZenBricks, 12, 3);
			world.setBlock(x - 6, y, z + 2, ZenScape.blockZenBricks, 12, 3);
			world.setBlock(x - 6, y + 1, z - 2, ZenScape.blockZenBricks, 12, 3);
			world.setBlock(x - 6, y + 1, z - 1, ZenScape.blockZenBricks, 12, 3);
			world.setBlock(x - 6, y + 1, z, ZenScape.blockZenBricks, 12, 3);
			world.setBlock(x - 6, y + 1, z + 1, ZenScape.blockZenBricks, 12, 3);
			world.setBlock(x - 6, y + 1, z + 2, ZenScape.blockZenBricks, 12, 3);
			world.setBlock(x - 6, y + 2, z - 2, ZenScape.blockZenBricks, 12, 3);
			world.setBlock(x - 6, y + 2, z - 1, ZenScape.blockZenBricks, 12, 3);
			world.setBlock(x - 6, y + 2, z, ZenScape.blockZenBricks, 15, 3);
			world.setBlock(x - 6, y + 2, z + 1, ZenScape.blockZenBricks, 12, 3);
			world.setBlock(x - 6, y + 2, z + 2, ZenScape.blockZenBricks, 12, 3);
			world.setBlock(x - 6, y + 3, z - 2, ZenScape.blockZenBricks, 12, 3);
			world.setBlock(x - 6, y + 3, z - 1, ZenScape.blockZenBricks, 12, 3);
			world.setBlock(x - 6, y + 3, z, ZenScape.blockZenBricks, 12, 3);
			world.setBlock(x - 6, y + 3, z + 1, ZenScape.blockZenBricks, 12, 3);
			world.setBlock(x - 6, y + 3, z + 2, ZenScape.blockZenBricks, 12, 3);
			world.setBlock(x - 5, y, z - 2, ZenScape.blockZenBricks, 12, 3);
			world.setBlock(x - 5, y, z - 1, ZenScape.blockZenBricks, 12, 3);
			world.setBlock(x - 5, y, z, ZenScape.blockZenBricks, 12, 3);
			world.setBlock(x - 5, y, z + 1, ZenScape.blockZenBricks, 12, 3);
			world.setBlock(x - 5, y, z + 2, ZenScape.blockZenBricks, 12, 3);
			world.setBlock(x - 5, y + 1, z - 2, ZenScape.blockZenBricks, 12, 3);
			world.setBlock(x - 5, y + 1, z + 2, ZenScape.blockZenBricks, 12, 3);
			world.setBlock(x - 5, y + 2, z - 2, ZenScape.blockZenBricks, 12, 3);
			world.setBlock(x - 5, y + 2, z + 2, ZenScape.blockZenBricks, 12, 3);
			world.setBlock(x - 5, y + 3, z - 2, ZenScape.blockZenBricks, 12, 3);
			world.setBlock(x - 5, y + 3, z + 2, ZenScape.blockZenBricks, 12, 3);
			world.setBlock(x - 5, y + 4, z - 1, ZenScape.blockZenBricks, 12, 3);
			world.setBlock(x - 5, y + 4, z, ZenScape.blockZenBricks, 12, 3);
			world.setBlock(x - 5, y + 4, z + 1, ZenScape.blockZenBricks, 12, 3);
			world.setBlock(x - 4, y, z - 2, ZenScape.blockZenBricks, 12, 3);
			world.setBlock(x - 4, y, z - 1, ZenScape.blockZenBricks, 12, 3);
			world.setBlock(x - 4, y, z, ZenScape.blockZenBricks, 12, 3);
			world.setBlock(x - 4, y, z + 1, ZenScape.blockZenBricks, 12, 3);
			world.setBlock(x - 4, y, z + 2, ZenScape.blockZenBricks, 12, 3);
			world.setBlock(x - 4, y + 1, z - 2, ZenScape.blockZenBricks, 12, 3);
			world.setBlock(x - 4, y + 1, z + 2, ZenScape.blockZenBricks, 12, 3);
			world.setBlock(x - 4, y + 2, z - 2, ZenScape.blockZenBricks, 12, 3);
			world.setBlock(x - 4, y + 2, z + 2, ZenScape.blockZenBricks, 12, 3);
			world.setBlock(x - 4, y + 3, z - 2, ZenScape.blockZenBricks, 12, 3);
			world.setBlock(x - 4, y + 3, z + 2, ZenScape.blockZenBricks, 12, 3);
			world.setBlock(x - 4, y + 4, z - 1, ZenScape.blockZenBricks, 12, 3);
			world.setBlock(x - 4, y + 4, z, ZenScape.blockZenBricks, 12, 3);
			world.setBlock(x - 4, y + 4, z + 1, ZenScape.blockZenBricks, 12, 3);
			world.setBlock(x - 3, y, z - 3, ZenScape.blockZenBricks, 12, 3);
			world.setBlock(x - 3, y, z - 2, ZenScape.blockZenBricks, 12, 3);
			world.setBlock(x - 3, y, z - 1, ZenScape.blockZenBricks, 12, 3);
			world.setBlock(x - 3, y, z, ZenScape.blockZenBricks, 12, 3);
			world.setBlock(x - 3, y, z + 1, ZenScape.blockZenBricks, 12, 3);
			world.setBlock(x - 3, y, z + 2, ZenScape.blockZenBricks, 12, 3);
			world.setBlock(x - 3, y, z + 3, ZenScape.blockZenBricks, 12, 3);
			world.setBlock(x - 3, y + 1, z - 3, ZenScape.blockZenBricks, 12, 3);
			world.setBlock(x - 3, y + 1, z - 2, ZenScape.double_slab, 7, 3);
			world.setBlock(x - 3, y + 1, z, ZenScape.double_slab, 7, 3);
			world.setBlock(x - 3, y + 1, z + 2, ZenScape.double_slab, 7, 3);
			world.setBlock(x - 3, y + 1, z + 3, ZenScape.blockZenBricks, 12, 3);
			world.setBlock(x - 3, y + 2, z - 3, ZenScape.blockZenBricks, 12, 3);
			world.setBlock(x - 3, y + 2, z - 2, ZenScape.double_slab, 7, 3);
			world.setBlock(x - 3, y + 2, z, ZenScape.blockZenBricks, 14, 3);
			world.setBlock(x - 3, y + 2, z + 2, ZenScape.double_slab, 7, 3);
			world.setBlock(x - 3, y + 2, z + 3, ZenScape.blockZenBricks, 12, 3);
			world.setBlock(x - 3, y + 3, z - 5, ZenScape.blockZenBricks, 12, 3);
			world.setBlock(x - 3, y + 3, z - 4, ZenScape.blockZenBricks, 12, 3);
			world.setBlock(x - 3, y + 3, z - 3, ZenScape.blockZenBricks, 12, 3);
			world.setBlock(x - 3, y + 3, z - 2, ZenScape.double_slab, 7, 3);
			world.setBlock(x - 3, y + 3, z, ZenScape.double_slab, 7, 3);
			world.setBlock(x - 3, y + 3, z + 2, ZenScape.double_slab, 7, 3);
			world.setBlock(x - 3, y + 3, z + 3, ZenScape.blockZenBricks, 12, 3);
			world.setBlock(x - 3, y + 3, z + 4, ZenScape.blockZenBricks, 12, 3);
			world.setBlock(x - 3, y + 3, z + 5, ZenScape.blockZenBricks, 12, 3);
			world.setBlock(x - 3, y + 4, z - 5, ZenScape.blockZenBricks, 12, 3);
			world.setBlock(x - 3, y + 4, z - 4, ZenScape.blockZenBricks, 12, 3);
			world.setBlock(x - 3, y + 4, z - 3, ZenScape.blockZenBricks, 12, 3);
			world.setBlock(x - 3, y + 4, z - 2, ZenScape.double_slab, 7, 3);
			world.setBlock(x - 3, y + 4, z - 1, ZenScape.blockZenBricks, 12, 3);
			world.setBlock(x - 3, y + 4, z, ZenScape.blockZenBricks, 12, 3);
			world.setBlock(x - 3, y + 4, z + 1, ZenScape.blockZenBricks, 12, 3);
			world.setBlock(x - 3, y + 4, z + 2, ZenScape.double_slab, 7, 3);
			world.setBlock(x - 3, y + 4, z + 3, ZenScape.blockZenBricks, 12, 3);
			world.setBlock(x - 3, y + 4, z + 4, ZenScape.blockZenBricks, 12, 3);
			world.setBlock(x - 3, y + 4, z + 5, ZenScape.blockZenBricks, 12, 3);
			world.setBlock(x - 3, y + 5, z - 5, ZenScape.blockZenBricks, 12, 3);
			world.setBlock(x - 3, y + 5, z - 4, ZenScape.blockZenBricks, 12, 3);
			world.setBlock(x - 3, y + 5, z - 3, ZenScape.blockZenBricks, 12, 3);
			world.setBlock(x - 3, y + 5, z - 2, ZenScape.blockZenBricks, 12, 3);
			world.setBlock(x - 3, y + 5, z - 1, ZenScape.blockZenBricks, 12, 3);
			world.setBlock(x - 3, y + 5, z, ZenScape.blockZenBricks, 12, 3);
			world.setBlock(x - 3, y + 5, z + 1, ZenScape.blockZenBricks, 12, 3);
			world.setBlock(x - 3, y + 5, z + 2, ZenScape.blockZenBricks, 12, 3);
			world.setBlock(x - 3, y + 5, z + 3, ZenScape.blockZenBricks, 12, 3);
			world.setBlock(x - 3, y + 5, z + 4, ZenScape.blockZenBricks, 12, 3);
			world.setBlock(x - 3, y + 5, z + 5, ZenScape.blockZenBricks, 12, 3);
			world.setBlock(x - 3, y + 6, z - 5, ZenScape.blockZenBricks, 12, 3);
			world.setBlock(x - 3, y + 6, z - 4, ZenScape.blockZenBricks, 12, 3);
			world.setBlock(x - 3, y + 6, z - 3, ZenScape.blockZenBricks, 12, 3);
			world.setBlock(x - 3, y + 6, z - 2, ZenScape.blockZenBricks, 12, 3);
			world.setBlock(x - 3, y + 6, z - 1, ZenScape.blockZenBricks, 12, 3);
			world.setBlock(x - 3, y + 6, z, ZenScape.blockZenBricks, 12, 3);
			world.setBlock(x - 3, y + 6, z + 1, ZenScape.blockZenBricks, 12, 3);
			world.setBlock(x - 3, y + 6, z + 2, ZenScape.blockZenBricks, 12, 3);
			world.setBlock(x - 3, y + 6, z + 3, ZenScape.blockZenBricks, 12, 3);
			world.setBlock(x - 3, y + 6, z + 4, ZenScape.blockZenBricks, 12, 3);
			world.setBlock(x - 3, y + 6, z + 5, ZenScape.blockZenBricks, 12, 3);
			world.setBlock(x - 2, y, z - 6, ZenScape.blockZenBricks, 12, 3);
			world.setBlock(x - 2, y, z - 5, ZenScape.blockZenBricks, 12, 3);
			world.setBlock(x - 2, y, z - 4, ZenScape.blockZenBricks, 12, 3);
			world.setBlock(x - 2, y, z - 3, ZenScape.blockZenBricks, 12, 3);
			world.setBlock(x - 2, y, z - 2, ZenScape.blockZenBricks, 12, 3);
			world.setBlock(x - 2, y, z - 1, ZenScape.blockZenBricks, 12, 3);
			world.setBlock(x - 2, y, z, ZenScape.blockZenBricks, 12, 3);
			world.setBlock(x - 2, y, z + 1, ZenScape.blockZenBricks, 12, 3);
			world.setBlock(x - 2, y, z + 2, ZenScape.blockZenBricks, 12, 3);
			world.setBlock(x - 2, y, z + 3, ZenScape.blockZenBricks, 12, 3);
			world.setBlock(x - 2, y, z + 4, ZenScape.blockZenBricks, 12, 3);
			world.setBlock(x - 2, y, z + 5, ZenScape.blockZenBricks, 12, 3);
			world.setBlock(x - 2, y, z + 6, ZenScape.blockZenBricks, 12, 3);
			world.setBlock(x - 2, y + 1, z - 6, ZenScape.blockZenBricks, 12, 3);
			world.setBlock(x - 2, y + 1, z - 5, ZenScape.blockZenBricks, 12, 3);
			world.setBlock(x - 2, y + 1, z - 4, ZenScape.blockZenBricks, 12, 3);
			world.setBlock(x - 2, y + 1, z - 3, ZenScape.blockZenBricks, 12, 3);
			world.setBlock(x - 2, y + 1, z - 2, ZenScape.blockBlackStairs, 3, 3);
			world.setBlock(x - 2, y + 1, z + 2, ZenScape.blockBlackStairs, 2, 3);
			world.setBlock(x - 2, y + 1, z + 3, ZenScape.blockZenBricks, 12, 3);
			world.setBlock(x - 2, y + 1, z + 4, ZenScape.blockZenBricks, 12, 3);
			world.setBlock(x - 2, y + 1, z + 5, ZenScape.blockZenBricks, 12, 3);
			world.setBlock(x - 2, y + 1, z + 6, ZenScape.blockZenBricks, 12, 3);
			world.setBlock(x - 2, y + 2, z - 6, ZenScape.blockZenBricks, 12, 3);
			world.setBlock(x - 2, y + 2, z - 5, ZenScape.blockZenBricks, 12, 3);
			world.setBlock(x - 2, y + 2, z - 4, ZenScape.blockZenBricks, 12, 3);
			world.setBlock(x - 2, y + 2, z - 3, ZenScape.blockBlackStairs, 3, 3);
			world.setBlock(x - 2, y + 2, z + 3, ZenScape.blockBlackStairs, 2, 3);
			world.setBlock(x - 2, y + 2, z + 4, ZenScape.blockZenBricks, 12, 3);
			world.setBlock(x - 2, y + 2, z + 5, ZenScape.blockZenBricks, 12, 3);
			world.setBlock(x - 2, y + 2, z + 6, ZenScape.blockZenBricks, 12, 3);
			world.setBlock(x - 2, y + 3, z - 6, ZenScape.blockZenBricks, 12, 3);
			world.setBlock(x - 2, y + 3, z - 5, ZenScape.blockZenBricks, 12, 3);
			world.setBlock(x - 2, y + 3, z - 4, ZenScape.blockBlackStairs, 3, 3);
			world.setBlock(x - 2, y + 3, z + 4, ZenScape.blockBlackStairs, 2, 3);
			world.setBlock(x - 2, y + 3, z + 5, ZenScape.blockZenBricks, 12, 3);
			world.setBlock(x - 2, y + 3, z + 6, ZenScape.blockZenBricks, 12, 3);
			world.setBlock(x - 2, y + 4, z - 6, ZenScape.blockZenBricks, 12, 3);
			world.setBlock(x - 2, y + 4, z, ZenScape.blockBlackStairs, 5, 3);
			world.setBlock(x - 2, y + 4, z + 6, ZenScape.blockZenBricks, 12, 3);
			world.setBlock(x - 2, y + 5, z - 6, ZenScape.blockZenBricks, 12, 3);
			world.setBlock(x - 2, y + 5, z - 2, ZenScape.blockBlackStairs, 5, 3);
			world.setBlock(x - 2, y + 5, z, ZenScape.blockZenBricks, 12, 3);
			world.setBlock(x - 2, y + 5, z + 2, ZenScape.blockBlackStairs, 5, 3);
			world.setBlock(x - 2, y + 5, z + 6, ZenScape.blockZenBricks, 12, 3);
			world.setBlock(x - 2, y + 6, z - 6, ZenScape.blockZenBricks, 12, 3);
			world.setBlock(x - 2, y + 6, z - 2, ZenScape.blockZenBricks, 12, 3);
			world.setBlock(x - 2, y + 6, z, ZenScape.blockZenBricks, 12, 3);
			world.setBlock(x - 2, y + 6, z + 2, ZenScape.blockZenBricks, 12, 3);
			world.setBlock(x - 2, y + 6, z + 6, ZenScape.blockZenBricks, 12, 3);
			world.setBlock(x - 2, y + 7, z - 5, ZenScape.blockZenBricks, 12, 3);
			world.setBlock(x - 2, y + 7, z - 4, ZenScape.blockZenBricks, 12, 3);
			world.setBlock(x - 2, y + 7, z - 3, ZenScape.blockZenBricks, 12, 3);
			world.setBlock(x - 2, y + 7, z - 2, ZenScape.blockZenBricks, 12, 3);
			world.setBlock(x - 2, y + 7, z - 1, ZenScape.blockZenBricks, 12, 3);
			world.setBlock(x - 2, y + 7, z, ZenScape.blockZenBricks, 12, 3);
			world.setBlock(x - 2, y + 7, z + 1, ZenScape.blockZenBricks, 12, 3);
			world.setBlock(x - 2, y + 7, z + 2, ZenScape.blockZenBricks, 12, 3);
			world.setBlock(x - 2, y + 7, z + 3, ZenScape.blockZenBricks, 12, 3);
			world.setBlock(x - 2, y + 7, z + 4, ZenScape.blockZenBricks, 12, 3);
			world.setBlock(x - 2, y + 7, z + 5, ZenScape.blockZenBricks, 12, 3);
			world.setBlock(x - 1, y, z - 6, ZenScape.blockZenBricks, 12, 3);
			world.setBlock(x - 1, y, z - 5, ZenScape.blockZenBricks, 12, 3);
			world.setBlock(x - 1, y, z - 4, ZenScape.blockZenBricks, 12, 3);
			world.setBlock(x - 1, y, z - 3, ZenScape.blockZenBricks, 12, 3);
			world.setBlock(x - 1, y, z - 2, ZenScape.blockZenBricks, 12, 3);
			world.setBlock(x - 1, y, z - 1, ZenScape.blockZenBricks, 12, 3);
			world.setBlock(x - 1, y, z, ZenScape.blockZenBricks, 12, 3);
			world.setBlock(x - 1, y, z + 1, ZenScape.blockZenBricks, 12, 3);
			world.setBlock(x - 1, y, z + 2, ZenScape.blockZenBricks, 12, 3);
			world.setBlock(x - 1, y, z + 3, ZenScape.blockZenBricks, 12, 3);
			world.setBlock(x - 1, y, z + 4, ZenScape.blockZenBricks, 12, 3);
			world.setBlock(x - 1, y, z + 5, ZenScape.blockZenBricks, 12, 3);
			world.setBlock(x - 1, y, z + 6, ZenScape.blockZenBricks, 12, 3);
			world.setBlock(x - 1, y + 1, z - 6, ZenScape.blockZenBricks, 12, 3);
			world.setBlock(x - 1, y + 1, z + 6, ZenScape.blockZenBricks, 12, 3);
			world.setBlock(x - 1, y + 2, z - 6, ZenScape.blockZenBricks, 12, 3);
			world.setBlock(x - 1, y + 2, z + 6, ZenScape.blockZenBricks, 12, 3);
			world.setBlock(x - 1, y + 3, z - 6, ZenScape.blockZenBricks, 12, 3);
			world.setBlock(x - 1, y + 3, z - 5, ZenScape.blockBlackStairs, 7, 3);
			world.setBlock(x - 1, y + 3, z + 5, ZenScape.blockBlackStairs, 6, 3);
			world.setBlock(x - 1, y + 3, z + 6, ZenScape.blockZenBricks, 12, 3);
			world.setBlock(x - 1, y + 4, z - 6, ZenScape.blockZenBricks, 12, 3);
			world.setBlock(x - 1, y + 4, z + 6, ZenScape.blockZenBricks, 12, 3);
			world.setBlock(x - 1, y + 5, z - 6, ZenScape.blockZenBricks, 12, 3);
			world.setBlock(x - 1, y + 5, z, ZenScape.blockBlackStairs, 5, 3);
			world.setBlock(x - 1, y + 5, z + 6, ZenScape.blockZenBricks, 12, 3);
			world.setBlock(x - 1, y + 6, z - 6, ZenScape.blockZenBricks, 12, 3);
			world.setBlock(x - 1, y + 6, z - 2, ZenScape.blockBlackStairs, 5, 3);
			world.setBlock(x - 1, y + 6, z, ZenScape.blockZenBricks, 12, 3);
			world.setBlock(x - 1, y + 6, z + 2, ZenScape.blockBlackStairs, 5, 3);
			world.setBlock(x - 1, y + 6, z + 6, ZenScape.blockZenBricks, 12, 3);
			world.setBlock(x - 1, y + 7, z - 5, ZenScape.blockZenBricks, 12, 3);
			world.setBlock(x - 1, y + 7, z - 4, ZenScape.blockZenBricks, 12, 3);
			world.setBlock(x - 1, y + 7, z - 3, ZenScape.blockZenBricks, 12, 3);
			world.setBlock(x - 1, y + 7, z - 2, ZenScape.blockZenBricks, 12, 3);
			world.setBlock(x - 1, y + 7, z - 1, ZenScape.blockZenBricks, 12, 3);
			world.setBlock(x - 1, y + 7, z, ZenScape.blockZenBricks, 12, 3);
			world.setBlock(x - 1, y + 7, z + 1, ZenScape.blockZenBricks, 12, 3);
			world.setBlock(x - 1, y + 7, z + 2, ZenScape.blockZenBricks, 12, 3);
			world.setBlock(x - 1, y + 7, z + 3, ZenScape.blockZenBricks, 12, 3);
			world.setBlock(x - 1, y + 7, z + 4, ZenScape.blockZenBricks, 12, 3);
			world.setBlock(x - 1, y + 7, z + 5, ZenScape.blockZenBricks, 12, 3);
			world.setBlock(x, y, z - 6, ZenScape.blockZenBricks, 12, 3);
			world.setBlock(x, y, z - 5, ZenScape.blockZenBricks, 12, 3);
			world.setBlock(x, y, z - 4, ZenScape.blockZenBricks, 12, 3);
			world.setBlock(x, y, z - 3, ZenScape.blockZenBricks, 12, 3);
			world.setBlock(x, y, z - 2, ZenScape.blockZenBricks, 12, 3);
			world.setBlock(x, y, z - 1, ZenScape.blockZenBricks, 12, 3);
			world.setBlock(x, y, z + 1, ZenScape.blockZenBricks, 12, 3);
			world.setBlock(x, y, z + 2, ZenScape.blockZenBricks, 12, 3);
			world.setBlock(x, y, z + 3, ZenScape.blockZenBricks, 12, 3);
			world.setBlock(x, y, z + 4, ZenScape.blockZenBricks, 12, 3);
			world.setBlock(x, y, z + 5, ZenScape.blockZenBricks, 12, 3);
			world.setBlock(x, y, z + 6, ZenScape.blockZenBricks, 12, 3);
			world.setBlock(x, y + 1, z - 6, ZenScape.blockZenBricks, 12, 3);
			world.setBlock(x, y + 1, z - 3, ZenScape.double_slab, 7, 3);
			world.setBlock(x, y + 1, z + 3, ZenScape.double_slab, 7, 3);
			world.setBlock(x, y + 1, z + 6, ZenScape.blockZenBricks, 12, 3);
			world.setBlock(x, y + 2, z - 6, ZenScape.blockZenBricks, 15, 3);
			world.setBlock(x, y + 2, z - 3, ZenScape.blockZenBricks, 14, 3);
			world.setBlock(x, y + 2, z + 3, ZenScape.blockZenBricks, 14, 3);
			world.setBlock(x, y + 2, z + 6, ZenScape.blockZenBricks, 15, 3);
			world.setBlock(x, y + 3, z - 6, ZenScape.blockZenBricks, 12, 3);
			world.setBlock(x, y + 3, z - 5, ZenScape.blockBlackStairs, 7, 3);
			world.setBlock(x, y + 3, z - 3, ZenScape.double_slab, 7, 3);
			world.setBlock(x, y + 3, z + 3, ZenScape.double_slab, 7, 3);
			world.setBlock(x, y + 3, z + 5, ZenScape.blockBlackStairs, 6, 3);
			world.setBlock(x, y + 3, z + 6, ZenScape.blockZenBricks, 12, 3);
			world.setBlock(x, y + 4, z - 3, ZenScape.double_slab, 7, 3);
			world.setBlock(x, y + 4, z + 3, ZenScape.double_slab, 7, 3);
			world.setBlock(x, y + 5, z - 3, ZenScape.blockZenBricks, 14, 3);
			world.setBlock(x, y + 5, z + 3, ZenScape.blockZenBricks, 14, 3);
			world.setBlock(x, y + 6, z - 6, ZenScape.blockZenBricks, 12, 3);
			world.setBlock(x, y + 6, z - 3, ZenScape.double_slab, 7, 3);
			world.setBlock(x, y + 6, z, ZenScape.blockZenBricks, 12, 3);
			world.setBlock(x, y + 6, z + 3, ZenScape.double_slab, 7, 3);
			world.setBlock(x, y + 6, z + 6, ZenScape.blockZenBricks, 12, 3);
			world.setBlock(x, y + 7, z - 5, ZenScape.blockZenBricks, 12, 3);
			world.setBlock(x, y + 7, z - 4, ZenScape.blockZenBricks, 12, 3);
			world.setBlock(x, y + 7, z - 3, ZenScape.blockZenBricks, 12, 3);
			world.setBlock(x, y + 7, z - 2, ZenScape.blockZenBricks, 12, 3);
			world.setBlock(x, y + 7, z - 1, ZenScape.blockZenBricks, 12, 3);
			world.setBlock(x, y + 7, z, ZenScape.blockZenBricks, 12, 3);
			world.setBlock(x, y + 7, z + 1, ZenScape.blockZenBricks, 12, 3);
			world.setBlock(x, y + 7, z + 2, ZenScape.blockZenBricks, 12, 3);
			world.setBlock(x, y + 7, z + 3, ZenScape.blockZenBricks, 12, 3);
			world.setBlock(x, y + 7, z + 4, ZenScape.blockZenBricks, 12, 3);
			world.setBlock(x, y + 7, z + 5, ZenScape.blockZenBricks, 12, 3);
			world.setBlock(x + 1, y, z - 6, ZenScape.blockZenBricks, 12, 3);
			world.setBlock(x + 1, y, z - 5, ZenScape.blockZenBricks, 12, 3);
			world.setBlock(x + 1, y, z - 4, ZenScape.blockZenBricks, 12, 3);
			world.setBlock(x + 1, y, z - 3, ZenScape.blockZenBricks, 12, 3);
			world.setBlock(x + 1, y, z - 2, ZenScape.blockZenBricks, 12, 3);
			world.setBlock(x + 1, y, z - 1, ZenScape.blockZenBricks, 12, 3);
			world.setBlock(x + 1, y, z, ZenScape.blockZenBricks, 12, 3);
			world.setBlock(x + 1, y, z + 1, ZenScape.blockZenBricks, 12, 3);
			world.setBlock(x + 1, y, z + 2, ZenScape.blockZenBricks, 12, 3);
			world.setBlock(x + 1, y, z + 3, ZenScape.blockZenBricks, 12, 3);
			world.setBlock(x + 1, y, z + 4, ZenScape.blockZenBricks, 12, 3);
			world.setBlock(x + 1, y, z + 5, ZenScape.blockZenBricks, 12, 3);
			world.setBlock(x + 1, y, z + 6, ZenScape.blockZenBricks, 12, 3);
			world.setBlock(x + 1, y + 1, z - 6, ZenScape.blockZenBricks, 12, 3);
			world.setBlock(x + 1, y + 1, z + 6, ZenScape.blockZenBricks, 12, 3);
			world.setBlock(x + 1, y + 2, z - 6, ZenScape.blockZenBricks, 12, 3);
			world.setBlock(x + 1, y + 2, z + 6, ZenScape.blockZenBricks, 12, 3);
			world.setBlock(x + 1, y + 3, z - 6, ZenScape.blockZenBricks, 12, 3);
			world.setBlock(x + 1, y + 3, z - 5, ZenScape.blockBlackStairs, 7, 3);
			world.setBlock(x + 1, y + 3, z + 5, ZenScape.blockBlackStairs, 6, 3);
			world.setBlock(x + 1, y + 3, z + 6, ZenScape.blockZenBricks, 12, 3);
			world.setBlock(x + 1, y + 4, z - 6, ZenScape.blockZenBricks, 12, 3);
			world.setBlock(x + 1, y + 4, z + 6, ZenScape.blockZenBricks, 12, 3);
			world.setBlock(x + 1, y + 5, z - 6, ZenScape.blockZenBricks, 12, 3);
			world.setBlock(x + 1, y + 5, z, ZenScape.blockBlackStairs, 4, 3);
			world.setBlock(x + 1, y + 5, z + 6, ZenScape.blockZenBricks, 12, 3);
			world.setBlock(x + 1, y + 6, z - 6, ZenScape.blockZenBricks, 12, 3);
			world.setBlock(x + 1, y + 6, z - 2, ZenScape.blockBlackStairs, 4, 3);
			world.setBlock(x + 1, y + 6, z, ZenScape.blockZenBricks, 12, 3);
			world.setBlock(x + 1, y + 6, z + 2, ZenScape.blockBlackStairs, 4, 3);
			world.setBlock(x + 1, y + 6, z + 6, ZenScape.blockZenBricks, 12, 3);
			world.setBlock(x + 1, y + 7, z - 5, ZenScape.blockZenBricks, 12, 3);
			world.setBlock(x + 1, y + 7, z - 4, ZenScape.blockZenBricks, 12, 3);
			world.setBlock(x + 1, y + 7, z - 3, ZenScape.blockZenBricks, 12, 3);
			world.setBlock(x + 1, y + 7, z - 2, ZenScape.blockZenBricks, 12, 3);
			world.setBlock(x + 1, y + 7, z - 1, ZenScape.blockZenBricks, 12, 3);
			world.setBlock(x + 1, y + 7, z, ZenScape.blockZenBricks, 12, 3);
			world.setBlock(x + 1, y + 7, z + 1, ZenScape.blockZenBricks, 12, 3);
			world.setBlock(x + 1, y + 7, z + 2, ZenScape.blockZenBricks, 12, 3);
			world.setBlock(x + 1, y + 7, z + 3, ZenScape.blockZenBricks, 12, 3);
			world.setBlock(x + 1, y + 7, z + 4, ZenScape.blockZenBricks, 12, 3);
			world.setBlock(x + 1, y + 7, z + 5, ZenScape.blockZenBricks, 12, 3);
			world.setBlock(x + 2, y, z - 6, ZenScape.blockZenBricks, 12, 3);
			world.setBlock(x + 2, y, z - 5, ZenScape.blockZenBricks, 12, 3);
			world.setBlock(x + 2, y, z - 4, ZenScape.blockZenBricks, 12, 3);
			world.setBlock(x + 2, y, z - 3, ZenScape.blockZenBricks, 12, 3);
			world.setBlock(x + 2, y, z - 2, ZenScape.blockZenBricks, 12, 3);
			world.setBlock(x + 2, y, z - 1, ZenScape.blockZenBricks, 12, 3);
			world.setBlock(x + 2, y, z, ZenScape.blockZenBricks, 12, 3);
			world.setBlock(x + 2, y, z + 1, ZenScape.blockZenBricks, 12, 3);
			world.setBlock(x + 2, y, z + 2, ZenScape.blockZenBricks, 12, 3);
			world.setBlock(x + 2, y, z + 3, ZenScape.blockZenBricks, 12, 3);
			world.setBlock(x + 2, y, z + 4, ZenScape.blockZenBricks, 12, 3);
			world.setBlock(x + 2, y, z + 5, ZenScape.blockZenBricks, 12, 3);
			world.setBlock(x + 2, y, z + 6, ZenScape.blockZenBricks, 12, 3);
			world.setBlock(x + 2, y + 1, z - 6, ZenScape.blockZenBricks, 12, 3);
			world.setBlock(x + 2, y + 1, z - 5, ZenScape.blockZenBricks, 12, 3);
			world.setBlock(x + 2, y + 1, z - 4, ZenScape.blockZenBricks, 12, 3);
			world.setBlock(x + 2, y + 1, z - 3, ZenScape.blockZenBricks, 12, 3);
			world.setBlock(x + 2, y + 1, z - 2, ZenScape.blockBlackStairs, 3, 3);
			world.setBlock(x + 2, y + 1, z + 2, ZenScape.blockBlackStairs, 2, 3);
			world.setBlock(x + 2, y + 1, z + 3, ZenScape.blockZenBricks, 12, 3);
			world.setBlock(x + 2, y + 1, z + 4, ZenScape.blockZenBricks, 12, 3);
			world.setBlock(x + 2, y + 1, z + 5, ZenScape.blockZenBricks, 12, 3);
			world.setBlock(x + 2, y + 1, z + 6, ZenScape.blockZenBricks, 12, 3);
			world.setBlock(x + 2, y + 2, z - 6, ZenScape.blockZenBricks, 12, 3);
			world.setBlock(x + 2, y + 2, z - 5, ZenScape.blockZenBricks, 12, 3);
			world.setBlock(x + 2, y + 2, z - 4, ZenScape.blockZenBricks, 12, 3);
			world.setBlock(x + 2, y + 2, z - 3, ZenScape.blockBlackStairs, 3, 3);
			world.setBlock(x + 2, y + 2, z + 3, ZenScape.blockBlackStairs, 2, 3);
			world.setBlock(x + 2, y + 2, z + 4, ZenScape.blockZenBricks, 12, 3);
			world.setBlock(x + 2, y + 2, z + 5, ZenScape.blockZenBricks, 12, 3);
			world.setBlock(x + 2, y + 2, z + 6, ZenScape.blockZenBricks, 12, 3);
			world.setBlock(x + 2, y + 3, z - 6, ZenScape.blockZenBricks, 12, 3);
			world.setBlock(x + 2, y + 3, z - 5, ZenScape.blockZenBricks, 12, 3);
			world.setBlock(x + 2, y + 3, z - 4, ZenScape.blockBlackStairs, 3, 3);
			world.setBlock(x + 2, y + 3, z + 4, ZenScape.blockBlackStairs, 2, 3);
			world.setBlock(x + 2, y + 3, z + 5, ZenScape.blockZenBricks, 12, 3);
			world.setBlock(x + 2, y + 3, z + 6, ZenScape.blockZenBricks, 12, 3);
			world.setBlock(x + 2, y + 4, z - 6, ZenScape.blockZenBricks, 12, 3);
			world.setBlock(x + 2, y + 4, z, ZenScape.blockBlackStairs, 4, 3);
			world.setBlock(x + 2, y + 4, z + 6, ZenScape.blockZenBricks, 12, 3);
			world.setBlock(x + 2, y + 5, z - 6, ZenScape.blockZenBricks, 12, 3);
			world.setBlock(x + 2, y + 5, z - 2, ZenScape.blockBlackStairs, 4, 3);
			world.setBlock(x + 2, y + 5, z, ZenScape.blockZenBricks, 12, 3);
			world.setBlock(x + 2, y + 5, z + 2, ZenScape.blockBlackStairs, 4, 3);
			world.setBlock(x + 2, y + 5, z + 6, ZenScape.blockZenBricks, 12, 3);
			world.setBlock(x + 2, y + 6, z - 6, ZenScape.blockZenBricks, 12, 3);
			world.setBlock(x + 2, y + 6, z - 2, ZenScape.blockZenBricks, 12, 3);
			world.setBlock(x + 2, y + 6, z, ZenScape.blockZenBricks, 12, 3);
			world.setBlock(x + 2, y + 6, z + 2, ZenScape.blockZenBricks, 12, 3);
			world.setBlock(x + 2, y + 6, z + 6, ZenScape.blockZenBricks, 12, 3);
			world.setBlock(x + 2, y + 7, z - 5, ZenScape.blockZenBricks, 12, 3);
			world.setBlock(x + 2, y + 7, z - 4, ZenScape.blockZenBricks, 12, 3);
			world.setBlock(x + 2, y + 7, z - 3, ZenScape.blockZenBricks, 12, 3);
			world.setBlock(x + 2, y + 7, z - 2, ZenScape.blockZenBricks, 12, 3);
			world.setBlock(x + 2, y + 7, z - 1, ZenScape.blockZenBricks, 12, 3);
			world.setBlock(x + 2, y + 7, z, ZenScape.blockZenBricks, 12, 3);
			world.setBlock(x + 2, y + 7, z + 1, ZenScape.blockZenBricks, 12, 3);
			world.setBlock(x + 2, y + 7, z + 2, ZenScape.blockZenBricks, 12, 3);
			world.setBlock(x + 2, y + 7, z + 3, ZenScape.blockZenBricks, 12, 3);
			world.setBlock(x + 2, y + 7, z + 4, ZenScape.blockZenBricks, 12, 3);
			world.setBlock(x + 2, y + 7, z + 5, ZenScape.blockZenBricks, 12, 3);
			world.setBlock(x + 3, y, z - 3, ZenScape.blockZenBricks, 12, 3);
			world.setBlock(x + 3, y, z - 2, ZenScape.blockZenBricks, 12, 3);
			world.setBlock(x + 3, y, z - 1, ZenScape.blockZenBricks, 12, 3);
			world.setBlock(x + 3, y, z, ZenScape.blockZenBricks, 12, 3);
			world.setBlock(x + 3, y, z + 1, ZenScape.blockZenBricks, 12, 3);
			world.setBlock(x + 3, y, z + 2, ZenScape.blockZenBricks, 12, 3);
			world.setBlock(x + 3, y, z + 3, ZenScape.blockZenBricks, 12, 3);
			world.setBlock(x + 3, y + 1, z - 3, ZenScape.blockZenBricks, 12, 3);
			world.setBlock(x + 3, y + 1, z - 2, ZenScape.double_slab, 7, 3);
			world.setBlock(x + 3, y + 1, z, ZenScape.double_slab, 7, 3);
			world.setBlock(x + 3, y + 1, z + 2, ZenScape.double_slab, 7, 3);
			world.setBlock(x + 3, y + 1, z + 3, ZenScape.blockZenBricks, 12, 3);
			world.setBlock(x + 3, y + 2, z - 3, ZenScape.blockZenBricks, 12, 3);
			world.setBlock(x + 3, y + 2, z - 2, ZenScape.double_slab, 7, 3);
			world.setBlock(x + 3, y + 2, z, ZenScape.blockZenBricks, 14, 3);
			world.setBlock(x + 3, y + 2, z + 2, ZenScape.double_slab, 7, 3);
			world.setBlock(x + 3, y + 2, z + 3, ZenScape.blockZenBricks, 12, 3);
			world.setBlock(x + 3, y + 3, z - 5, ZenScape.blockZenBricks, 12, 3);
			world.setBlock(x + 3, y + 3, z - 4, ZenScape.blockZenBricks, 12, 3);
			world.setBlock(x + 3, y + 3, z - 3, ZenScape.blockZenBricks, 12, 3);
			world.setBlock(x + 3, y + 3, z - 2, ZenScape.double_slab, 7, 3);
			world.setBlock(x + 3, y + 3, z, ZenScape.double_slab, 7, 3);
			world.setBlock(x + 3, y + 3, z + 2, ZenScape.double_slab, 7, 3);
			world.setBlock(x + 3, y + 3, z + 3, ZenScape.blockZenBricks, 12, 3);
			world.setBlock(x + 3, y + 3, z + 4, ZenScape.blockZenBricks, 12, 3);
			world.setBlock(x + 3, y + 3, z + 5, ZenScape.blockZenBricks, 12, 3);
			world.setBlock(x + 3, y + 4, z - 5, ZenScape.blockZenBricks, 12, 3);
			world.setBlock(x + 3, y + 4, z - 4, ZenScape.blockZenBricks, 12, 3);
			world.setBlock(x + 3, y + 4, z - 3, ZenScape.blockZenBricks, 12, 3);
			world.setBlock(x + 3, y + 4, z - 2, ZenScape.double_slab, 7, 3);
			world.setBlock(x + 3, y + 4, z - 1, ZenScape.blockZenBricks, 12, 3);
			world.setBlock(x + 3, y + 4, z, ZenScape.blockZenBricks, 12, 3);
			world.setBlock(x + 3, y + 4, z + 1, ZenScape.blockZenBricks, 12, 3);
			world.setBlock(x + 3, y + 4, z + 2, ZenScape.double_slab, 7, 3);
			world.setBlock(x + 3, y + 4, z + 3, ZenScape.blockZenBricks, 12, 3);
			world.setBlock(x + 3, y + 4, z + 4, ZenScape.blockZenBricks, 12, 3);
			world.setBlock(x + 3, y + 4, z + 5, ZenScape.blockZenBricks, 12, 3);
			world.setBlock(x + 3, y + 5, z - 5, ZenScape.blockZenBricks, 12, 3);
			world.setBlock(x + 3, y + 5, z - 4, ZenScape.blockZenBricks, 12, 3);
			world.setBlock(x + 3, y + 5, z - 3, ZenScape.blockZenBricks, 12, 3);
			world.setBlock(x + 3, y + 5, z - 2, ZenScape.blockZenBricks, 12, 3);
			world.setBlock(x + 3, y + 5, z - 1, ZenScape.blockZenBricks, 12, 3);
			world.setBlock(x + 3, y + 5, z, ZenScape.blockZenBricks, 12, 3);
			world.setBlock(x + 3, y + 5, z + 1, ZenScape.blockZenBricks, 12, 3);
			world.setBlock(x + 3, y + 5, z + 2, ZenScape.blockZenBricks, 12, 3);
			world.setBlock(x + 3, y + 5, z + 3, ZenScape.blockZenBricks, 12, 3);
			world.setBlock(x + 3, y + 5, z + 4, ZenScape.blockZenBricks, 12, 3);
			world.setBlock(x + 3, y + 5, z + 5, ZenScape.blockZenBricks, 12, 3);
			world.setBlock(x + 3, y + 6, z - 5, ZenScape.blockZenBricks, 12, 3);
			world.setBlock(x + 3, y + 6, z - 4, ZenScape.blockZenBricks, 12, 3);
			world.setBlock(x + 3, y + 6, z - 3, ZenScape.blockZenBricks, 12, 3);
			world.setBlock(x + 3, y + 6, z - 2, ZenScape.blockZenBricks, 12, 3);
			world.setBlock(x + 3, y + 6, z - 1, ZenScape.blockZenBricks, 12, 3);
			world.setBlock(x + 3, y + 6, z, ZenScape.blockZenBricks, 12, 3);
			world.setBlock(x + 3, y + 6, z + 1, ZenScape.blockZenBricks, 12, 3);
			world.setBlock(x + 3, y + 6, z + 2, ZenScape.blockZenBricks, 12, 3);
			world.setBlock(x + 3, y + 6, z + 3, ZenScape.blockZenBricks, 12, 3);
			world.setBlock(x + 3, y + 6, z + 4, ZenScape.blockZenBricks, 12, 3);
			world.setBlock(x + 3, y + 6, z + 5, ZenScape.blockZenBricks, 12, 3);
			world.setBlock(x + 4, y, z - 2, ZenScape.blockZenBricks, 12, 3);
			world.setBlock(x + 4, y, z - 1, ZenScape.blockZenBricks, 12, 3);
			world.setBlock(x + 4, y, z, ZenScape.blockZenBricks, 12, 3);
			world.setBlock(x + 4, y, z + 1, ZenScape.blockZenBricks, 12, 3);
			world.setBlock(x + 4, y, z + 2, ZenScape.blockZenBricks, 12, 3);
			world.setBlock(x + 4, y + 1, z - 2, ZenScape.blockZenBricks, 12, 3);
			world.setBlock(x + 4, y + 1, z + 2, ZenScape.blockZenBricks, 12, 3);
			world.setBlock(x + 4, y + 2, z - 2, ZenScape.blockZenBricks, 12, 3);
			world.setBlock(x + 4, y + 2, z + 2, ZenScape.blockZenBricks, 12, 3);
			world.setBlock(x + 4, y + 3, z - 2, ZenScape.blockZenBricks, 12, 3);
			world.setBlock(x + 4, y + 3, z + 2, ZenScape.blockZenBricks, 12, 3);
			world.setBlock(x + 4, y + 4, z - 1, ZenScape.blockZenBricks, 12, 3);
			world.setBlock(x + 4, y + 4, z, ZenScape.blockZenBricks, 12, 3);
			world.setBlock(x + 4, y + 4, z + 1, ZenScape.blockZenBricks, 12, 3);
			world.setBlock(x + 5, y, z - 2, ZenScape.blockZenBricks, 12, 3);
			world.setBlock(x + 5, y, z - 1, ZenScape.blockZenBricks, 12, 3);
			world.setBlock(x + 5, y, z, ZenScape.blockZenBricks, 12, 3);
			world.setBlock(x + 5, y, z + 1, ZenScape.blockZenBricks, 12, 3);
			world.setBlock(x + 5, y, z + 2, ZenScape.blockZenBricks, 12, 3);
			world.setBlock(x + 5, y + 1, z - 2, ZenScape.blockZenBricks, 12, 3);
			world.setBlock(x + 5, y + 1, z + 2, ZenScape.blockZenBricks, 12, 3);
			world.setBlock(x + 5, y + 2, z - 2, ZenScape.blockZenBricks, 12, 3);
			world.setBlock(x + 5, y + 2, z + 2, ZenScape.blockZenBricks, 12, 3);
			world.setBlock(x + 5, y + 3, z - 2, ZenScape.blockZenBricks, 12, 3);
			world.setBlock(x + 5, y + 3, z + 2, ZenScape.blockZenBricks, 12, 3);
			world.setBlock(x + 5, y + 4, z - 1, ZenScape.blockZenBricks, 12, 3);
			world.setBlock(x + 5, y + 4, z, ZenScape.blockZenBricks, 12, 3);
			world.setBlock(x + 5, y + 4, z + 1, ZenScape.blockZenBricks, 12, 3);
			world.setBlock(x + 6, y, z - 2, ZenScape.blockZenBricks, 12, 3);
			world.setBlock(x + 6, y, z - 1, ZenScape.blockZenBricks, 12, 3);
			world.setBlock(x + 6, y, z, ZenScape.blockZenBricks, 12, 3);
			world.setBlock(x + 6, y, z + 1, ZenScape.blockZenBricks, 12, 3);
			world.setBlock(x + 6, y, z + 2, ZenScape.blockZenBricks, 12, 3);
			world.setBlock(x + 6, y + 1, z - 2, ZenScape.blockZenBricks, 12, 3);
			world.setBlock(x + 6, y + 1, z - 1, ZenScape.blockZenBricks, 12, 3);
			world.setBlock(x + 6, y + 1, z, ZenScape.blockZenBricks, 12, 3);
			world.setBlock(x + 6, y + 1, z + 1, ZenScape.blockZenBricks, 12, 3);
			world.setBlock(x + 6, y + 1, z + 2, ZenScape.blockZenBricks, 12, 3);
			world.setBlock(x + 6, y + 2, z - 2, ZenScape.blockZenBricks, 12, 3);
			world.setBlock(x + 6, y + 2, z - 1, ZenScape.blockZenBricks, 12, 3);
			world.setBlock(x + 6, y + 2, z, ZenScape.blockZenBricks, 15, 3);
			world.setBlock(x + 6, y + 2, z + 1, ZenScape.blockZenBricks, 12, 3);
			world.setBlock(x + 6, y + 2, z + 2, ZenScape.blockZenBricks, 12, 3);
			world.setBlock(x + 6, y + 3, z - 2, ZenScape.blockZenBricks, 12, 3);
			world.setBlock(x + 6, y + 3, z - 1, ZenScape.blockZenBricks, 12, 3);
			world.setBlock(x + 6, y + 3, z, ZenScape.blockZenBricks, 12, 3);
			world.setBlock(x + 6, y + 3, z + 1, ZenScape.blockZenBricks, 12, 3);
			world.setBlock(x + 6, y + 3, z + 2, ZenScape.blockZenBricks, 12, 3);

			return true;
		}
		return false;
	}
}
