package com.bafomdad.zenscape.worldgen;

import java.util.Random;

import com.bafomdad.zenscape.ZenScape;

import net.minecraft.block.Block;
import net.minecraft.init.Blocks;
import net.minecraft.world.World;
import net.minecraft.world.gen.feature.WorldGenerator;

public class WorldGenSmallIsland extends WorldGenerator {
	
	Block soil = ZenScape.blockZenDirtGrass;

	@Override
	public boolean generate(World world, Random rand, int x, int y, int z) {

		world.setBlock(x, y, z, Blocks.wool, 6, 2);
		world.setBlock(x, y, z + 1, soil, 0, 2);
		world.setBlock(x, y, z - 1, soil, 0, 2);
		world.setBlock(x, y, z - 1, soil, 0, 2);
		world.setBlock(x, y, z + 1, soil, 0, 2);
		world.setBlock(x, y, z - 1, soil, 0, 2);
		world.setBlock(x, y, z + 1, soil, 0, 2);
		world.setBlock(x, y, z + 1, soil, 0, 2);
		world.setBlock(x, y, z - 1, soil, 0, 2);
		world.setBlock(x, y, z + 2, soil, 1, 2);
		world.setBlock(x, y, z + 2, soil, 1, 2);
		world.setBlock(x, y, z + 2, soil, 1, 2);
		world.setBlock(x, y, z + 2, soil, 1, 2);
		world.setBlock(x, y, z + 3, soil, 1, 2);
		world.setBlock(x, y, z + 3, soil, 1, 2);
		world.setBlock(x, y, z + 3, soil, 1, 2);
		world.setBlock(x, y, z + 3, soil, 1, 2);
		world.setBlock(x, y - 1, z, soil, 1, 2);
		world.setBlock(x, y - 1, z, soil, 1, 2);
		world.setBlock(x, y - 1, z, soil, 1, 2);
		world.setBlock(x, y - 1, z, soil, 1, 2);
		world.setBlock(x, y - 1, z - 1, soil, 1, 2);
		world.setBlock(x, y - 1, z - 1, soil, 1, 2);
		world.setBlock(x, y - 1, z + 1, soil, 1, 2);
		world.setBlock(x, y - 1, z + 1, soil, 1, 2);
		world.setBlock(x, y + 1, z + 2, soil, 0, 2);
		world.setBlock(x, y - 1, z + 2, soil, 1, 2);
		world.setBlock(x, y + 1, z + 2, soil, 0, 2);
		world.setBlock(x, y - 1, z + 2, soil, 1, 2);
		world.setBlock(x, y + 1, z + 3, soil, 0, 2);
		world.setBlock(x, y - 1, z + 3, soil, 1, 2);
		world.setBlock(x, y + 1, z + 3, soil, 0, 2);
		world.setBlock(x, y - 1, z + 3, soil, 1, 2);
		world.setBlock(x, y + 1, z + 4, soil, 0, 2);
		world.setBlock(x, y + 1, z + 4, soil, 0, 2);
		world.setBlock(x, y - 2, z, soil, 1, 2);
		world.setBlock(x, y - 2, z, soil, 1, 2);
		world.setBlock(x, y - 2, z, soil, 1, 2);
		world.setBlock(x, y - 2, z, soil, 1, 2);
		world.setBlock(x, y - 2, z + 1, soil, 1, 2);
		world.setBlock(x, y - 2, z + 1, soil, 1, 2);
		world.setBlock(x, y - 2, z + 2, soil, 1, 2);
		world.setBlock(x, y - 2, z + 2, soil, 1, 2);
		world.setBlock(x + 1, y, z, soil, 0, 2);
		world.setBlock(x - 1, y, z, soil, 0, 2);
		world.setBlock(x + 1, y, z, soil, 0, 2);
		world.setBlock(x - 1, y, z, soil, 0, 2);
		world.setBlock(x + 1, y, z, soil, 0, 2);
		world.setBlock(x - 1, y, z, soil, 0, 2);
		world.setBlock(x + 1, y, z, soil, 0, 2);
		world.setBlock(x - 1, y, z, soil, 0, 2);
		world.setBlock(x + 1, y, z + 1, soil, 0, 2);
		world.setBlock(x - 1, y, z - 1, soil, 0, 2);
		world.setBlock(x + 1, y, z - 1, soil, 0, 2);
		world.setBlock(x - 1, y, z + 1, soil, 0, 2);
		world.setBlock(x + 1, y, z - 1, soil, 0, 2);
		world.setBlock(x - 1, y, z + 1, soil, 0, 2);
		world.setBlock(x + 1, y, z + 1, soil, 0, 2);
		world.setBlock(x - 1, y, z - 1, soil, 0, 2);
		world.setBlock(x + 1, y, z + 2, soil, 1, 2);
		world.setBlock(x - 1, y, z - 2, soil, 0, 2);
		world.setBlock(x + 1, y, z + 2, soil, 1, 2);
		world.setBlock(x - 1, y, z - 2, soil, 0, 2);
		world.setBlock(x + 1, y, z + 3, soil, 1, 2);
		world.setBlock(x + 1, y, z + 3, soil, 1, 2);
		world.setBlock(x + 1, y, z + 4, soil, 1, 2);
		world.setBlock(x + 1, y, z + 4, soil, 1, 2);
		world.setBlock(x - 1, y - 1, z, soil, 1, 2);
		world.setBlock(x + 1, y - 1, z, soil, 1, 2);
		world.setBlock(x - 1, y - 1, z, soil, 1, 2);
		world.setBlock(x + 1, y - 1, z, soil, 1, 2);
		world.setBlock(x - 1, y - 1, z - 1, soil, 1, 2);
		world.setBlock(x - 1, y - 1, z + 1, soil, 1, 2);
		world.setBlock(x + 1, y - 1, z + 1, soil, 1, 2);
		world.setBlock(x + 1, y + 1, z + 2, soil, 0, 2);
		world.setBlock(x - 1, y - 1, z + 2, soil, 0, 2);
		world.setBlock(x + 1, y - 1, z + 2, soil, 1, 2);
		world.setBlock(x + 1, y + 1, z + 3, soil, 0, 2);
		world.setBlock(x + 1, y - 1, z + 3, soil, 1, 2);
		world.setBlock(x + 1, y + 1, z + 4, soil, 0, 2);
		world.setBlock(x - 1, y - 2, z, soil, 1, 2);
		world.setBlock(x + 1, y - 2, z, soil, 1, 2);
		world.setBlock(x - 1, y - 2, z, soil, 1, 2);
		world.setBlock(x + 1, y - 2, z, soil, 1, 2);
		world.setBlock(x - 1, y - 2, z - 1, soil, 1, 2);
		world.setBlock(x - 1, y - 2, z + 1, soil, 1, 2);
		world.setBlock(x + 1, y - 2, z + 1, soil, 1, 2);
		world.setBlock(x - 1, y - 2, z + 2, soil, 1, 2);
		world.setBlock(x + 1, y - 2, z + 2, soil, 1, 2);
		world.setBlock(x - 1, y - 3, z, soil, 1, 2);
		world.setBlock(x - 1, y - 3, z, soil, 1, 2);
		world.setBlock(x - 1, y - 3, z - 1, soil, 1, 2);
		world.setBlock(x + 1, y - 3, z + 1, soil, 1, 2);
		world.setBlock(x + 1, y - 3, z + 2, soil, 1, 2);
		world.setBlock(x - 2, y, z, soil, 0, 2);
		world.setBlock(x - 2, y, z, soil, 0, 2);
		world.setBlock(x - 2, y, z, soil, 0, 2);
		world.setBlock(x - 2, y, z, soil, 0, 2);
		world.setBlock(x + 2, y, z + 1, soil, 1, 2);
		world.setBlock(x - 2, y, z - 1, soil, 0, 2);
		world.setBlock(x - 2, y, z + 1, soil, 0, 2);
		world.setBlock(x - 2, y, z + 1, soil, 0, 2);
		world.setBlock(x + 2, y, z + 1, soil, 1, 2);
		world.setBlock(x - 2, y, z - 1, soil, 0, 2);
		world.setBlock(x + 2, y, z + 2, soil, 1, 2);
		world.setBlock(x - 2, y, z - 2, soil, 0, 2);
		world.setBlock(x + 2, y, z + 2, soil, 1, 2);
		world.setBlock(x - 2, y, z - 2, soil, 0, 2);
		world.setBlock(x + 2, y, z + 3, soil, 1, 2);
		world.setBlock(x + 2, y, z + 3, soil, 1, 2);
		world.setBlock(x + 2, y, z + 4, soil, 1, 2);
		world.setBlock(x + 2, y, z + 4, soil, 1, 2);
		world.setBlock(x - 2, y - 1, z, soil, 1, 2);
		world.setBlock(x - 2, y - 1, z, soil, 1, 2);
		world.setBlock(x + 2, y + 1, z + 1, soil, 0, 2);
		world.setBlock(x - 2, y - 1, z - 1, soil, 1, 2);
		world.setBlock(x - 2, y - 1, z + 1, soil, 1, 2);
		world.setBlock(x + 2, y - 1, z + 1, soil, 1, 2);
		world.setBlock(x + 2, y + 1, z + 2, soil, 0, 2);
		world.setBlock(x - 2, y - 1, z - 2, soil, 1, 2);
		world.setBlock(x + 2, y - 1, z + 2, soil, 1, 2);
		world.setBlock(x + 2, y + 1, z + 3, soil, 0, 2);
		world.setBlock(x + 2, y - 1, z + 3, soil, 1, 2);
		world.setBlock(x + 2, y + 1, z + 4, soil, 0, 2);
		world.setBlock(x - 2, y - 2, z, soil, 1, 2);
		world.setBlock(x - 2, y - 2, z, soil, 1, 2);
		world.setBlock(x - 2, y - 2, z - 1, soil, 1, 2);
		world.setBlock(x + 2, y - 2, z + 1, soil, 1, 2);
		world.setBlock(x - 2, y - 2, z - 2, soil, 1, 2);
		world.setBlock(x + 2, y - 2, z + 2, soil, 1, 2);
		world.setBlock(x - 2, y - 3, z, soil, 1, 2);
		world.setBlock(x - 2, y - 3, z, soil, 1, 2);
		world.setBlock(x - 2, y - 3, z - 1, soil, 1, 2);
		world.setBlock(x + 2, y - 3, z + 1, soil, 1, 2);
		world.setBlock(x + 2, y - 3, z + 2, soil, 1, 2);
		world.setBlock(x - 3, y, z, soil, 0, 2);
		world.setBlock(x - 3, y, z, soil, 0, 2);
		world.setBlock(x - 3, y, z, soil, 0, 2);
		world.setBlock(x - 3, y, z, soil, 0, 2);
		world.setBlock(x + 3, y, z + 1, soil, 1, 2);
		world.setBlock(x - 3, y, z - 1, soil, 0, 2);
		world.setBlock(x + 3, y, z + 1, soil, 1, 2);
		world.setBlock(x - 3, y, z - 1, soil, 0, 2);
		world.setBlock(x + 3, y, z + 2, soil, 1, 2);
		world.setBlock(x + 3, y, z + 2, soil, 1, 2);
		world.setBlock(x + 3, y, z + 3, soil, 1, 2);
		world.setBlock(x + 3, y, z + 3, soil, 1, 2);
		world.setBlock(x - 3, y - 1, z, soil, 1, 2);
		world.setBlock(x - 3, y - 1, z, soil, 1, 2);
		world.setBlock(x + 3, y + 1, z + 1, soil, 0, 2);
		world.setBlock(x - 3, y - 1, z - 1, soil, 1, 2);
		world.setBlock(x + 3, y + 1, z + 2, soil, 0, 2);
		world.setBlock(x - 3, y - 1, z - 2, soil, 0, 2);
		world.setBlock(x + 3, y + 1, z + 3, soil, 0, 2);
		world.setBlock(x - 3, y - 2, z - 1, soil, 1, 2);
		world.setBlock(x - 3, y - 2, z - 2, soil, 1, 2);

		return true;
	}
}
