package com.bafomdad.zenscape.worldgen;

import java.util.Random;

import net.minecraft.block.Block;
import net.minecraft.init.Blocks;
import net.minecraft.world.World;
import net.minecraft.world.gen.feature.WorldGenerator;

import com.bafomdad.zenscape.ZenScape;
import com.bafomdad.zenscape.worldgen.trees.WorldGenFlyWood;

public class WorldGenLargeIsland extends WorldGenerator {
	
	Block soil = ZenScape.blockZenDirtGrass;
	WorldGenSkyStruc struc = new WorldGenSkyStruc();
	WorldGenFlyWood trees = new WorldGenFlyWood(true);
	int size;
	
	public WorldGenLargeIsland(int size) {
		
		this.size = size;
	}
	
	@Override
	public boolean generate(World world, Random rand, int x, int y, int z) {
	
		world.setBlock(x, y, z, Blocks.wool, 10, 3);
		world.setBlock(x, y, z + 1, soil, 0, 2);
		world.setBlock(x, y, z - 1, soil, 0, 2);
		world.setBlock(x, y, z - 1, soil, 0, 2);
		world.setBlock(x, y, z + 1, soil, 0, 2);
		world.setBlock(x, y, z - 1, soil, 0, 2);
		world.setBlock(x, y, z + 1, soil, 0, 2);
		world.setBlock(x, y, z + 1, soil, 0, 2);
		world.setBlock(x, y, z - 1, soil, 0, 2);
		world.setBlock(x, y, z + 2, soil, 0, 2);
		world.setBlock(x, y, z - 2, soil, 0, 2);
		world.setBlock(x, y, z - 2, soil, 0, 2);
		world.setBlock(x, y, z + 2, soil, 0, 2);
		world.setBlock(x, y, z - 2, soil, 0, 2);
		world.setBlock(x, y, z + 2, soil, 0, 2);
		world.setBlock(x, y, z + 2, soil, 0, 2);
		world.setBlock(x, y, z - 2, soil, 0, 2);
		world.setBlock(x, y, z + 3, soil, 0, 2);
		world.setBlock(x, y, z - 3, soil, 0, 2);
		world.setBlock(x, y, z - 3, soil, 0, 2);
		world.setBlock(x, y, z + 3, soil, 0, 2);
		world.setBlock(x, y, z - 3, soil, 0, 2);
		world.setBlock(x, y, z + 3, soil, 0, 2);
		world.setBlock(x, y, z + 3, soil, 0, 2);
		world.setBlock(x, y, z - 3, soil, 0, 2);
		world.setBlock(x, y, z + 4, soil, 0, 2);
		world.setBlock(x, y, z - 4, soil, 0, 2);
		world.setBlock(x, y, z - 4, soil, 0, 2);
		world.setBlock(x, y, z + 4, soil, 0, 2);
		world.setBlock(x, y, z - 4, soil, 0, 2);
		world.setBlock(x, y, z + 4, soil, 0, 2);
		world.setBlock(x, y, z + 4, soil, 0, 2);
		world.setBlock(x, y, z - 4, soil, 0, 2);
		world.setBlock(x, y, z + 5, soil, 0, 2);
		world.setBlock(x, y, z - 5, soil, 0, 2);
		world.setBlock(x, y, z - 5, soil, 0, 2);
		world.setBlock(x, y, z + 5, soil, 0, 2);
		world.setBlock(x, y, z - 5, soil, 0, 2);
		world.setBlock(x, y, z + 5, soil, 0, 2);
		world.setBlock(x, y, z + 5, soil, 0, 2);
		world.setBlock(x, y, z - 5, soil, 0, 2);
		world.setBlock(x, y, z + 6, soil, 0, 2);
		world.setBlock(x, y, z - 6, soil, 0, 2);
		world.setBlock(x, y, z - 6, soil, 0, 2);
		world.setBlock(x, y, z + 6, soil, 0, 2);
		world.setBlock(x, y, z - 6, soil, 0, 2);
		world.setBlock(x, y, z + 6, soil, 0, 2);
		world.setBlock(x, y, z + 6, soil, 0, 2);
		world.setBlock(x, y, z - 6, soil, 0, 2);
		world.setBlock(x, y, z + 7, soil, 0, 2);
		world.setBlock(x, y, z - 7, soil, 0, 2);
		world.setBlock(x, y, z - 7, soil, 0, 2);
		world.setBlock(x, y, z + 7, soil, 0, 2);
		world.setBlock(x, y, z - 7, soil, 0, 2);
		world.setBlock(x, y, z + 7, soil, 0, 2);
		world.setBlock(x, y, z + 7, soil, 0, 2);
		world.setBlock(x, y, z - 7, soil, 0, 2);
		world.setBlock(x, y, z + 8, soil, 0, 2);
		world.setBlock(x, y, z - 8, soil, 0, 2);
		world.setBlock(x, y, z - 8, soil, 0, 2);
		world.setBlock(x, y, z + 8, soil, 0, 2);
		world.setBlock(x, y, z - 8, soil, 0, 2);
		world.setBlock(x, y, z + 8, soil, 0, 2);
		world.setBlock(x, y, z + 8, soil, 0, 2);
		world.setBlock(x, y, z - 8, soil, 0, 2);
		world.setBlock(x, y - 1, z, soil, 1, 2);
		world.setBlock(x, y - 1, z, soil, 1, 2);
		world.setBlock(x, y - 1, z, soil, 1, 2);
		world.setBlock(x, y - 1, z, soil, 1, 2);
		world.setBlock(x, y - 1, z - 1, soil, 1, 2);
		world.setBlock(x, y - 1, z - 1, soil, 1, 2);
		world.setBlock(x, y - 1, z + 1, soil, 1, 2);
		world.setBlock(x, y - 1, z + 1, soil, 1, 2);
		world.setBlock(x, y - 1, z - 2, soil, 1, 2);
		world.setBlock(x, y - 1, z - 2, soil, 1, 2);
		world.setBlock(x, y - 1, z + 2, soil, 1, 2);
		world.setBlock(x, y - 1, z + 2, soil, 1, 2);
		world.setBlock(x, y - 1, z - 3, soil, 1, 2);
		world.setBlock(x, y - 1, z - 3, soil, 1, 2);
		world.setBlock(x, y - 1, z + 3, soil, 1, 2);
		world.setBlock(x, y - 1, z + 3, soil, 1, 2);
		world.setBlock(x, y - 1, z - 4, soil, 1, 2);
		world.setBlock(x, y - 1, z - 4, soil, 1, 2);
		world.setBlock(x, y - 1, z + 4, soil, 1, 2);
		world.setBlock(x, y - 1, z + 4, soil, 1, 2);
		world.setBlock(x, y - 1, z - 5, soil, 1, 2);
		world.setBlock(x, y - 1, z - 5, soil, 1, 2);
		world.setBlock(x, y - 1, z + 5, soil, 1, 2);
		world.setBlock(x, y - 1, z + 5, soil, 1, 2);
		world.setBlock(x, y - 1, z - 6, soil, 1, 2);
		world.setBlock(x, y - 1, z - 6, soil, 1, 2);
		world.setBlock(x, y - 1, z + 6, soil, 1, 2);
		world.setBlock(x, y - 1, z + 6, soil, 1, 2);
		world.setBlock(x, y - 1, z - 7, soil, 1, 2);
		world.setBlock(x, y - 1, z - 7, soil, 1, 2);
		world.setBlock(x, y - 1, z + 7, soil, 1, 2);
		world.setBlock(x, y - 1, z + 7, soil, 1, 2);
		world.setBlock(x, y - 1, z - 8, soil, 1, 2);
		world.setBlock(x, y - 1, z - 8, soil, 1, 2);
		world.setBlock(x, y - 1, z + 8, soil, 1, 2);
		world.setBlock(x, y - 1, z + 8, soil, 1, 2);
		world.setBlock(x, y - 1, z - 9, soil, 0, 2);
		world.setBlock(x, y - 1, z - 9, soil, 0, 2);
		world.setBlock(x, y - 1, z + 9, soil, 0, 2);
		world.setBlock(x, y - 1, z + 9, soil, 0, 2);
		world.setBlock(x, y - 1, z + 10, soil, 0, 2);
		world.setBlock(x, y - 1, z + 10, soil, 0, 2);
		world.setBlock(x, y - 2, z, soil, 1, 2);
		world.setBlock(x, y - 2, z, soil, 1, 2);
		world.setBlock(x, y - 2, z, soil, 1, 2);
		world.setBlock(x, y - 2, z, soil, 1, 2);
		world.setBlock(x, y - 2, z - 1, soil, 1, 2);
		world.setBlock(x, y - 2, z - 1, soil, 1, 2);
		world.setBlock(x, y - 2, z + 1, soil, 1, 2);
		world.setBlock(x, y - 2, z + 1, soil, 1, 2);
		world.setBlock(x, y - 2, z - 2, soil, 1, 2);
		world.setBlock(x, y - 2, z - 2, soil, 1, 2);
		world.setBlock(x, y - 2, z + 2, soil, 1, 2);
		world.setBlock(x, y - 2, z + 2, soil, 1, 2);
		world.setBlock(x, y - 2, z - 3, soil, 1, 2);
		world.setBlock(x, y - 2, z - 3, soil, 1, 2);
		world.setBlock(x, y - 2, z + 3, soil, 1, 2);
		world.setBlock(x, y - 2, z + 3, soil, 1, 2);
		world.setBlock(x, y - 2, z - 4, soil, 1, 2);
		world.setBlock(x, y - 2, z - 4, soil, 1, 2);
		world.setBlock(x, y - 2, z + 4, soil, 1, 2);
		world.setBlock(x, y - 2, z + 4, soil, 1, 2);
		world.setBlock(x, y - 2, z - 5, soil, 1, 2);
		world.setBlock(x, y - 2, z - 5, soil, 1, 2);
		world.setBlock(x, y - 2, z + 5, soil, 1, 2);
		world.setBlock(x, y - 2, z + 5, soil, 1, 2);
		world.setBlock(x, y - 2, z - 6, soil, 1, 2);
		world.setBlock(x, y - 2, z - 6, soil, 1, 2);
		world.setBlock(x, y - 2, z + 6, soil, 1, 2);
		world.setBlock(x, y - 2, z + 6, soil, 1, 2);
		world.setBlock(x, y - 2, z - 7, soil, 1, 2);
		world.setBlock(x, y - 2, z - 7, soil, 1, 2);
		world.setBlock(x, y - 2, z + 7, soil, 1, 2);
		world.setBlock(x, y - 2, z + 7, soil, 1, 2);
		world.setBlock(x, y - 2, z - 8, soil, 1, 2);
		world.setBlock(x, y - 2, z - 8, soil, 1, 2);
		world.setBlock(x, y - 2, z + 8, soil, 1, 2);
		world.setBlock(x, y - 2, z + 8, soil, 1, 2);
		world.setBlock(x, y - 2, z - 9, soil, 1, 2);
		world.setBlock(x, y - 2, z - 9, soil, 1, 2);
		world.setBlock(x, y - 2, z + 9, soil, 1, 2);
		world.setBlock(x, y - 2, z + 9, soil, 1, 2);
		world.setBlock(x, y - 3, z, soil, 1, 2);
		world.setBlock(x, y - 3, z, soil, 1, 2);
		world.setBlock(x, y - 3, z, soil, 1, 2);
		world.setBlock(x, y - 3, z, soil, 1, 2);
		world.setBlock(x, y - 3, z - 1, soil, 1, 2);
		world.setBlock(x, y - 3, z - 1, soil, 1, 2);
		world.setBlock(x, y - 3, z + 1, soil, 1, 2);
		world.setBlock(x, y - 3, z + 1, soil, 1, 2);
		world.setBlock(x, y - 3, z - 2, soil, 1, 2);
		world.setBlock(x, y - 3, z - 2, soil, 1, 2);
		world.setBlock(x, y - 3, z + 2, soil, 1, 2);
		world.setBlock(x, y - 3, z + 2, soil, 1, 2);
		world.setBlock(x, y - 3, z - 3, soil, 1, 2);
		world.setBlock(x, y - 3, z - 3, soil, 1, 2);
		world.setBlock(x, y - 3, z + 3, soil, 1, 2);
		world.setBlock(x, y - 3, z + 3, soil, 1, 2);
		world.setBlock(x, y - 3, z - 4, soil, 1, 2);
		world.setBlock(x, y - 3, z - 4, soil, 1, 2);
		world.setBlock(x, y - 3, z + 4, soil, 1, 2);
		world.setBlock(x, y - 3, z + 4, soil, 1, 2);
		world.setBlock(x, y - 3, z - 5, soil, 1, 2);
		world.setBlock(x, y - 3, z - 5, soil, 1, 2);
		world.setBlock(x, y - 3, z + 5, soil, 1, 2);
		world.setBlock(x, y - 3, z + 5, soil, 1, 2);
		world.setBlock(x, y - 3, z - 6, soil, 1, 2);
		world.setBlock(x, y - 3, z - 6, soil, 1, 2);
		world.setBlock(x, y - 3, z + 6, soil, 1, 2);
		world.setBlock(x, y - 3, z + 6, soil, 1, 2);
		world.setBlock(x, y - 3, z - 7, soil, 1, 2);
		world.setBlock(x, y - 3, z - 7, soil, 1, 2);
		world.setBlock(x, y - 4, z, soil, 1, 2);
		world.setBlock(x, y - 4, z, soil, 1, 2);
		world.setBlock(x, y - 4, z, soil, 1, 2);
		world.setBlock(x, y - 4, z, soil, 1, 2);
		world.setBlock(x, y - 4, z - 1, soil, 1, 2);
		world.setBlock(x, y - 4, z - 1, soil, 1, 2);
		world.setBlock(x, y - 4, z + 1, soil, 1, 2);
		world.setBlock(x, y - 4, z + 1, soil, 1, 2);
		world.setBlock(x, y - 4, z - 2, soil, 1, 2);
		world.setBlock(x, y - 4, z - 2, soil, 1, 2);
		world.setBlock(x, y - 4, z + 2, soil, 1, 2);
		world.setBlock(x, y - 4, z + 2, soil, 1, 2);
		world.setBlock(x, y - 4, z - 3, soil, 1, 2);
		world.setBlock(x, y - 4, z - 3, soil, 1, 2);
		world.setBlock(x, y - 4, z + 3, soil, 1, 2);
		world.setBlock(x, y - 4, z + 3, soil, 1, 2);
		world.setBlock(x, y - 4, z - 4, soil, 1, 2);
		world.setBlock(x, y - 4, z - 4, soil, 1, 2);
		world.setBlock(x, y - 4, z + 4, soil, 1, 2);
		world.setBlock(x, y - 4, z + 4, soil, 1, 2);
		world.setBlock(x, y - 4, z - 5, soil, 1, 2);
		world.setBlock(x, y - 4, z - 5, soil, 1, 2);
		world.setBlock(x, y - 4, z + 5, soil, 1, 2);
		world.setBlock(x, y - 4, z + 5, soil, 1, 2);
		world.setBlock(x, y - 4, z - 6, soil, 1, 2);
		world.setBlock(x, y - 4, z - 6, soil, 1, 2);
		world.setBlock(x, y - 4, z + 6, soil, 1, 2);
		world.setBlock(x, y - 4, z + 6, soil, 1, 2);
		world.setBlock(x, y - 5, z, soil, 1, 2);
		world.setBlock(x, y - 5, z, soil, 1, 2);
		world.setBlock(x, y - 5, z, soil, 1, 2);
		world.setBlock(x, y - 5, z, soil, 1, 2);
		world.setBlock(x, y - 5, z - 1, soil, 1, 2);
		world.setBlock(x, y - 5, z - 1, soil, 1, 2);
		world.setBlock(x, y - 5, z + 1, soil, 1, 2);
		world.setBlock(x, y - 5, z + 1, soil, 1, 2);
		world.setBlock(x, y - 5, z - 2, soil, 1, 2);
		world.setBlock(x, y - 5, z - 2, soil, 1, 2);
		world.setBlock(x, y - 5, z + 2, soil, 1, 2);
		world.setBlock(x, y - 5, z + 2, soil, 1, 2);
		world.setBlock(x, y - 5, z - 3, soil, 1, 2);
		world.setBlock(x, y - 5, z - 3, soil, 1, 2);
		world.setBlock(x, y - 5, z + 3, soil, 1, 2);
		world.setBlock(x, y - 5, z + 3, soil, 1, 2);
		world.setBlock(x, y - 5, z - 4, soil, 1, 2);
		world.setBlock(x, y - 5, z - 4, soil, 1, 2);
		world.setBlock(x, y - 5, z + 4, soil, 1, 2);
		world.setBlock(x, y - 5, z + 4, soil, 1, 2);
		world.setBlock(x, y - 5, z + 5, soil, 1, 2);
		world.setBlock(x, y - 5, z + 5, soil, 1, 2);
		world.setBlock(x, y - 5, z + 6, soil, 1, 2);
		world.setBlock(x, y - 5, z + 6, soil, 1, 2);
		world.setBlock(x, y - 6, z, soil, 1, 2);
		world.setBlock(x, y - 6, z, soil, 1, 2);
		world.setBlock(x, y - 6, z, soil, 1, 2);
		world.setBlock(x, y - 6, z, soil, 1, 2);
		world.setBlock(x, y - 6, z - 1, soil, 1, 2);
		world.setBlock(x, y - 6, z - 1, soil, 1, 2);
		world.setBlock(x, y - 6, z + 1, soil, 1, 2);
		world.setBlock(x, y - 6, z + 1, soil, 1, 2);
		world.setBlock(x, y - 6, z - 2, soil, 1, 2);
		world.setBlock(x, y - 6, z - 2, soil, 1, 2);
		world.setBlock(x, y - 6, z + 2, soil, 1, 2);
		world.setBlock(x, y - 6, z + 2, soil, 1, 2);
		world.setBlock(x, y - 6, z + 3, soil, 1, 2);
		world.setBlock(x, y - 6, z + 3, soil, 1, 2);
		world.setBlock(x, y - 7, z, soil, 1, 2);
		world.setBlock(x, y - 7, z, soil, 1, 2);
		world.setBlock(x, y - 7, z, soil, 1, 2);
		world.setBlock(x, y - 7, z, soil, 1, 2);
		world.setBlock(x, y - 7, z - 1, soil, 1, 2);
		world.setBlock(x, y - 7, z - 1, soil, 1, 2);
		world.setBlock(x, y - 7, z + 1, soil, 1, 2);
		world.setBlock(x, y - 7, z + 1, soil, 1, 2);
		world.setBlock(x, y - 7, z + 2, soil, 1, 2);
		world.setBlock(x, y - 7, z + 2, soil, 1, 2);
		world.setBlock(x, y - 7, z + 3, soil, 1, 2);
		world.setBlock(x, y - 7, z + 3, soil, 1, 2);
		world.setBlock(x, y - 8, z, soil, 1, 2);
		world.setBlock(x, y - 8, z, soil, 1, 2);
		world.setBlock(x, y - 8, z, soil, 1, 2);
		world.setBlock(x, y - 8, z, soil, 1, 2);
		world.setBlock(x, y - 8, z - 1, soil, 1, 2);
		world.setBlock(x, y - 8, z - 1, soil, 1, 2);
		world.setBlock(x + 1, y, z, soil, 0, 2);
		world.setBlock(x - 1, y, z, soil, 0, 2);
		world.setBlock(x + 1, y, z, soil, 0, 2);
		world.setBlock(x - 1, y, z, soil, 0, 2);
		world.setBlock(x + 1, y, z, soil, 0, 2);
		world.setBlock(x - 1, y, z, soil, 0, 2);
		world.setBlock(x + 1, y, z, soil, 0, 2);
		world.setBlock(x - 1, y, z, soil, 0, 2);
		world.setBlock(x + 1, y, z + 1, soil, 0, 2);
		world.setBlock(x - 1, y, z - 1, soil, 0, 2);
		world.setBlock(x + 1, y, z - 1, soil, 0, 2);
		world.setBlock(x - 1, y, z + 1, soil, 0, 2);
		world.setBlock(x + 1, y, z - 1, soil, 0, 2);
		world.setBlock(x - 1, y, z + 1, soil, 0, 2);
		world.setBlock(x + 1, y, z + 1, soil, 0, 2);
		world.setBlock(x - 1, y, z - 1, soil, 0, 2);
		world.setBlock(x + 1, y, z + 2, soil, 0, 2);
		world.setBlock(x - 1, y, z - 2, soil, 0, 2);
		world.setBlock(x + 1, y, z - 2, soil, 0, 2);
		world.setBlock(x - 1, y, z + 2, soil, 0, 2);
		world.setBlock(x + 1, y, z - 2, soil, 0, 2);
		world.setBlock(x - 1, y, z + 2, soil, 0, 2);
		world.setBlock(x + 1, y, z + 2, soil, 0, 2);
		world.setBlock(x - 1, y, z - 2, soil, 0, 2);
		world.setBlock(x + 1, y, z + 3, soil, 0, 2);
		world.setBlock(x - 1, y, z - 3, soil, 0, 2);
		world.setBlock(x + 1, y, z - 3, soil, 0, 2);
		world.setBlock(x - 1, y, z + 3, soil, 0, 2);
		world.setBlock(x + 1, y, z - 3, soil, 0, 2);
		world.setBlock(x - 1, y, z + 3, soil, 0, 2);
		world.setBlock(x + 1, y, z + 3, soil, 0, 2);
		world.setBlock(x - 1, y, z - 3, soil, 0, 2);
		world.setBlock(x + 1, y, z + 4, soil, 0, 2);
		world.setBlock(x - 1, y, z - 4, soil, 0, 2);
		world.setBlock(x + 1, y, z - 4, soil, 0, 2);
		world.setBlock(x - 1, y, z + 4, soil, 0, 2);
		world.setBlock(x + 1, y, z - 4, soil, 0, 2);
		world.setBlock(x - 1, y, z + 4, soil, 0, 2);
		world.setBlock(x + 1, y, z + 4, soil, 0, 2);
		world.setBlock(x - 1, y, z - 4, soil, 0, 2);
		world.setBlock(x + 1, y, z + 5, soil, 0, 2);
		world.setBlock(x - 1, y, z - 5, soil, 0, 2);
		world.setBlock(x + 1, y, z - 5, soil, 0, 2);
		world.setBlock(x - 1, y, z + 5, soil, 0, 2);
		world.setBlock(x + 1, y, z - 5, soil, 0, 2);
		world.setBlock(x - 1, y, z + 5, soil, 0, 2);
		world.setBlock(x + 1, y, z + 5, soil, 0, 2);
		world.setBlock(x - 1, y, z - 5, soil, 0, 2);
		world.setBlock(x + 1, y, z + 6, soil, 0, 2);
		world.setBlock(x - 1, y, z - 6, soil, 0, 2);
		world.setBlock(x + 1, y, z - 6, soil, 0, 2);
		world.setBlock(x - 1, y, z + 6, soil, 0, 2);
		world.setBlock(x + 1, y, z - 6, soil, 0, 2);
		world.setBlock(x - 1, y, z + 6, soil, 0, 2);
		world.setBlock(x + 1, y, z + 6, soil, 0, 2);
		world.setBlock(x - 1, y, z - 6, soil, 0, 2);
		world.setBlock(x + 1, y, z + 7, soil, 0, 2);
		world.setBlock(x - 1, y, z - 7, soil, 0, 2);
		world.setBlock(x + 1, y, z - 7, soil, 0, 2);
		world.setBlock(x - 1, y, z + 7, soil, 0, 2);
		world.setBlock(x + 1, y, z - 7, soil, 0, 2);
		world.setBlock(x - 1, y, z + 7, soil, 0, 2);
		world.setBlock(x + 1, y, z + 7, soil, 0, 2);
		world.setBlock(x - 1, y, z - 7, soil, 0, 2);
		world.setBlock(x + 1, y, z + 8, soil, 0, 2);
		world.setBlock(x - 1, y, z - 8, soil, 0, 2);
		world.setBlock(x + 1, y, z - 8, soil, 0, 2);
		world.setBlock(x - 1, y, z + 8, soil, 0, 2);
		world.setBlock(x + 1, y, z - 8, soil, 0, 2);
		world.setBlock(x - 1, y, z + 8, soil, 0, 2);
		world.setBlock(x + 1, y, z + 8, soil, 0, 2);
		world.setBlock(x - 1, y, z - 8, soil, 0, 2);
		world.setBlock(x - 1, y - 1, z, soil, 1, 2);
		world.setBlock(x + 1, y - 1, z, soil, 1, 2);
		world.setBlock(x - 1, y - 1, z, soil, 1, 2);
		world.setBlock(x + 1, y - 1, z, soil, 1, 2);
		world.setBlock(x - 1, y - 1, z - 1, soil, 1, 2);
		world.setBlock(x + 1, y - 1, z - 1, soil, 1, 2);
		world.setBlock(x - 1, y - 1, z + 1, soil, 1, 2);
		world.setBlock(x + 1, y - 1, z + 1, soil, 1, 2);
		world.setBlock(x - 1, y - 1, z - 2, soil, 1, 2);
		world.setBlock(x + 1, y - 1, z - 2, soil, 1, 2);
		world.setBlock(x - 1, y - 1, z + 2, soil, 1, 2);
		world.setBlock(x + 1, y - 1, z + 2, soil, 1, 2);
		world.setBlock(x - 1, y - 1, z - 3, soil, 1, 2);
		world.setBlock(x + 1, y - 1, z - 3, soil, 1, 2);
		world.setBlock(x - 1, y - 1, z + 3, soil, 1, 2);
		world.setBlock(x + 1, y - 1, z + 3, soil, 1, 2);
		world.setBlock(x - 1, y - 1, z - 4, soil, 1, 2);
		world.setBlock(x + 1, y - 1, z - 4, soil, 1, 2);
		world.setBlock(x - 1, y - 1, z + 4, soil, 1, 2);
		world.setBlock(x + 1, y - 1, z + 4, soil, 1, 2);
		world.setBlock(x - 1, y - 1, z - 5, soil, 1, 2);
		world.setBlock(x + 1, y - 1, z - 5, soil, 1, 2);
		world.setBlock(x - 1, y - 1, z + 5, soil, 1, 2);
		world.setBlock(x + 1, y - 1, z + 5, soil, 1, 2);
		world.setBlock(x - 1, y - 1, z - 6, soil, 1, 2);
		world.setBlock(x + 1, y - 1, z - 6, soil, 1, 2);
		world.setBlock(x - 1, y - 1, z + 6, soil, 1, 2);
		world.setBlock(x + 1, y - 1, z + 6, soil, 1, 2);
		world.setBlock(x - 1, y - 1, z - 7, soil, 1, 2);
		world.setBlock(x + 1, y - 1, z - 7, soil, 1, 2);
		world.setBlock(x - 1, y - 1, z + 7, soil, 1, 2);
		world.setBlock(x + 1, y - 1, z + 7, soil, 1, 2);
		world.setBlock(x - 1, y - 1, z - 8, soil, 1, 2);
		world.setBlock(x + 1, y - 1, z - 8, soil, 1, 2);
		world.setBlock(x - 1, y - 1, z + 8, soil, 1, 2);
		world.setBlock(x + 1, y - 1, z + 8, soil, 1, 2);
		world.setBlock(x - 1, y - 1, z - 9, soil, 0, 2);
		world.setBlock(x - 1, y - 1, z + 9, soil, 0, 2);
		world.setBlock(x - 1, y - 1, z + 10, soil, 0, 2);
		world.setBlock(x - 1, y - 2, z, soil, 1, 2);
		world.setBlock(x + 1, y - 2, z, soil, 1, 2);
		world.setBlock(x - 1, y - 2, z, soil, 1, 2);
		world.setBlock(x + 1, y - 2, z, soil, 1, 2);
		world.setBlock(x - 1, y - 2, z - 1, soil, 1, 2);
		world.setBlock(x + 1, y - 2, z - 1, soil, 1, 2);
		world.setBlock(x - 1, y - 2, z + 1, soil, 1, 2);
		world.setBlock(x + 1, y - 2, z + 1, soil, 1, 2);
		world.setBlock(x - 1, y - 2, z - 2, soil, 1, 2);
		world.setBlock(x + 1, y - 2, z - 2, soil, 1, 2);
		world.setBlock(x - 1, y - 2, z + 2, soil, 1, 2);
		world.setBlock(x + 1, y - 2, z + 2, soil, 1, 2);
		world.setBlock(x - 1, y - 2, z - 3, soil, 1, 2);
		world.setBlock(x + 1, y - 2, z - 3, soil, 1, 2);
		world.setBlock(x - 1, y - 2, z + 3, soil, 1, 2);
		world.setBlock(x + 1, y - 2, z + 3, soil, 1, 2);
		world.setBlock(x - 1, y - 2, z - 4, soil, 1, 2);
		world.setBlock(x + 1, y - 2, z - 4, soil, 1, 2);
		world.setBlock(x - 1, y - 2, z + 4, soil, 1, 2);
		world.setBlock(x + 1, y - 2, z + 4, soil, 1, 2);
		world.setBlock(x - 1, y - 2, z - 5, soil, 1, 2);
		world.setBlock(x + 1, y - 2, z - 5, soil, 1, 2);
		world.setBlock(x - 1, y - 2, z + 5, soil, 1, 2);
		world.setBlock(x + 1, y - 2, z + 5, soil, 1, 2);
		world.setBlock(x - 1, y - 2, z - 6, soil, 1, 2);
		world.setBlock(x + 1, y - 2, z - 6, soil, 1, 2);
		world.setBlock(x - 1, y - 2, z + 6, soil, 1, 2);
		world.setBlock(x + 1, y - 2, z + 6, soil, 1, 2);
		world.setBlock(x - 1, y - 2, z - 7, soil, 1, 2);
		world.setBlock(x + 1, y - 2, z - 7, soil, 1, 2);
		world.setBlock(x - 1, y - 2, z + 7, soil, 1, 2);
		world.setBlock(x + 1, y - 2, z + 7, soil, 1, 2);
		world.setBlock(x - 1, y - 2, z - 8, soil, 1, 2);
		world.setBlock(x - 1, y - 2, z + 8, soil, 1, 2);
		world.setBlock(x - 1, y - 2, z - 9, soil, 1, 2);
		world.setBlock(x - 1, y - 2, z + 9, soil, 1, 2);
		world.setBlock(x - 1, y - 2, z + 10, soil, 1, 2);
		world.setBlock(x - 1, y - 3, z, soil, 1, 2);
		world.setBlock(x + 1, y - 3, z, soil, 1, 2);
		world.setBlock(x - 1, y - 3, z, soil, 1, 2);
		world.setBlock(x + 1, y - 3, z, soil, 1, 2);
		world.setBlock(x - 1, y - 3, z - 1, soil, 1, 2);
		world.setBlock(x + 1, y - 3, z - 1, soil, 1, 2);
		world.setBlock(x - 1, y - 3, z + 1, soil, 1, 2);
		world.setBlock(x + 1, y - 3, z + 1, soil, 1, 2);
		world.setBlock(x - 1, y - 3, z - 2, soil, 1, 2);
		world.setBlock(x + 1, y - 3, z - 2, soil, 1, 2);
		world.setBlock(x - 1, y - 3, z + 2, soil, 1, 2);
		world.setBlock(x + 1, y - 3, z + 2, soil, 1, 2);
		world.setBlock(x - 1, y - 3, z - 3, soil, 1, 2);
		world.setBlock(x + 1, y - 3, z - 3, soil, 1, 2);
		world.setBlock(x - 1, y - 3, z + 3, soil, 1, 2);
		world.setBlock(x + 1, y - 3, z + 3, soil, 1, 2);
		world.setBlock(x - 1, y - 3, z - 4, soil, 1, 2);
		world.setBlock(x + 1, y - 3, z - 4, soil, 1, 2);
		world.setBlock(x - 1, y - 3, z + 4, soil, 1, 2);
		world.setBlock(x + 1, y - 3, z + 4, soil, 1, 2);
		world.setBlock(x - 1, y - 3, z - 5, soil, 1, 2);
		world.setBlock(x + 1, y - 3, z - 5, soil, 1, 2);
		world.setBlock(x - 1, y - 3, z + 5, soil, 1, 2);
		world.setBlock(x + 1, y - 3, z + 5, soil, 1, 2);
		world.setBlock(x - 1, y - 3, z - 6, soil, 1, 2);
		world.setBlock(x + 1, y - 3, z - 6, soil, 1, 2);
		world.setBlock(x - 1, y - 3, z + 6, soil, 1, 2);
		world.setBlock(x - 1, y - 3, z - 7, soil, 1, 2);
		world.setBlock(x - 1, y - 3, z + 7, soil, 1, 2);
		world.setBlock(x - 1, y - 3, z - 8, soil, 1, 2);
		world.setBlock(x - 1, y - 3, z + 8, soil, 1, 2);
		world.setBlock(x - 1, y - 4, z, soil, 1, 2);
		world.setBlock(x + 1, y - 4, z, soil, 1, 2);
		world.setBlock(x - 1, y - 4, z, soil, 1, 2);
		world.setBlock(x + 1, y - 4, z, soil, 1, 2);
		world.setBlock(x - 1, y - 4, z - 1, soil, 1, 2);
		world.setBlock(x + 1, y - 4, z - 1, soil, 1, 2);
		world.setBlock(x - 1, y - 4, z + 1, soil, 1, 2);
		world.setBlock(x + 1, y - 4, z + 1, soil, 1, 2);
		world.setBlock(x - 1, y - 4, z - 2, soil, 1, 2);
		world.setBlock(x + 1, y - 4, z - 2, soil, 1, 2);
		world.setBlock(x - 1, y - 4, z + 2, soil, 1, 2);
		world.setBlock(x + 1, y - 4, z + 2, soil, 1, 2);
		world.setBlock(x - 1, y - 4, z - 3, soil, 1, 2);
		world.setBlock(x + 1, y - 4, z - 3, soil, 1, 2);
		world.setBlock(x - 1, y - 4, z + 3, soil, 1, 2);
		world.setBlock(x + 1, y - 4, z + 3, soil, 1, 2);
		world.setBlock(x - 1, y - 4, z - 4, soil, 1, 2);
		world.setBlock(x + 1, y - 4, z - 4, soil, 1, 2);
		world.setBlock(x - 1, y - 4, z + 4, soil, 1, 2);
		world.setBlock(x + 1, y - 4, z + 4, soil, 1, 2);
		world.setBlock(x - 1, y - 4, z - 5, soil, 1, 2);
		world.setBlock(x + 1, y - 4, z - 5, soil, 1, 2);
		world.setBlock(x - 1, y - 4, z + 5, soil, 1, 2);
		world.setBlock(x + 1, y - 4, z + 5, soil, 1, 2);
		world.setBlock(x - 1, y - 4, z - 6, soil, 1, 2);
		world.setBlock(x + 1, y - 4, z - 6, soil, 1, 2);
		world.setBlock(x - 1, y - 4, z + 6, soil, 1, 2);
		world.setBlock(x - 1, y - 4, z - 7, soil, 1, 2);
		world.setBlock(x - 1, y - 4, z - 8, soil, 1, 2);
		world.setBlock(x - 1, y - 5, z, soil, 1, 2);
		world.setBlock(x + 1, y - 5, z, soil, 1, 2);
		world.setBlock(x - 1, y - 5, z, soil, 1, 2);
		world.setBlock(x + 1, y - 5, z, soil, 1, 2);
		world.setBlock(x - 1, y - 5, z - 1, soil, 1, 2);
		world.setBlock(x + 1, y - 5, z - 1, soil, 1, 2);
		world.setBlock(x - 1, y - 5, z + 1, soil, 1, 2);
		world.setBlock(x + 1, y - 5, z + 1, soil, 1, 2);
		world.setBlock(x - 1, y - 5, z - 2, soil, 1, 2);
		world.setBlock(x + 1, y - 5, z - 2, soil, 1, 2);
		world.setBlock(x - 1, y - 5, z + 2, soil, 1, 2);
		world.setBlock(x + 1, y - 5, z + 2, soil, 1, 2);
		world.setBlock(x - 1, y - 5, z - 3, soil, 1, 2);
		world.setBlock(x + 1, y - 5, z - 3, soil, 1, 2);
		world.setBlock(x - 1, y - 5, z + 3, soil, 1, 2);
		world.setBlock(x + 1, y - 5, z + 3, soil, 1, 2);
		world.setBlock(x - 1, y - 5, z - 4, soil, 1, 2);
		world.setBlock(x + 1, y - 5, z - 4, soil, 1, 2);
		world.setBlock(x - 1, y - 5, z + 4, soil, 1, 2);
		world.setBlock(x - 1, y - 5, z - 5, soil, 1, 2);
		world.setBlock(x + 1, y - 5, z - 5, soil, 1, 2);
		world.setBlock(x - 1, y - 5, z + 5, soil, 1, 2);
		world.setBlock(x - 1, y - 5, z - 6, soil, 1, 2);
		world.setBlock(x + 1, y - 5, z - 6, soil, 1, 2);
		world.setBlock(x - 1, y - 5, z + 6, soil, 1, 2);
		world.setBlock(x - 1, y - 6, z, soil, 1, 2);
		world.setBlock(x + 1, y - 6, z, soil, 1, 2);
		world.setBlock(x - 1, y - 6, z, soil, 1, 2);
		world.setBlock(x + 1, y - 6, z, soil, 1, 2);
		world.setBlock(x - 1, y - 6, z - 1, soil, 1, 2);
		world.setBlock(x + 1, y - 6, z - 1, soil, 1, 2);
		world.setBlock(x - 1, y - 6, z + 1, soil, 1, 2);
		world.setBlock(x + 1, y - 6, z + 1, soil, 1, 2);
		world.setBlock(x - 1, y - 6, z - 2, soil, 1, 2);
		world.setBlock(x + 1, y - 6, z - 2, soil, 1, 2);
		world.setBlock(x - 1, y - 6, z + 2, soil, 1, 2);
		world.setBlock(x + 1, y - 6, z + 2, soil, 1, 2);
		world.setBlock(x + 1, y - 6, z - 3, soil, 1, 2);
		world.setBlock(x - 1, y - 6, z + 3, soil, 1, 2);
		world.setBlock(x + 1, y - 6, z + 3, soil, 1, 2);
		world.setBlock(x + 1, y - 6, z - 4, soil, 1, 2);
		world.setBlock(x - 1, y - 6, z + 4, soil, 1, 2);
		world.setBlock(x - 1, y - 6, z + 5, soil, 1, 2);
		world.setBlock(x - 1, y - 7, z, soil, 1, 2);
		world.setBlock(x + 1, y - 7, z, soil, 1, 2);
		world.setBlock(x - 1, y - 7, z, soil, 1, 2);
		world.setBlock(x + 1, y - 7, z, soil, 1, 2);
		world.setBlock(x - 1, y - 7, z - 1, soil, 1, 2);
		world.setBlock(x + 1, y - 7, z - 1, soil, 1, 2);
		world.setBlock(x - 1, y - 7, z + 1, soil, 1, 2);
		world.setBlock(x + 1, y - 7, z + 1, soil, 1, 2);
		world.setBlock(x - 1, y - 7, z - 2, soil, 1, 2);
		world.setBlock(x + 1, y - 7, z - 2, soil, 1, 2);
		world.setBlock(x - 1, y - 7, z + 2, soil, 1, 2);
		world.setBlock(x + 1, y - 7, z + 2, soil, 1, 2);
		world.setBlock(x + 1, y - 7, z - 3, soil, 1, 2);
		world.setBlock(x + 1, y - 7, z + 3, soil, 1, 2);
		world.setBlock(x + 1, y - 7, z - 4, soil, 1, 2);
		world.setBlock(x + 1, y - 8, z, soil, 1, 2);
		world.setBlock(x + 1, y - 8, z, soil, 1, 2);
		world.setBlock(x + 1, y - 8, z - 1, soil, 1, 2);
		world.setBlock(x + 2, y, z, soil, 0, 2);
		world.setBlock(x - 2, y, z, soil, 0, 2);
		world.setBlock(x + 2, y, z, soil, 0, 2);
		world.setBlock(x - 2, y, z, soil, 0, 2);
		world.setBlock(x + 2, y, z, soil, 0, 2);
		world.setBlock(x - 2, y, z, soil, 0, 2);
		world.setBlock(x + 2, y, z, soil, 0, 2);
		world.setBlock(x - 2, y, z, soil, 0, 2);
		world.setBlock(x + 2, y, z + 1, soil, 0, 2);
		world.setBlock(x - 2, y, z - 1, soil, 0, 2);
		world.setBlock(x + 2, y, z - 1, soil, 0, 2);
		world.setBlock(x - 2, y, z + 1, soil, 0, 2);
		world.setBlock(x + 2, y, z - 1, soil, 0, 2);
		world.setBlock(x - 2, y, z + 1, soil, 0, 2);
		world.setBlock(x + 2, y, z + 1, soil, 0, 2);
		world.setBlock(x - 2, y, z - 1, soil, 0, 2);
		world.setBlock(x + 2, y, z + 2, soil, 0, 2);
		world.setBlock(x - 2, y, z - 2, soil, 0, 2);
		world.setBlock(x + 2, y, z - 2, soil, 0, 2);
		world.setBlock(x - 2, y, z + 2, soil, 0, 2);
		world.setBlock(x + 2, y, z - 2, soil, 0, 2);
		world.setBlock(x - 2, y, z + 2, soil, 0, 2);
		world.setBlock(x + 2, y, z + 2, soil, 0, 2);
		world.setBlock(x - 2, y, z - 2, soil, 0, 2);
		world.setBlock(x + 2, y, z + 3, soil, 0, 2);
		world.setBlock(x - 2, y, z - 3, soil, 0, 2);
		world.setBlock(x + 2, y, z - 3, soil, 0, 2);
		world.setBlock(x - 2, y, z + 3, soil, 0, 2);
		world.setBlock(x + 2, y, z - 3, soil, 0, 2);
		world.setBlock(x - 2, y, z + 3, soil, 0, 2);
		world.setBlock(x + 2, y, z + 3, soil, 0, 2);
		world.setBlock(x - 2, y, z - 3, soil, 0, 2);
		world.setBlock(x + 2, y, z + 4, soil, 0, 2);
		world.setBlock(x - 2, y, z - 4, soil, 0, 2);
		world.setBlock(x + 2, y, z - 4, soil, 0, 2);
		world.setBlock(x - 2, y, z + 4, soil, 0, 2);
		world.setBlock(x + 2, y, z - 4, soil, 0, 2);
		world.setBlock(x - 2, y, z + 4, soil, 0, 2);
		world.setBlock(x + 2, y, z + 4, soil, 0, 2);
		world.setBlock(x - 2, y, z - 4, soil, 0, 2);
		world.setBlock(x + 2, y, z + 5, soil, 0, 2);
		world.setBlock(x - 2, y, z - 5, soil, 0, 2);
		world.setBlock(x + 2, y, z - 5, soil, 0, 2);
		world.setBlock(x - 2, y, z + 5, soil, 0, 2);
		world.setBlock(x + 2, y, z - 5, soil, 0, 2);
		world.setBlock(x - 2, y, z + 5, soil, 0, 2);
		world.setBlock(x + 2, y, z + 5, soil, 0, 2);
		world.setBlock(x - 2, y, z - 5, soil, 0, 2);
		world.setBlock(x + 2, y, z + 6, soil, 0, 2);
		world.setBlock(x - 2, y, z - 6, soil, 0, 2);
		world.setBlock(x + 2, y, z - 6, soil, 0, 2);
		world.setBlock(x - 2, y, z + 6, soil, 0, 2);
		world.setBlock(x + 2, y, z - 6, soil, 0, 2);
		world.setBlock(x - 2, y, z + 6, soil, 0, 2);
		world.setBlock(x + 2, y, z + 6, soil, 0, 2);
		world.setBlock(x - 2, y, z - 6, soil, 0, 2);
		world.setBlock(x + 2, y, z + 7, soil, 0, 2);
		world.setBlock(x - 2, y, z - 7, soil, 0, 2);
		world.setBlock(x + 2, y, z - 7, soil, 0, 2);
		world.setBlock(x - 2, y, z + 7, soil, 0, 2);
		world.setBlock(x + 2, y, z - 7, soil, 0, 2);
		world.setBlock(x - 2, y, z + 7, soil, 0, 2);
		world.setBlock(x + 2, y, z + 7, soil, 0, 2);
		world.setBlock(x - 2, y, z - 7, soil, 0, 2);
		world.setBlock(x - 2, y, z - 8, soil, 0, 2);
		world.setBlock(x + 2, y, z - 8, soil, 0, 2);
		world.setBlock(x - 2, y, z + 8, soil, 0, 2);
		world.setBlock(x + 2, y, z - 8, soil, 0, 2);
		world.setBlock(x - 2, y, z + 8, soil, 0, 2);
		world.setBlock(x - 2, y, z - 8, soil, 0, 2);
		world.setBlock(x - 2, y, z - 9, soil, 0, 2);
		world.setBlock(x + 2, y, z - 9, soil, 0, 2);
		world.setBlock(x + 2, y, z - 9, soil, 0, 2);
		world.setBlock(x - 2, y, z - 9, soil, 0, 2);
		world.setBlock(x - 2, y - 1, z, soil, 1, 2);
		world.setBlock(x + 2, y - 1, z, soil, 1, 2);
		world.setBlock(x - 2, y - 1, z, soil, 1, 2);
		world.setBlock(x + 2, y - 1, z, soil, 1, 2);
		world.setBlock(x - 2, y - 1, z - 1, soil, 1, 2);
		world.setBlock(x + 2, y - 1, z - 1, soil, 1, 2);
		world.setBlock(x - 2, y - 1, z + 1, soil, 1, 2);
		world.setBlock(x + 2, y - 1, z + 1, soil, 1, 2);
		world.setBlock(x - 2, y - 1, z - 2, soil, 1, 2);
		world.setBlock(x + 2, y - 1, z - 2, soil, 1, 2);
		world.setBlock(x - 2, y - 1, z + 2, soil, 1, 2);
		world.setBlock(x + 2, y - 1, z + 2, soil, 1, 2);
		world.setBlock(x - 2, y - 1, z - 3, soil, 1, 2);
		world.setBlock(x + 2, y - 1, z - 3, soil, 1, 2);
		world.setBlock(x - 2, y - 1, z + 3, soil, 1, 2);
		world.setBlock(x + 2, y - 1, z + 3, soil, 1, 2);
		world.setBlock(x - 2, y - 1, z - 4, soil, 1, 2);
		world.setBlock(x + 2, y - 1, z - 4, soil, 1, 2);
		world.setBlock(x - 2, y - 1, z + 4, soil, 1, 2);
		world.setBlock(x + 2, y - 1, z + 4, soil, 1, 2);
		world.setBlock(x - 2, y - 1, z - 5, soil, 1, 2);
		world.setBlock(x + 2, y - 1, z - 5, soil, 1, 2);
		world.setBlock(x - 2, y - 1, z + 5, soil, 1, 2);
		world.setBlock(x + 2, y - 1, z + 5, soil, 1, 2);
		world.setBlock(x - 2, y - 1, z - 6, soil, 1, 2);
		world.setBlock(x + 2, y - 1, z - 6, soil, 1, 2);
		world.setBlock(x - 2, y - 1, z + 6, soil, 1, 2);
		world.setBlock(x + 2, y - 1, z + 6, soil, 1, 2);
		world.setBlock(x - 2, y - 1, z - 7, soil, 1, 2);
		world.setBlock(x + 2, y - 1, z - 7, soil, 1, 2);
		world.setBlock(x - 2, y - 1, z + 7, soil, 1, 2);
		world.setBlock(x + 2, y - 1, z + 7, soil, 1, 2);
		world.setBlock(x - 2, y - 1, z - 8, soil, 1, 2);
		world.setBlock(x + 2, y - 1, z - 8, soil, 1, 2);
		world.setBlock(x - 2, y - 1, z + 8, soil, 1, 2);
		world.setBlock(x - 2, y - 1, z - 9, soil, 1, 2);
		world.setBlock(x + 2, y - 1, z - 9, soil, 1, 2);
		world.setBlock(x - 2, y - 1, z + 9, soil, 0, 2);
		world.setBlock(x - 2, y - 1, z + 10, soil, 0, 2);
		world.setBlock(x - 2, y - 2, z, soil, 1, 2);
		world.setBlock(x + 2, y - 2, z, soil, 1, 2);
		world.setBlock(x - 2, y - 2, z, soil, 1, 2);
		world.setBlock(x + 2, y - 2, z, soil, 1, 2);
		world.setBlock(x - 2, y - 2, z - 1, soil, 1, 2);
		world.setBlock(x + 2, y - 2, z - 1, soil, 1, 2);
		world.setBlock(x - 2, y - 2, z + 1, soil, 1, 2);
		world.setBlock(x + 2, y - 2, z + 1, soil, 1, 2);
		world.setBlock(x - 2, y - 2, z - 2, soil, 1, 2);
		world.setBlock(x + 2, y - 2, z - 2, soil, 1, 2);
		world.setBlock(x - 2, y - 2, z + 2, soil, 1, 2);
		world.setBlock(x + 2, y - 2, z + 2, soil, 1, 2);
		world.setBlock(x - 2, y - 2, z - 3, soil, 1, 2);
		world.setBlock(x + 2, y - 2, z - 3, soil, 1, 2);
		world.setBlock(x - 2, y - 2, z + 3, soil, 1, 2);
		world.setBlock(x + 2, y - 2, z + 3, soil, 1, 2);
		world.setBlock(x - 2, y - 2, z - 4, soil, 1, 2);
		world.setBlock(x + 2, y - 2, z - 4, soil, 1, 2);
		world.setBlock(x - 2, y - 2, z + 4, soil, 1, 2);
		world.setBlock(x + 2, y - 2, z + 4, soil, 1, 2);
		world.setBlock(x - 2, y - 2, z - 5, soil, 1, 2);
		world.setBlock(x + 2, y - 2, z - 5, soil, 1, 2);
		world.setBlock(x - 2, y - 2, z + 5, soil, 1, 2);
		world.setBlock(x + 2, y - 2, z + 5, soil, 1, 2);
		world.setBlock(x - 2, y - 2, z - 6, soil, 1, 2);
		world.setBlock(x + 2, y - 2, z - 6, soil, 1, 2);
		world.setBlock(x - 2, y - 2, z + 6, soil, 1, 2);
		world.setBlock(x + 2, y - 2, z + 6, soil, 1, 2);
		world.setBlock(x - 2, y - 2, z - 7, soil, 1, 2);
		world.setBlock(x + 2, y - 2, z - 7, soil, 1, 2);
		world.setBlock(x - 2, y - 2, z + 7, soil, 1, 2);
		world.setBlock(x - 2, y - 2, z - 8, soil, 1, 2);
		world.setBlock(x + 2, y - 2, z - 8, soil, 1, 2);
		world.setBlock(x - 2, y - 2, z + 8, soil, 1, 2);
		world.setBlock(x - 2, y - 2, z - 9, soil, 1, 2);
		world.setBlock(x - 2, y - 2, z + 9, soil, 1, 2);
		world.setBlock(x - 2, y - 2, z + 10, soil, 1, 2);
		world.setBlock(x - 2, y - 3, z, soil, 1, 2);
		world.setBlock(x + 2, y - 3, z, soil, 1, 2);
		world.setBlock(x - 2, y - 3, z, soil, 1, 2);
		world.setBlock(x + 2, y - 3, z, soil, 1, 2);
		world.setBlock(x - 2, y - 3, z - 1, soil, 1, 2);
		world.setBlock(x + 2, y - 3, z - 1, soil, 1, 2);
		world.setBlock(x - 2, y - 3, z + 1, soil, 1, 2);
		world.setBlock(x + 2, y - 3, z + 1, soil, 1, 2);
		world.setBlock(x - 2, y - 3, z - 2, soil, 1, 2);
		world.setBlock(x + 2, y - 3, z - 2, soil, 1, 2);
		world.setBlock(x - 2, y - 3, z + 2, soil, 1, 2);
		world.setBlock(x + 2, y - 3, z + 2, soil, 1, 2);
		world.setBlock(x - 2, y - 3, z - 3, soil, 1, 2);
		world.setBlock(x + 2, y - 3, z - 3, soil, 1, 2);
		world.setBlock(x - 2, y - 3, z + 3, soil, 1, 2);
		world.setBlock(x + 2, y - 3, z + 3, soil, 1, 2);
		world.setBlock(x - 2, y - 3, z - 4, soil, 1, 2);
		world.setBlock(x + 2, y - 3, z - 4, soil, 1, 2);
		world.setBlock(x - 2, y - 3, z + 4, soil, 1, 2);
		world.setBlock(x + 2, y - 3, z + 4, soil, 1, 2);
		world.setBlock(x - 2, y - 3, z - 5, soil, 1, 2);
		world.setBlock(x + 2, y - 3, z - 5, soil, 1, 2);
		world.setBlock(x - 2, y - 3, z + 5, soil, 1, 2);
		world.setBlock(x + 2, y - 3, z + 5, soil, 1, 2);
		world.setBlock(x - 2, y - 3, z - 6, soil, 1, 2);
		world.setBlock(x + 2, y - 3, z - 6, soil, 1, 2);
		world.setBlock(x - 2, y - 3, z + 6, soil, 1, 2);
		world.setBlock(x + 2, y - 3, z + 6, soil, 1, 2);
		world.setBlock(x - 2, y - 3, z - 7, soil, 1, 2);
		world.setBlock(x - 2, y - 3, z + 7, soil, 1, 2);
		world.setBlock(x - 2, y - 3, z - 8, soil, 1, 2);
		world.setBlock(x - 2, y - 3, z + 8, soil, 1, 2);
		world.setBlock(x - 2, y - 4, z, soil, 1, 2);
		world.setBlock(x + 2, y - 4, z, soil, 1, 2);
		world.setBlock(x - 2, y - 4, z, soil, 1, 2);
		world.setBlock(x + 2, y - 4, z, soil, 1, 2);
		world.setBlock(x - 2, y - 4, z - 1, soil, 1, 2);
		world.setBlock(x + 2, y - 4, z - 1, soil, 1, 2);
		world.setBlock(x - 2, y - 4, z + 1, soil, 1, 2);
		world.setBlock(x + 2, y - 4, z + 1, soil, 1, 2);
		world.setBlock(x - 2, y - 4, z - 2, soil, 1, 2);
		world.setBlock(x + 2, y - 4, z - 2, soil, 1, 2);
		world.setBlock(x - 2, y - 4, z + 2, soil, 1, 2);
		world.setBlock(x + 2, y - 4, z + 2, soil, 1, 2);
		world.setBlock(x - 2, y - 4, z - 3, soil, 1, 2);
		world.setBlock(x + 2, y - 4, z - 3, soil, 1, 2);
		world.setBlock(x - 2, y - 4, z + 3, soil, 1, 2);
		world.setBlock(x + 2, y - 4, z + 3, soil, 1, 2);
		world.setBlock(x - 2, y - 4, z - 4, soil, 1, 2);
		world.setBlock(x + 2, y - 4, z - 4, soil, 1, 2);
		world.setBlock(x - 2, y - 4, z + 4, soil, 1, 2);
		world.setBlock(x + 2, y - 4, z + 4, soil, 1, 2);
		world.setBlock(x - 2, y - 4, z - 5, soil, 1, 2);
		world.setBlock(x + 2, y - 4, z - 5, soil, 1, 2);
		world.setBlock(x - 2, y - 4, z + 5, soil, 1, 2);
		world.setBlock(x + 2, y - 4, z + 5, soil, 1, 2);
		world.setBlock(x - 2, y - 4, z - 6, soil, 1, 2);
		world.setBlock(x + 2, y - 4, z - 6, soil, 1, 2);
		world.setBlock(x - 2, y - 4, z + 6, soil, 1, 2);
		world.setBlock(x - 2, y - 4, z - 7, soil, 1, 2);
		world.setBlock(x - 2, y - 4, z + 7, soil, 1, 2);
		world.setBlock(x - 2, y - 4, z - 8, soil, 1, 2);
		world.setBlock(x - 2, y - 5, z, soil, 1, 2);
		world.setBlock(x + 2, y - 5, z, soil, 1, 2);
		world.setBlock(x - 2, y - 5, z, soil, 1, 2);
		world.setBlock(x + 2, y - 5, z, soil, 1, 2);
		world.setBlock(x - 2, y - 5, z - 1, soil, 1, 2);
		world.setBlock(x + 2, y - 5, z - 1, soil, 1, 2);
		world.setBlock(x - 2, y - 5, z + 1, soil, 1, 2);
		world.setBlock(x + 2, y - 5, z + 1, soil, 1, 2);
		world.setBlock(x - 2, y - 5, z - 2, soil, 1, 2);
		world.setBlock(x + 2, y - 5, z - 2, soil, 1, 2);
		world.setBlock(x - 2, y - 5, z + 2, soil, 1, 2);
		world.setBlock(x + 2, y - 5, z + 2, soil, 1, 2);
		world.setBlock(x - 2, y - 5, z - 3, soil, 1, 2);
		world.setBlock(x + 2, y - 5, z - 3, soil, 1, 2);
		world.setBlock(x - 2, y - 5, z + 3, soil, 1, 2);
		world.setBlock(x + 2, y - 5, z + 3, soil, 1, 2);
		world.setBlock(x - 2, y - 5, z - 4, soil, 1, 2);
		world.setBlock(x + 2, y - 5, z - 4, soil, 1, 2);
		world.setBlock(x - 2, y - 5, z + 4, soil, 1, 2);
		world.setBlock(x - 2, y - 5, z - 5, soil, 1, 2);
		world.setBlock(x + 2, y - 5, z - 5, soil, 1, 2);
		world.setBlock(x - 2, y - 5, z + 5, soil, 1, 2);
		world.setBlock(x - 2, y - 5, z - 6, soil, 1, 2);
		world.setBlock(x + 2, y - 5, z - 6, soil, 1, 2);
		world.setBlock(x - 2, y - 5, z + 6, soil, 1, 2);
		world.setBlock(x - 2, y - 5, z + 7, soil, 1, 2);
		world.setBlock(x - 2, y - 6, z, soil, 1, 2);
		world.setBlock(x + 2, y - 6, z, soil, 1, 2);
		world.setBlock(x - 2, y - 6, z, soil, 1, 2);
		world.setBlock(x + 2, y - 6, z, soil, 1, 2);
		world.setBlock(x - 2, y - 6, z - 1, soil, 1, 2);
		world.setBlock(x + 2, y - 6, z - 1, soil, 1, 2);
		world.setBlock(x - 2, y - 6, z + 1, soil, 1, 2);
		world.setBlock(x + 2, y - 6, z + 1, soil, 1, 2);
		world.setBlock(x - 2, y - 6, z - 2, soil, 1, 2);
		world.setBlock(x + 2, y - 6, z - 2, soil, 1, 2);
		world.setBlock(x - 2, y - 6, z + 2, soil, 1, 2);
		world.setBlock(x + 2, y - 6, z + 2, soil, 1, 2);
		world.setBlock(x - 2, y - 6, z - 3, soil, 1, 2);
		world.setBlock(x + 2, y - 6, z - 3, soil, 1, 2);
		world.setBlock(x - 2, y - 6, z + 3, soil, 1, 2);
		world.setBlock(x + 2, y - 6, z + 3, soil, 1, 2);
		world.setBlock(x - 2, y - 6, z - 4, soil, 1, 2);
		world.setBlock(x + 2, y - 6, z - 4, soil, 1, 2);
		world.setBlock(x - 2, y - 6, z + 4, soil, 1, 2);
		world.setBlock(x - 2, y - 6, z - 5, soil, 1, 2);
		world.setBlock(x - 2, y - 6, z + 5, soil, 1, 2);
		world.setBlock(x - 2, y - 7, z, soil, 1, 2);
		world.setBlock(x + 2, y - 7, z, soil, 1, 2);
		world.setBlock(x - 2, y - 7, z, soil, 1, 2);
		world.setBlock(x + 2, y - 7, z, soil, 1, 2);
		world.setBlock(x - 2, y - 7, z - 1, soil, 1, 2);
		world.setBlock(x + 2, y - 7, z - 1, soil, 1, 2);
		world.setBlock(x - 2, y - 7, z + 1, soil, 1, 2);
		world.setBlock(x + 2, y - 7, z + 1, soil, 1, 2);
		world.setBlock(x - 2, y - 7, z - 2, soil, 1, 2);
		world.setBlock(x + 2, y - 7, z - 2, soil, 1, 2);
		world.setBlock(x - 2, y - 7, z + 2, soil, 1, 2);
		world.setBlock(x + 2, y - 7, z + 2, soil, 1, 2);
		world.setBlock(x + 2, y - 7, z - 3, soil, 1, 2);
		world.setBlock(x + 2, y - 7, z + 3, soil, 1, 2);
		world.setBlock(x + 2, y - 7, z - 4, soil, 1, 2);
		world.setBlock(x + 2, y - 8, z, soil, 1, 2);
		world.setBlock(x + 2, y - 8, z, soil, 1, 2);
		world.setBlock(x + 2, y - 8, z - 1, soil, 1, 2);
		world.setBlock(x + 2, y - 8, z - 2, soil, 1, 2);
		world.setBlock(x + 2, y - 8, z - 3, soil, 1, 2);
		world.setBlock(x + 3, y, z, soil, 0, 2);
		world.setBlock(x - 3, y, z, soil, 0, 2);
		world.setBlock(x + 3, y, z, soil, 0, 2);
		world.setBlock(x - 3, y, z, soil, 0, 2);
		world.setBlock(x + 3, y, z, soil, 0, 2);
		world.setBlock(x - 3, y, z, soil, 0, 2);
		world.setBlock(x + 3, y, z, soil, 0, 2);
		world.setBlock(x - 3, y, z, soil, 0, 2);
		world.setBlock(x + 3, y, z + 1, soil, 0, 2);
		world.setBlock(x - 3, y, z - 1, soil, 0, 2);
		world.setBlock(x + 3, y, z - 1, soil, 0, 2);
		world.setBlock(x - 3, y, z + 1, soil, 0, 2);
		world.setBlock(x + 3, y, z - 1, soil, 0, 2);
		world.setBlock(x - 3, y, z + 1, soil, 0, 2);
		world.setBlock(x + 3, y, z + 1, soil, 0, 2);
		world.setBlock(x - 3, y, z - 1, soil, 0, 2);
		world.setBlock(x + 3, y, z + 2, soil, 0, 2);
		world.setBlock(x - 3, y, z - 2, soil, 0, 2);
		world.setBlock(x + 3, y, z - 2, soil, 0, 2);
		world.setBlock(x - 3, y, z + 2, soil, 0, 2);
		world.setBlock(x + 3, y, z - 2, soil, 0, 2);
		world.setBlock(x - 3, y, z + 2, soil, 0, 2);
		world.setBlock(x + 3, y, z + 2, soil, 0, 2);
		world.setBlock(x - 3, y, z - 2, soil, 0, 2);
		world.setBlock(x + 3, y, z + 3, soil, 0, 2);
		world.setBlock(x - 3, y, z - 3, soil, 0, 2);
		world.setBlock(x + 3, y, z - 3, soil, 0, 2);
		world.setBlock(x - 3, y, z + 3, soil, 0, 2);
		world.setBlock(x + 3, y, z - 3, soil, 0, 2);
		world.setBlock(x - 3, y, z + 3, soil, 0, 2);
		world.setBlock(x + 3, y, z + 3, soil, 0, 2);
		world.setBlock(x - 3, y, z - 3, soil, 0, 2);
		world.setBlock(x + 3, y, z + 4, soil, 0, 2);
		world.setBlock(x - 3, y, z - 4, soil, 0, 2);
		world.setBlock(x + 3, y, z - 4, soil, 0, 2);
		world.setBlock(x - 3, y, z + 4, soil, 0, 2);
		world.setBlock(x + 3, y, z - 4, soil, 0, 2);
		world.setBlock(x - 3, y, z + 4, soil, 0, 2);
		world.setBlock(x + 3, y, z + 4, soil, 0, 2);
		world.setBlock(x - 3, y, z - 4, soil, 0, 2);
		world.setBlock(x + 3, y, z + 5, soil, 0, 2);
		world.setBlock(x - 3, y, z - 5, soil, 0, 2);
		world.setBlock(x + 3, y, z - 5, soil, 0, 2);
		world.setBlock(x - 3, y, z + 5, soil, 0, 2);
		world.setBlock(x + 3, y, z - 5, soil, 0, 2);
		world.setBlock(x - 3, y, z + 5, soil, 0, 2);
		world.setBlock(x + 3, y, z + 5, soil, 0, 2);
		world.setBlock(x - 3, y, z - 5, soil, 0, 2);
		world.setBlock(x + 3, y, z + 6, soil, 0, 2);
		world.setBlock(x - 3, y, z - 6, soil, 0, 2);
		world.setBlock(x + 3, y, z - 6, soil, 0, 2);
		world.setBlock(x - 3, y, z + 6, soil, 0, 2);
		world.setBlock(x + 3, y, z - 6, soil, 0, 2);
		world.setBlock(x - 3, y, z + 6, soil, 0, 2);
		world.setBlock(x + 3, y, z + 6, soil, 0, 2);
		world.setBlock(x - 3, y, z - 6, soil, 0, 2);
		world.setBlock(x + 3, y, z + 7, soil, 0, 2);
		world.setBlock(x - 3, y, z - 7, soil, 0, 2);
		world.setBlock(x + 3, y, z - 7, soil, 0, 2);
		world.setBlock(x - 3, y, z + 7, soil, 0, 2);
		world.setBlock(x + 3, y, z - 7, soil, 0, 2);
		world.setBlock(x - 3, y, z + 7, soil, 0, 2);
		world.setBlock(x + 3, y, z + 7, soil, 0, 2);
		world.setBlock(x - 3, y, z - 7, soil, 0, 2);
		world.setBlock(x - 3, y, z - 8, soil, 0, 2);
		world.setBlock(x + 3, y, z - 8, soil, 0, 2);
		world.setBlock(x - 3, y, z + 8, soil, 0, 2);
		world.setBlock(x + 3, y, z - 8, soil, 0, 2);
		world.setBlock(x - 3, y, z + 8, soil, 0, 2);
		world.setBlock(x - 3, y, z - 8, soil, 0, 2);
		world.setBlock(x - 3, y, z - 9, soil, 0, 2);
		world.setBlock(x + 3, y, z - 9, soil, 0, 2);
		world.setBlock(x - 3, y, z + 9, soil, 0, 2);
		world.setBlock(x + 3, y, z - 9, soil, 0, 2);
		world.setBlock(x - 3, y, z + 9, soil, 0, 2);
		world.setBlock(x - 3, y, z - 9, soil, 0, 2);
		world.setBlock(x - 3, y - 1, z, soil, 1, 2);
		world.setBlock(x + 3, y - 1, z, soil, 1, 2);
		world.setBlock(x - 3, y - 1, z, soil, 1, 2);
		world.setBlock(x + 3, y - 1, z, soil, 1, 2);
		world.setBlock(x - 3, y - 1, z - 1, soil, 1, 2);
		world.setBlock(x + 3, y - 1, z - 1, soil, 1, 2);
		world.setBlock(x - 3, y - 1, z + 1, soil, 1, 2);
		world.setBlock(x + 3, y - 1, z + 1, soil, 1, 2);
		world.setBlock(x - 3, y - 1, z - 2, soil, 1, 2);
		world.setBlock(x + 3, y - 1, z - 2, soil, 1, 2);
		world.setBlock(x - 3, y - 1, z + 2, soil, 1, 2);
		world.setBlock(x + 3, y - 1, z + 2, soil, 1, 2);
		world.setBlock(x - 3, y - 1, z - 3, soil, 1, 2);
		world.setBlock(x + 3, y - 1, z - 3, soil, 1, 2);
		world.setBlock(x - 3, y - 1, z + 3, soil, 1, 2);
		world.setBlock(x + 3, y - 1, z + 3, soil, 1, 2);
		world.setBlock(x - 3, y - 1, z - 4, soil, 1, 2);
		world.setBlock(x + 3, y - 1, z - 4, soil, 1, 2);
		world.setBlock(x - 3, y - 1, z + 4, soil, 1, 2);
		world.setBlock(x + 3, y - 1, z + 4, soil, 1, 2);
		world.setBlock(x - 3, y - 1, z - 5, soil, 1, 2);
		world.setBlock(x + 3, y - 1, z - 5, soil, 1, 2);
		world.setBlock(x - 3, y - 1, z + 5, soil, 1, 2);
		world.setBlock(x + 3, y - 1, z + 5, soil, 1, 2);
		world.setBlock(x - 3, y - 1, z - 6, soil, 1, 2);
		world.setBlock(x + 3, y - 1, z - 6, soil, 1, 2);
		world.setBlock(x - 3, y - 1, z + 6, soil, 1, 2);
		world.setBlock(x + 3, y - 1, z + 6, soil, 1, 2);
		world.setBlock(x - 3, y - 1, z - 7, soil, 1, 2);
		world.setBlock(x + 3, y - 1, z - 7, soil, 1, 2);
		world.setBlock(x - 3, y - 1, z + 7, soil, 1, 2);
		world.setBlock(x + 3, y - 1, z + 7, soil, 1, 2);
		world.setBlock(x - 3, y - 1, z - 8, soil, 1, 2);
		world.setBlock(x + 3, y - 1, z - 8, soil, 1, 2);
		world.setBlock(x - 3, y - 1, z + 8, soil, 1, 2);
		world.setBlock(x - 3, y - 1, z - 9, soil, 1, 2);
		world.setBlock(x + 3, y - 1, z - 9, soil, 1, 2);
		world.setBlock(x - 3, y - 1, z + 9, soil, 1, 2);
		world.setBlock(x - 3, y - 1, z + 10, soil, 0, 2);
		world.setBlock(x - 3, y - 2, z, soil, 1, 2);
		world.setBlock(x + 3, y - 2, z, soil, 1, 2);
		world.setBlock(x - 3, y - 2, z, soil, 1, 2);
		world.setBlock(x + 3, y - 2, z, soil, 1, 2);
		world.setBlock(x - 3, y - 2, z - 1, soil, 1, 2);
		world.setBlock(x + 3, y - 2, z - 1, soil, 1, 2);
		world.setBlock(x - 3, y - 2, z + 1, soil, 1, 2);
		world.setBlock(x + 3, y - 2, z + 1, soil, 1, 2);
		world.setBlock(x - 3, y - 2, z - 2, soil, 1, 2);
		world.setBlock(x + 3, y - 2, z - 2, soil, 1, 2);
		world.setBlock(x - 3, y - 2, z + 2, soil, 1, 2);
		world.setBlock(x + 3, y - 2, z + 2, soil, 1, 2);
		world.setBlock(x - 3, y - 2, z - 3, soil, 1, 2);
		world.setBlock(x + 3, y - 2, z - 3, soil, 1, 2);
		world.setBlock(x - 3, y - 2, z + 3, soil, 1, 2);
		world.setBlock(x + 3, y - 2, z + 3, soil, 1, 2);
		world.setBlock(x - 3, y - 2, z - 4, soil, 1, 2);
		world.setBlock(x + 3, y - 2, z - 4, soil, 1, 2);
		world.setBlock(x - 3, y - 2, z + 4, soil, 1, 2);
		world.setBlock(x + 3, y - 2, z + 4, soil, 1, 2);
		world.setBlock(x - 3, y - 2, z - 5, soil, 1, 2);
		world.setBlock(x + 3, y - 2, z - 5, soil, 1, 2);
		world.setBlock(x - 3, y - 2, z + 5, soil, 1, 2);
		world.setBlock(x + 3, y - 2, z + 5, soil, 1, 2);
		world.setBlock(x - 3, y - 2, z - 6, soil, 1, 2);
		world.setBlock(x + 3, y - 2, z - 6, soil, 1, 2);
		world.setBlock(x - 3, y - 2, z + 6, soil, 1, 2);
		world.setBlock(x + 3, y - 2, z + 6, soil, 1, 2);
		world.setBlock(x - 3, y - 2, z - 7, soil, 1, 2);
		world.setBlock(x + 3, y - 2, z - 7, soil, 1, 2);
		world.setBlock(x - 3, y - 2, z + 7, soil, 1, 2);
		world.setBlock(x - 3, y - 2, z - 8, soil, 1, 2);
		world.setBlock(x + 3, y - 2, z - 8, soil, 1, 2);
		world.setBlock(x - 3, y - 2, z + 8, soil, 1, 2);
		world.setBlock(x - 3, y - 2, z + 9, soil, 1, 2);
		world.setBlock(x - 3, y - 2, z + 10, soil, 1, 2);
		world.setBlock(x - 3, y - 3, z, soil, 1, 2);
		world.setBlock(x + 3, y - 3, z, soil, 1, 2);
		world.setBlock(x - 3, y - 3, z, soil, 1, 2);
		world.setBlock(x + 3, y - 3, z, soil, 1, 2);
		world.setBlock(x - 3, y - 3, z - 1, soil, 1, 2);
		world.setBlock(x + 3, y - 3, z - 1, soil, 1, 2);
		world.setBlock(x - 3, y - 3, z + 1, soil, 1, 2);
		world.setBlock(x + 3, y - 3, z + 1, soil, 1, 2);
		world.setBlock(x - 3, y - 3, z - 2, soil, 1, 2);
		world.setBlock(x + 3, y - 3, z - 2, soil, 1, 2);
		world.setBlock(x - 3, y - 3, z + 2, soil, 1, 2);
		world.setBlock(x + 3, y - 3, z + 2, soil, 1, 2);
		world.setBlock(x - 3, y - 3, z - 3, soil, 1, 2);
		world.setBlock(x + 3, y - 3, z - 3, soil, 1, 2);
		world.setBlock(x - 3, y - 3, z + 3, soil, 1, 2);
		world.setBlock(x + 3, y - 3, z + 3, soil, 1, 2);
		world.setBlock(x - 3, y - 3, z - 4, soil, 1, 2);
		world.setBlock(x + 3, y - 3, z - 4, soil, 1, 2);
		world.setBlock(x - 3, y - 3, z + 4, soil, 1, 2);
		world.setBlock(x + 3, y - 3, z + 4, soil, 1, 2);
		world.setBlock(x - 3, y - 3, z - 5, soil, 1, 2);
		world.setBlock(x + 3, y - 3, z - 5, soil, 1, 2);
		world.setBlock(x - 3, y - 3, z + 5, soil, 1, 2);
		world.setBlock(x + 3, y - 3, z + 5, soil, 1, 2);
		world.setBlock(x - 3, y - 3, z - 6, soil, 1, 2);
		world.setBlock(x + 3, y - 3, z - 6, soil, 1, 2);
		world.setBlock(x - 3, y - 3, z + 6, soil, 1, 2);
		world.setBlock(x + 3, y - 3, z + 6, soil, 1, 2);
		world.setBlock(x - 3, y - 3, z + 7, soil, 1, 2);
		world.setBlock(x - 3, y - 3, z + 8, soil, 1, 2);
		world.setBlock(x - 3, y - 4, z, soil, 1, 2);
		world.setBlock(x + 3, y - 4, z, soil, 1, 2);
		world.setBlock(x - 3, y - 4, z, soil, 1, 2);
		world.setBlock(x + 3, y - 4, z, soil, 1, 2);
		world.setBlock(x - 3, y - 4, z - 1, soil, 1, 2);
		world.setBlock(x + 3, y - 4, z - 1, soil, 1, 2);
		world.setBlock(x - 3, y - 4, z + 1, soil, 1, 2);
		world.setBlock(x + 3, y - 4, z + 1, soil, 1, 2);
		world.setBlock(x - 3, y - 4, z - 2, soil, 1, 2);
		world.setBlock(x + 3, y - 4, z - 2, soil, 1, 2);
		world.setBlock(x - 3, y - 4, z + 2, soil, 1, 2);
		world.setBlock(x + 3, y - 4, z + 2, soil, 1, 2);
		world.setBlock(x - 3, y - 4, z - 3, soil, 1, 2);
		world.setBlock(x + 3, y - 4, z - 3, soil, 1, 2);
		world.setBlock(x - 3, y - 4, z + 3, soil, 1, 2);
		world.setBlock(x + 3, y - 4, z + 3, soil, 1, 2);
		world.setBlock(x - 3, y - 4, z - 4, soil, 1, 2);
		world.setBlock(x + 3, y - 4, z - 4, soil, 1, 2);
		world.setBlock(x - 3, y - 4, z + 4, soil, 1, 2);
		world.setBlock(x + 3, y - 4, z + 4, soil, 1, 2);
		world.setBlock(x - 3, y - 4, z - 5, soil, 1, 2);
		world.setBlock(x + 3, y - 4, z - 5, soil, 1, 2);
		world.setBlock(x - 3, y - 4, z + 5, soil, 1, 2);
		world.setBlock(x + 3, y - 4, z + 5, soil, 1, 2);
		world.setBlock(x - 3, y - 4, z - 6, soil, 1, 2);
		world.setBlock(x + 3, y - 4, z - 6, soil, 1, 2);
		world.setBlock(x - 3, y - 4, z + 6, soil, 1, 2);
		world.setBlock(x + 3, y - 4, z + 6, soil, 1, 2);
		world.setBlock(x - 3, y - 4, z + 7, soil, 1, 2);
		world.setBlock(x - 3, y - 5, z, soil, 1, 2);
		world.setBlock(x + 3, y - 5, z, soil, 1, 2);
		world.setBlock(x - 3, y - 5, z, soil, 1, 2);
		world.setBlock(x + 3, y - 5, z, soil, 1, 2);
		world.setBlock(x - 3, y - 5, z - 1, soil, 1, 2);
		world.setBlock(x + 3, y - 5, z - 1, soil, 1, 2);
		world.setBlock(x - 3, y - 5, z + 1, soil, 1, 2);
		world.setBlock(x + 3, y - 5, z + 1, soil, 1, 2);
		world.setBlock(x - 3, y - 5, z - 2, soil, 1, 2);
		world.setBlock(x + 3, y - 5, z - 2, soil, 1, 2);
		world.setBlock(x - 3, y - 5, z + 2, soil, 1, 2);
		world.setBlock(x + 3, y - 5, z + 2, soil, 1, 2);
		world.setBlock(x - 3, y - 5, z - 3, soil, 1, 2);
		world.setBlock(x + 3, y - 5, z - 3, soil, 1, 2);
		world.setBlock(x - 3, y - 5, z + 3, soil, 1, 2);
		world.setBlock(x + 3, y - 5, z + 3, soil, 1, 2);
		world.setBlock(x - 3, y - 5, z - 4, soil, 1, 2);
		world.setBlock(x + 3, y - 5, z - 4, soil, 1, 2);
		world.setBlock(x - 3, y - 5, z + 4, soil, 1, 2);
		world.setBlock(x + 3, y - 5, z + 4, soil, 1, 2);
		world.setBlock(x - 3, y - 5, z - 5, soil, 1, 2);
		world.setBlock(x + 3, y - 5, z - 5, soil, 1, 2);
		world.setBlock(x - 3, y - 5, z + 5, soil, 1, 2);
		world.setBlock(x + 3, y - 5, z + 5, soil, 1, 2);
		world.setBlock(x - 3, y - 5, z - 6, soil, 1, 2);
		world.setBlock(x + 3, y - 5, z - 6, soil, 1, 2);
		world.setBlock(x - 3, y - 5, z + 6, soil, 1, 2);
		world.setBlock(x + 3, y - 5, z + 6, soil, 1, 2);
		world.setBlock(x - 3, y - 5, z + 7, soil, 1, 2);
		world.setBlock(x - 3, y - 6, z, soil, 1, 2);
		world.setBlock(x + 3, y - 6, z, soil, 1, 2);
		world.setBlock(x - 3, y - 6, z, soil, 1, 2);
		world.setBlock(x + 3, y - 6, z, soil, 1, 2);
		world.setBlock(x - 3, y - 6, z - 1, soil, 1, 2);
		world.setBlock(x + 3, y - 6, z - 1, soil, 1, 2);
		world.setBlock(x - 3, y - 6, z + 1, soil, 1, 2);
		world.setBlock(x + 3, y - 6, z + 1, soil, 1, 2);
		world.setBlock(x - 3, y - 6, z - 2, soil, 1, 2);
		world.setBlock(x + 3, y - 6, z - 2, soil, 1, 2);
		world.setBlock(x - 3, y - 6, z + 2, soil, 1, 2);
		world.setBlock(x + 3, y - 6, z + 2, soil, 1, 2);
		world.setBlock(x - 3, y - 6, z - 3, soil, 1, 2);
		world.setBlock(x + 3, y - 6, z - 3, soil, 1, 2);
		world.setBlock(x - 3, y - 6, z + 3, soil, 1, 2);
		world.setBlock(x + 3, y - 6, z + 3, soil, 1, 2);
		world.setBlock(x - 3, y - 6, z - 4, soil, 1, 2);
		world.setBlock(x + 3, y - 6, z - 4, soil, 1, 2);
		world.setBlock(x - 3, y - 6, z + 4, soil, 1, 2);
		world.setBlock(x - 3, y - 6, z - 5, soil, 1, 2);
		world.setBlock(x - 3, y - 6, z + 5, soil, 1, 2);
		world.setBlock(x - 3, y - 6, z + 6, soil, 1, 2);
		world.setBlock(x + 3, y - 7, z, soil, 1, 2);
		world.setBlock(x + 3, y - 7, z, soil, 1, 2);
		world.setBlock(x + 3, y - 7, z - 1, soil, 1, 2);
		world.setBlock(x + 3, y - 7, z + 1, soil, 1, 2);
		world.setBlock(x - 3, y - 7, z - 2, soil, 1, 2);
		world.setBlock(x + 3, y - 7, z - 2, soil, 1, 2);
		world.setBlock(x + 3, y - 7, z + 2, soil, 1, 2);
		world.setBlock(x - 3, y - 7, z - 3, soil, 1, 2);
		world.setBlock(x + 3, y - 7, z - 3, soil, 1, 2);
		world.setBlock(x + 3, y - 7, z + 3, soil, 1, 2);
		world.setBlock(x + 3, y - 7, z - 4, soil, 1, 2);
		world.setBlock(x - 3, y - 7, z + 4, soil, 1, 2);
		world.setBlock(x - 3, y - 7, z + 5, soil, 1, 2);
		world.setBlock(x - 3, y - 7, z + 6, soil, 1, 2);
		world.setBlock(x + 3, y - 8, z - 2, soil, 1, 2);
		world.setBlock(x + 3, y - 8, z - 3, soil, 1, 2);
		world.setBlock(x + 4, y, z, soil, 0, 2);
		world.setBlock(x - 4, y, z, soil, 0, 2);
		world.setBlock(x + 4, y, z, soil, 0, 2);
		world.setBlock(x - 4, y, z, soil, 0, 2);
		world.setBlock(x + 4, y, z, soil, 0, 2);
		world.setBlock(x - 4, y, z, soil, 0, 2);
		world.setBlock(x + 4, y, z, soil, 0, 2);
		world.setBlock(x - 4, y, z, soil, 0, 2);
		world.setBlock(x + 4, y, z + 1, soil, 0, 2);
		world.setBlock(x - 4, y, z - 1, soil, 0, 2);
		world.setBlock(x + 4, y, z - 1, soil, 0, 2);
		world.setBlock(x - 4, y, z + 1, soil, 0, 2);
		world.setBlock(x + 4, y, z - 1, soil, 0, 2);
		world.setBlock(x - 4, y, z + 1, soil, 0, 2);
		world.setBlock(x + 4, y, z + 1, soil, 0, 2);
		world.setBlock(x - 4, y, z - 1, soil, 0, 2);
		world.setBlock(x + 4, y, z + 2, soil, 0, 2);
		world.setBlock(x - 4, y, z - 2, soil, 0, 2);
		world.setBlock(x + 4, y, z - 2, soil, 0, 2);
		world.setBlock(x - 4, y, z + 2, soil, 0, 2);
		world.setBlock(x + 4, y, z - 2, soil, 0, 2);
		world.setBlock(x - 4, y, z + 2, soil, 0, 2);
		world.setBlock(x + 4, y, z + 2, soil, 0, 2);
		world.setBlock(x - 4, y, z - 2, soil, 0, 2);
		world.setBlock(x + 4, y, z + 3, soil, 0, 2);
		world.setBlock(x - 4, y, z - 3, soil, 0, 2);
		world.setBlock(x + 4, y, z - 3, soil, 0, 2);
		world.setBlock(x - 4, y, z + 3, soil, 0, 2);
		world.setBlock(x + 4, y, z - 3, soil, 0, 2);
		world.setBlock(x - 4, y, z + 3, soil, 0, 2);
		world.setBlock(x + 4, y, z + 3, soil, 0, 2);
		world.setBlock(x - 4, y, z - 3, soil, 0, 2);
		world.setBlock(x + 4, y, z + 4, soil, 0, 2);
		world.setBlock(x - 4, y, z - 4, soil, 0, 2);
		world.setBlock(x + 4, y, z - 4, soil, 0, 2);
		world.setBlock(x - 4, y, z + 4, soil, 0, 2);
		world.setBlock(x + 4, y, z - 4, soil, 0, 2);
		world.setBlock(x - 4, y, z + 4, soil, 0, 2);
		world.setBlock(x + 4, y, z + 4, soil, 0, 2);
		world.setBlock(x - 4, y, z - 4, soil, 0, 2);
		world.setBlock(x + 4, y, z + 5, soil, 0, 2);
		world.setBlock(x - 4, y, z - 5, soil, 0, 2);
		world.setBlock(x + 4, y, z - 5, soil, 0, 2);
		world.setBlock(x - 4, y, z + 5, soil, 0, 2);
		world.setBlock(x + 4, y, z - 5, soil, 0, 2);
		world.setBlock(x - 4, y, z + 5, soil, 0, 2);
		world.setBlock(x + 4, y, z + 5, soil, 0, 2);
		world.setBlock(x - 4, y, z - 5, soil, 0, 2);
		world.setBlock(x + 4, y, z + 6, soil, 0, 2);
		world.setBlock(x - 4, y, z - 6, soil, 0, 2);
		world.setBlock(x + 4, y, z - 6, soil, 0, 2);
		world.setBlock(x - 4, y, z + 6, soil, 0, 2);
		world.setBlock(x + 4, y, z - 6, soil, 0, 2);
		world.setBlock(x - 4, y, z + 6, soil, 0, 2);
		world.setBlock(x + 4, y, z + 6, soil, 0, 2);
		world.setBlock(x - 4, y, z - 6, soil, 0, 2);
		world.setBlock(x + 4, y, z + 7, soil, 0, 2);
		world.setBlock(x - 4, y, z - 7, soil, 0, 2);
		world.setBlock(x + 4, y, z - 7, soil, 0, 2);
		world.setBlock(x - 4, y, z + 7, soil, 0, 2);
		world.setBlock(x + 4, y, z - 7, soil, 0, 2);
		world.setBlock(x - 4, y, z + 7, soil, 0, 2);
		world.setBlock(x + 4, y, z + 7, soil, 0, 2);
		world.setBlock(x - 4, y, z - 7, soil, 0, 2);
		world.setBlock(x - 4, y, z - 8, soil, 0, 2);
		world.setBlock(x + 4, y, z - 8, soil, 0, 2);
		world.setBlock(x - 4, y, z + 8, soil, 0, 2);
		world.setBlock(x + 4, y, z - 8, soil, 0, 2);
		world.setBlock(x - 4, y, z + 8, soil, 0, 2);
		world.setBlock(x - 4, y, z - 8, soil, 0, 2);
		world.setBlock(x - 4, y, z - 9, soil, 0, 2);
		world.setBlock(x - 4, y, z + 9, soil, 0, 2);
		world.setBlock(x - 4, y, z + 9, soil, 0, 2);
		world.setBlock(x - 4, y, z - 9, soil, 0, 2);
		world.setBlock(x - 4, y - 1, z, soil, 1, 2);
		world.setBlock(x + 4, y - 1, z, soil, 1, 2);
		world.setBlock(x - 4, y - 1, z, soil, 1, 2);
		world.setBlock(x + 4, y - 1, z, soil, 1, 2);
		world.setBlock(x - 4, y - 1, z - 1, soil, 1, 2);
		world.setBlock(x + 4, y - 1, z - 1, soil, 1, 2);
		world.setBlock(x - 4, y - 1, z + 1, soil, 1, 2);
		world.setBlock(x + 4, y - 1, z + 1, soil, 1, 2);
		world.setBlock(x - 4, y - 1, z - 2, soil, 1, 2);
		world.setBlock(x + 4, y - 1, z - 2, soil, 1, 2);
		world.setBlock(x - 4, y - 1, z + 2, soil, 1, 2);
		world.setBlock(x + 4, y - 1, z + 2, soil, 1, 2);
		world.setBlock(x - 4, y - 1, z - 3, soil, 1, 2);
		world.setBlock(x + 4, y - 1, z - 3, soil, 1, 2);
		world.setBlock(x - 4, y - 1, z + 3, soil, 1, 2);
		world.setBlock(x + 4, y - 1, z + 3, soil, 1, 2);
		world.setBlock(x - 4, y - 1, z - 4, soil, 1, 2);
		world.setBlock(x + 4, y - 1, z - 4, soil, 1, 2);
		world.setBlock(x - 4, y - 1, z + 4, soil, 1, 2);
		world.setBlock(x + 4, y - 1, z + 4, soil, 1, 2);
		world.setBlock(x - 4, y - 1, z - 5, soil, 1, 2);
		world.setBlock(x + 4, y - 1, z - 5, soil, 1, 2);
		world.setBlock(x - 4, y - 1, z + 5, soil, 1, 2);
		world.setBlock(x + 4, y - 1, z + 5, soil, 1, 2);
		world.setBlock(x - 4, y - 1, z - 6, soil, 1, 2);
		world.setBlock(x + 4, y - 1, z - 6, soil, 1, 2);
		world.setBlock(x - 4, y - 1, z + 6, soil, 1, 2);
		world.setBlock(x + 4, y - 1, z + 6, soil, 1, 2);
		world.setBlock(x - 4, y - 1, z - 7, soil, 1, 2);
		world.setBlock(x + 4, y - 1, z - 7, soil, 1, 2);
		world.setBlock(x - 4, y - 1, z + 7, soil, 1, 2);
		world.setBlock(x + 4, y - 1, z + 7, soil, 1, 2);
		world.setBlock(x - 4, y - 1, z - 8, soil, 1, 2);
		world.setBlock(x + 4, y - 1, z - 8, soil, 1, 2);
		world.setBlock(x - 4, y - 1, z + 8, soil, 1, 2);
		world.setBlock(x - 4, y - 1, z - 9, soil, 1, 2);
		world.setBlock(x - 4, y - 1, z + 9, soil, 1, 2);
		world.setBlock(x - 4, y - 2, z, soil, 1, 2);
		world.setBlock(x + 4, y - 2, z, soil, 1, 2);
		world.setBlock(x - 4, y - 2, z, soil, 1, 2);
		world.setBlock(x + 4, y - 2, z, soil, 1, 2);
		world.setBlock(x - 4, y - 2, z - 1, soil, 1, 2);
		world.setBlock(x + 4, y - 2, z - 1, soil, 1, 2);
		world.setBlock(x - 4, y - 2, z + 1, soil, 1, 2);
		world.setBlock(x + 4, y - 2, z + 1, soil, 1, 2);
		world.setBlock(x - 4, y - 2, z - 2, soil, 1, 2);
		world.setBlock(x + 4, y - 2, z - 2, soil, 1, 2);
		world.setBlock(x - 4, y - 2, z + 2, soil, 1, 2);
		world.setBlock(x + 4, y - 2, z + 2, soil, 1, 2);
		world.setBlock(x - 4, y - 2, z - 3, soil, 1, 2);
		world.setBlock(x + 4, y - 2, z - 3, soil, 1, 2);
		world.setBlock(x - 4, y - 2, z + 3, soil, 1, 2);
		world.setBlock(x + 4, y - 2, z + 3, soil, 1, 2);
		world.setBlock(x - 4, y - 2, z - 4, soil, 1, 2);
		world.setBlock(x + 4, y - 2, z - 4, soil, 1, 2);
		world.setBlock(x - 4, y - 2, z + 4, soil, 1, 2);
		world.setBlock(x + 4, y - 2, z + 4, soil, 1, 2);
		world.setBlock(x - 4, y - 2, z - 5, soil, 1, 2);
		world.setBlock(x + 4, y - 2, z - 5, soil, 1, 2);
		world.setBlock(x - 4, y - 2, z + 5, soil, 1, 2);
		world.setBlock(x + 4, y - 2, z + 5, soil, 1, 2);
		world.setBlock(x - 4, y - 2, z - 6, soil, 1, 2);
		world.setBlock(x + 4, y - 2, z - 6, soil, 1, 2);
		world.setBlock(x - 4, y - 2, z + 6, soil, 1, 2);
		world.setBlock(x + 4, y - 2, z + 6, soil, 1, 2);
		world.setBlock(x - 4, y - 2, z - 7, soil, 1, 2);
		world.setBlock(x + 4, y - 2, z - 7, soil, 1, 2);
		world.setBlock(x - 4, y - 2, z + 7, soil, 1, 2);
		world.setBlock(x + 4, y - 2, z + 7, soil, 1, 2);
		world.setBlock(x - 4, y - 2, z + 8, soil, 1, 2);
		world.setBlock(x + 4, y - 2, z + 8, soil, 0, 2);
		world.setBlock(x - 4, y - 2, z + 9, soil, 1, 2);
		world.setBlock(x - 4, y - 3, z, soil, 1, 2);
		world.setBlock(x + 4, y - 3, z, soil, 1, 2);
		world.setBlock(x - 4, y - 3, z, soil, 1, 2);
		world.setBlock(x + 4, y - 3, z, soil, 1, 2);
		world.setBlock(x - 4, y - 3, z - 1, soil, 1, 2);
		world.setBlock(x + 4, y - 3, z - 1, soil, 1, 2);
		world.setBlock(x - 4, y - 3, z + 1, soil, 1, 2);
		world.setBlock(x + 4, y - 3, z + 1, soil, 1, 2);
		world.setBlock(x - 4, y - 3, z - 2, soil, 1, 2);
		world.setBlock(x + 4, y - 3, z - 2, soil, 1, 2);
		world.setBlock(x - 4, y - 3, z + 2, soil, 1, 2);
		world.setBlock(x + 4, y - 3, z + 2, soil, 1, 2);
		world.setBlock(x - 4, y - 3, z - 3, soil, 1, 2);
		world.setBlock(x + 4, y - 3, z - 3, soil, 1, 2);
		world.setBlock(x - 4, y - 3, z + 3, soil, 1, 2);
		world.setBlock(x + 4, y - 3, z + 3, soil, 1, 2);
		world.setBlock(x - 4, y - 3, z - 4, soil, 1, 2);
		world.setBlock(x + 4, y - 3, z - 4, soil, 1, 2);
		world.setBlock(x - 4, y - 3, z + 4, soil, 1, 2);
		world.setBlock(x + 4, y - 3, z + 4, soil, 1, 2);
		world.setBlock(x - 4, y - 3, z - 5, soil, 1, 2);
		world.setBlock(x + 4, y - 3, z - 5, soil, 1, 2);
		world.setBlock(x - 4, y - 3, z + 5, soil, 1, 2);
		world.setBlock(x + 4, y - 3, z + 5, soil, 1, 2);
		world.setBlock(x - 4, y - 3, z - 6, soil, 1, 2);
		world.setBlock(x + 4, y - 3, z - 6, soil, 1, 2);
		world.setBlock(x - 4, y - 3, z + 6, soil, 1, 2);
		world.setBlock(x + 4, y - 3, z + 6, soil, 1, 2);
		world.setBlock(x - 4, y - 3, z + 7, soil, 1, 2);
		world.setBlock(x + 4, y - 3, z + 7, soil, 1, 2);
		world.setBlock(x - 4, y - 3, z + 8, soil, 1, 2);
		world.setBlock(x + 4, y - 3, z + 8, soil, 1, 2);
		world.setBlock(x - 4, y - 4, z, soil, 1, 2);
		world.setBlock(x + 4, y - 4, z, soil, 1, 2);
		world.setBlock(x - 4, y - 4, z, soil, 1, 2);
		world.setBlock(x + 4, y - 4, z, soil, 1, 2);
		world.setBlock(x - 4, y - 4, z - 1, soil, 1, 2);
		world.setBlock(x + 4, y - 4, z - 1, soil, 1, 2);
		world.setBlock(x - 4, y - 4, z + 1, soil, 1, 2);
		world.setBlock(x + 4, y - 4, z + 1, soil, 1, 2);
		world.setBlock(x - 4, y - 4, z - 2, soil, 1, 2);
		world.setBlock(x + 4, y - 4, z - 2, soil, 1, 2);
		world.setBlock(x - 4, y - 4, z + 2, soil, 1, 2);
		world.setBlock(x + 4, y - 4, z + 2, soil, 1, 2);
		world.setBlock(x - 4, y - 4, z - 3, soil, 1, 2);
		world.setBlock(x + 4, y - 4, z - 3, soil, 1, 2);
		world.setBlock(x - 4, y - 4, z + 3, soil, 1, 2);
		world.setBlock(x + 4, y - 4, z + 3, soil, 1, 2);
		world.setBlock(x - 4, y - 4, z - 4, soil, 1, 2);
		world.setBlock(x + 4, y - 4, z - 4, soil, 1, 2);
		world.setBlock(x - 4, y - 4, z + 4, soil, 1, 2);
		world.setBlock(x + 4, y - 4, z + 4, soil, 1, 2);
		world.setBlock(x - 4, y - 4, z - 5, soil, 1, 2);
		world.setBlock(x + 4, y - 4, z - 5, soil, 1, 2);
		world.setBlock(x - 4, y - 4, z + 5, soil, 1, 2);
		world.setBlock(x + 4, y - 4, z + 5, soil, 1, 2);
		world.setBlock(x - 4, y - 4, z - 6, soil, 1, 2);
		world.setBlock(x + 4, y - 4, z - 6, soil, 1, 2);
		world.setBlock(x - 4, y - 4, z + 6, soil, 1, 2);
		world.setBlock(x + 4, y - 4, z + 6, soil, 1, 2);
		world.setBlock(x - 4, y - 4, z + 7, soil, 1, 2);
		world.setBlock(x - 4, y - 5, z, soil, 1, 2);
		world.setBlock(x + 4, y - 5, z, soil, 1, 2);
		world.setBlock(x - 4, y - 5, z, soil, 1, 2);
		world.setBlock(x + 4, y - 5, z, soil, 1, 2);
		world.setBlock(x - 4, y - 5, z - 1, soil, 1, 2);
		world.setBlock(x + 4, y - 5, z - 1, soil, 1, 2);
		world.setBlock(x - 4, y - 5, z + 1, soil, 1, 2);
		world.setBlock(x + 4, y - 5, z + 1, soil, 1, 2);
		world.setBlock(x - 4, y - 5, z - 2, soil, 1, 2);
		world.setBlock(x + 4, y - 5, z - 2, soil, 1, 2);
		world.setBlock(x - 4, y - 5, z + 2, soil, 1, 2);
		world.setBlock(x + 4, y - 5, z + 2, soil, 1, 2);
		world.setBlock(x - 4, y - 5, z - 3, soil, 1, 2);
		world.setBlock(x + 4, y - 5, z - 3, soil, 1, 2);
		world.setBlock(x - 4, y - 5, z + 3, soil, 1, 2);
		world.setBlock(x + 4, y - 5, z + 3, soil, 1, 2);
		world.setBlock(x - 4, y - 5, z - 4, soil, 1, 2);
		world.setBlock(x + 4, y - 5, z - 4, soil, 1, 2);
		world.setBlock(x - 4, y - 5, z + 4, soil, 1, 2);
		world.setBlock(x + 4, y - 5, z + 4, soil, 1, 2);
		world.setBlock(x - 4, y - 5, z - 5, soil, 1, 2);
		world.setBlock(x + 4, y - 5, z - 5, soil, 1, 2);
		world.setBlock(x - 4, y - 5, z + 5, soil, 1, 2);
		world.setBlock(x + 4, y - 5, z + 5, soil, 1, 2);
		world.setBlock(x - 4, y - 5, z + 6, soil, 1, 2);
		world.setBlock(x + 4, y - 5, z + 6, soil, 1, 2);
		world.setBlock(x - 4, y - 5, z + 7, soil, 1, 2);
		world.setBlock(x - 4, y - 6, z, soil, 1, 2);
		world.setBlock(x + 4, y - 6, z, soil, 1, 2);
		world.setBlock(x - 4, y - 6, z, soil, 1, 2);
		world.setBlock(x + 4, y - 6, z, soil, 1, 2);
		world.setBlock(x - 4, y - 6, z - 1, soil, 1, 2);
		world.setBlock(x + 4, y - 6, z - 1, soil, 1, 2);
		world.setBlock(x - 4, y - 6, z + 1, soil, 1, 2);
		world.setBlock(x + 4, y - 6, z + 1, soil, 1, 2);
		world.setBlock(x - 4, y - 6, z - 2, soil, 1, 2);
		world.setBlock(x + 4, y - 6, z - 2, soil, 1, 2);
		world.setBlock(x - 4, y - 6, z + 2, soil, 1, 2);
		world.setBlock(x + 4, y - 6, z + 2, soil, 1, 2);
		world.setBlock(x - 4, y - 6, z - 3, soil, 1, 2);
		world.setBlock(x + 4, y - 6, z - 3, soil, 1, 2);
		world.setBlock(x + 4, y - 6, z + 3, soil, 1, 2);
		world.setBlock(x - 4, y - 6, z - 4, soil, 1, 2);
		world.setBlock(x + 4, y - 6, z - 4, soil, 1, 2);
		world.setBlock(x - 4, y - 6, z + 4, soil, 1, 2);
		world.setBlock(x + 4, y - 6, z + 4, soil, 1, 2);
		world.setBlock(x - 4, y - 6, z + 5, soil, 1, 2);
		world.setBlock(x + 4, y - 6, z + 5, soil, 1, 2);
		world.setBlock(x - 4, y - 6, z + 6, soil, 1, 2);
		world.setBlock(x - 4, y - 7, z, soil, 1, 2);
		world.setBlock(x + 4, y - 7, z, soil, 1, 2);
		world.setBlock(x - 4, y - 7, z, soil, 1, 2);
		world.setBlock(x + 4, y - 7, z, soil, 1, 2);
		world.setBlock(x + 4, y - 7, z - 1, soil, 1, 2);
		world.setBlock(x - 4, y - 7, z + 1, soil, 1, 2);
		world.setBlock(x + 4, y - 7, z + 1, soil, 1, 2);
		world.setBlock(x - 4, y - 7, z - 2, soil, 1, 2);
		world.setBlock(x + 4, y - 7, z - 2, soil, 1, 2);
		world.setBlock(x + 4, y - 7, z + 2, soil, 1, 2);
		world.setBlock(x - 4, y - 7, z - 3, soil, 1, 2);
		world.setBlock(x + 4, y - 7, z - 3, soil, 1, 2);
		world.setBlock(x + 4, y - 7, z - 4, soil, 1, 2);
		world.setBlock(x - 4, y - 7, z + 4, soil, 1, 2);
		world.setBlock(x - 4, y - 7, z + 5, soil, 1, 2);
		world.setBlock(x - 4, y - 7, z + 6, soil, 1, 2);
		world.setBlock(x + 5, y, z, soil, 0, 2);
		world.setBlock(x - 5, y, z, soil, 0, 2);
		world.setBlock(x + 5, y, z, soil, 0, 2);
		world.setBlock(x - 5, y, z, soil, 0, 2);
		world.setBlock(x + 5, y, z, soil, 0, 2);
		world.setBlock(x - 5, y, z, soil, 0, 2);
		world.setBlock(x + 5, y, z, soil, 0, 2);
		world.setBlock(x - 5, y, z, soil, 0, 2);
		world.setBlock(x + 5, y, z + 1, soil, 0, 2);
		world.setBlock(x - 5, y, z - 1, soil, 0, 2);
		world.setBlock(x + 5, y, z - 1, soil, 0, 2);
		world.setBlock(x - 5, y, z + 1, soil, 0, 2);
		world.setBlock(x + 5, y, z - 1, soil, 0, 2);
		world.setBlock(x - 5, y, z + 1, soil, 0, 2);
		world.setBlock(x + 5, y, z + 1, soil, 0, 2);
		world.setBlock(x - 5, y, z - 1, soil, 0, 2);
		world.setBlock(x + 5, y, z + 2, soil, 0, 2);
		world.setBlock(x - 5, y, z - 2, soil, 0, 2);
		world.setBlock(x + 5, y, z - 2, soil, 0, 2);
		world.setBlock(x - 5, y, z + 2, soil, 0, 2);
		world.setBlock(x + 5, y, z - 2, soil, 0, 2);
		world.setBlock(x - 5, y, z + 2, soil, 0, 2);
		world.setBlock(x + 5, y, z + 2, soil, 0, 2);
		world.setBlock(x - 5, y, z - 2, soil, 0, 2);
		world.setBlock(x + 5, y, z + 3, soil, 0, 2);
		world.setBlock(x - 5, y, z - 3, soil, 0, 2);
		world.setBlock(x + 5, y, z - 3, soil, 0, 2);
		world.setBlock(x - 5, y, z + 3, soil, 0, 2);
		world.setBlock(x + 5, y, z - 3, soil, 0, 2);
		world.setBlock(x - 5, y, z + 3, soil, 0, 2);
		world.setBlock(x + 5, y, z + 3, soil, 0, 2);
		world.setBlock(x - 5, y, z - 3, soil, 0, 2);
		world.setBlock(x + 5, y, z + 4, soil, 0, 2);
		world.setBlock(x - 5, y, z - 4, soil, 0, 2);
		world.setBlock(x + 5, y, z - 4, soil, 0, 2);
		world.setBlock(x - 5, y, z + 4, soil, 0, 2);
		world.setBlock(x + 5, y, z - 4, soil, 0, 2);
		world.setBlock(x - 5, y, z + 4, soil, 0, 2);
		world.setBlock(x + 5, y, z + 4, soil, 0, 2);
		world.setBlock(x - 5, y, z - 4, soil, 0, 2);
		world.setBlock(x + 5, y, z + 5, soil, 0, 2);
		world.setBlock(x - 5, y, z - 5, soil, 0, 2);
		world.setBlock(x + 5, y, z - 5, soil, 0, 2);
		world.setBlock(x - 5, y, z + 5, soil, 0, 2);
		world.setBlock(x + 5, y, z - 5, soil, 0, 2);
		world.setBlock(x - 5, y, z + 5, soil, 0, 2);
		world.setBlock(x + 5, y, z + 5, soil, 0, 2);
		world.setBlock(x - 5, y, z - 5, soil, 0, 2);
		world.setBlock(x + 5, y, z + 6, soil, 0, 2);
		world.setBlock(x - 5, y, z - 6, soil, 0, 2);
		world.setBlock(x + 5, y, z - 6, soil, 0, 2);
		world.setBlock(x - 5, y, z + 6, soil, 0, 2);
		world.setBlock(x + 5, y, z - 6, soil, 0, 2);
		world.setBlock(x - 5, y, z + 6, soil, 0, 2);
		world.setBlock(x + 5, y, z + 6, soil, 0, 2);
		world.setBlock(x - 5, y, z - 6, soil, 0, 2);
		world.setBlock(x - 5, y, z - 7, soil, 0, 2);
		world.setBlock(x + 5, y, z - 7, soil, 0, 2);
		world.setBlock(x - 5, y, z + 7, soil, 0, 2);
		world.setBlock(x + 5, y, z - 7, soil, 0, 2);
		world.setBlock(x - 5, y, z + 7, soil, 0, 2);
		world.setBlock(x - 5, y, z - 7, soil, 0, 2);
		world.setBlock(x + 5, y, z - 8, soil, 0, 2);
		world.setBlock(x - 5, y, z + 8, soil, 0, 2);
		world.setBlock(x + 5, y, z - 8, soil, 0, 2);
		world.setBlock(x - 5, y, z + 8, soil, 0, 2);
		world.setBlock(x - 5, y - 1, z, soil, 1, 2);
		world.setBlock(x + 5, y - 1, z, soil, 1, 2);
		world.setBlock(x - 5, y - 1, z, soil, 1, 2);
		world.setBlock(x + 5, y - 1, z, soil, 1, 2);
		world.setBlock(x - 5, y - 1, z - 1, soil, 1, 2);
		world.setBlock(x + 5, y - 1, z - 1, soil, 1, 2);
		world.setBlock(x - 5, y - 1, z + 1, soil, 1, 2);
		world.setBlock(x + 5, y - 1, z + 1, soil, 1, 2);
		world.setBlock(x - 5, y - 1, z - 2, soil, 1, 2);
		world.setBlock(x + 5, y - 1, z - 2, soil, 1, 2);
		world.setBlock(x - 5, y - 1, z + 2, soil, 1, 2);
		world.setBlock(x + 5, y - 1, z + 2, soil, 1, 2);
		world.setBlock(x - 5, y - 1, z - 3, soil, 1, 2);
		world.setBlock(x + 5, y - 1, z - 3, soil, 1, 2);
		world.setBlock(x - 5, y - 1, z + 3, soil, 1, 2);
		world.setBlock(x + 5, y - 1, z + 3, soil, 1, 2);
		world.setBlock(x - 5, y - 1, z - 4, soil, 1, 2);
		world.setBlock(x + 5, y - 1, z - 4, soil, 1, 2);
		world.setBlock(x - 5, y - 1, z + 4, soil, 1, 2);
		world.setBlock(x + 5, y - 1, z + 4, soil, 1, 2);
		world.setBlock(x - 5, y - 1, z - 5, soil, 1, 2);
		world.setBlock(x + 5, y - 1, z - 5, soil, 1, 2);
		world.setBlock(x - 5, y - 1, z + 5, soil, 1, 2);
		world.setBlock(x + 5, y - 1, z + 5, soil, 1, 2);
		world.setBlock(x - 5, y - 1, z - 6, soil, 1, 2);
		world.setBlock(x + 5, y - 1, z - 6, soil, 1, 2);
		world.setBlock(x - 5, y - 1, z + 6, soil, 1, 2);
		world.setBlock(x + 5, y - 1, z + 6, soil, 1, 2);
		world.setBlock(x - 5, y - 1, z - 7, soil, 1, 2);
		world.setBlock(x + 5, y - 1, z - 7, soil, 1, 2);
		world.setBlock(x - 5, y - 1, z + 7, soil, 1, 2);
		world.setBlock(x + 5, y - 1, z + 7, soil, 0, 2);
		world.setBlock(x + 5, y - 1, z - 8, soil, 1, 2);
		world.setBlock(x - 5, y - 1, z + 8, soil, 1, 2);
		world.setBlock(x - 5, y - 1, z + 9, soil, 0, 2);
		world.setBlock(x - 5, y - 2, z, soil, 1, 2);
		world.setBlock(x + 5, y - 2, z, soil, 1, 2);
		world.setBlock(x - 5, y - 2, z, soil, 1, 2);
		world.setBlock(x + 5, y - 2, z, soil, 1, 2);
		world.setBlock(x - 5, y - 2, z - 1, soil, 1, 2);
		world.setBlock(x + 5, y - 2, z - 1, soil, 1, 2);
		world.setBlock(x - 5, y - 2, z + 1, soil, 1, 2);
		world.setBlock(x + 5, y - 2, z + 1, soil, 1, 2);
		world.setBlock(x - 5, y - 2, z - 2, soil, 1, 2);
		world.setBlock(x + 5, y - 2, z - 2, soil, 1, 2);
		world.setBlock(x - 5, y - 2, z + 2, soil, 1, 2);
		world.setBlock(x + 5, y - 2, z + 2, soil, 1, 2);
		world.setBlock(x - 5, y - 2, z - 3, soil, 1, 2);
		world.setBlock(x + 5, y - 2, z - 3, soil, 1, 2);
		world.setBlock(x - 5, y - 2, z + 3, soil, 1, 2);
		world.setBlock(x + 5, y - 2, z + 3, soil, 1, 2);
		world.setBlock(x - 5, y - 2, z - 4, soil, 1, 2);
		world.setBlock(x + 5, y - 2, z - 4, soil, 1, 2);
		world.setBlock(x - 5, y - 2, z + 4, soil, 1, 2);
		world.setBlock(x + 5, y - 2, z + 4, soil, 1, 2);
		world.setBlock(x - 5, y - 2, z - 5, soil, 1, 2);
		world.setBlock(x + 5, y - 2, z - 5, soil, 1, 2);
		world.setBlock(x - 5, y - 2, z + 5, soil, 1, 2);
		world.setBlock(x + 5, y - 2, z + 5, soil, 1, 2);
		world.setBlock(x - 5, y - 2, z - 6, soil, 1, 2);
		world.setBlock(x + 5, y - 2, z - 6, soil, 1, 2);
		world.setBlock(x - 5, y - 2, z + 6, soil, 1, 2);
		world.setBlock(x + 5, y - 2, z + 6, soil, 1, 2);
		world.setBlock(x - 5, y - 2, z - 7, soil, 1, 2);
		world.setBlock(x + 5, y - 2, z - 7, soil, 1, 2);
		world.setBlock(x - 5, y - 2, z + 7, soil, 1, 2);
		world.setBlock(x + 5, y - 2, z + 7, soil, 1, 2);
		world.setBlock(x - 5, y - 2, z + 8, soil, 1, 2);
		world.setBlock(x + 5, y - 2, z + 8, soil, 0, 2);
		world.setBlock(x - 5, y - 2, z + 9, soil, 1, 2);
		world.setBlock(x - 5, y - 3, z, soil, 1, 2);
		world.setBlock(x + 5, y - 3, z, soil, 1, 2);
		world.setBlock(x - 5, y - 3, z, soil, 1, 2);
		world.setBlock(x + 5, y - 3, z, soil, 1, 2);
		world.setBlock(x - 5, y - 3, z - 1, soil, 1, 2);
		world.setBlock(x + 5, y - 3, z - 1, soil, 1, 2);
		world.setBlock(x - 5, y - 3, z + 1, soil, 1, 2);
		world.setBlock(x + 5, y - 3, z + 1, soil, 1, 2);
		world.setBlock(x - 5, y - 3, z - 2, soil, 1, 2);
		world.setBlock(x + 5, y - 3, z - 2, soil, 1, 2);
		world.setBlock(x - 5, y - 3, z + 2, soil, 1, 2);
		world.setBlock(x + 5, y - 3, z + 2, soil, 1, 2);
		world.setBlock(x - 5, y - 3, z - 3, soil, 1, 2);
		world.setBlock(x + 5, y - 3, z - 3, soil, 1, 2);
		world.setBlock(x - 5, y - 3, z + 3, soil, 1, 2);
		world.setBlock(x + 5, y - 3, z + 3, soil, 1, 2);
		world.setBlock(x - 5, y - 3, z - 4, soil, 1, 2);
		world.setBlock(x + 5, y - 3, z - 4, soil, 1, 2);
		world.setBlock(x - 5, y - 3, z + 4, soil, 1, 2);
		world.setBlock(x + 5, y - 3, z + 4, soil, 1, 2);
		world.setBlock(x - 5, y - 3, z - 5, soil, 1, 2);
		world.setBlock(x + 5, y - 3, z - 5, soil, 1, 2);
		world.setBlock(x - 5, y - 3, z + 5, soil, 1, 2);
		world.setBlock(x + 5, y - 3, z + 5, soil, 1, 2);
		world.setBlock(x - 5, y - 3, z - 6, soil, 1, 2);
		world.setBlock(x - 5, y - 3, z + 6, soil, 1, 2);
		world.setBlock(x + 5, y - 3, z + 6, soil, 1, 2);
		world.setBlock(x - 5, y - 3, z + 7, soil, 1, 2);
		world.setBlock(x + 5, y - 3, z + 7, soil, 1, 2);
		world.setBlock(x - 5, y - 3, z + 8, soil, 1, 2);
		world.setBlock(x + 5, y - 3, z + 8, soil, 1, 2);
		world.setBlock(x - 5, y - 4, z, soil, 1, 2);
		world.setBlock(x + 5, y - 4, z, soil, 1, 2);
		world.setBlock(x - 5, y - 4, z, soil, 1, 2);
		world.setBlock(x + 5, y - 4, z, soil, 1, 2);
		world.setBlock(x - 5, y - 4, z - 1, soil, 1, 2);
		world.setBlock(x + 5, y - 4, z - 1, soil, 1, 2);
		world.setBlock(x - 5, y - 4, z + 1, soil, 1, 2);
		world.setBlock(x + 5, y - 4, z + 1, soil, 1, 2);
		world.setBlock(x - 5, y - 4, z - 2, soil, 1, 2);
		world.setBlock(x + 5, y - 4, z - 2, soil, 1, 2);
		world.setBlock(x - 5, y - 4, z + 2, soil, 1, 2);
		world.setBlock(x + 5, y - 4, z + 2, soil, 1, 2);
		world.setBlock(x - 5, y - 4, z - 3, soil, 1, 2);
		world.setBlock(x + 5, y - 4, z - 3, soil, 1, 2);
		world.setBlock(x - 5, y - 4, z + 3, soil, 1, 2);
		world.setBlock(x + 5, y - 4, z + 3, soil, 1, 2);
		world.setBlock(x - 5, y - 4, z - 4, soil, 1, 2);
		world.setBlock(x + 5, y - 4, z - 4, soil, 1, 2);
		world.setBlock(x - 5, y - 4, z + 4, soil, 1, 2);
		world.setBlock(x + 5, y - 4, z + 4, soil, 1, 2);
		world.setBlock(x - 5, y - 4, z - 5, soil, 1, 2);
		world.setBlock(x + 5, y - 4, z - 5, soil, 1, 2);
		world.setBlock(x - 5, y - 4, z + 5, soil, 1, 2);
		world.setBlock(x + 5, y - 4, z + 5, soil, 1, 2);
		world.setBlock(x - 5, y - 4, z + 6, soil, 1, 2);
		world.setBlock(x + 5, y - 4, z + 6, soil, 1, 2);
		world.setBlock(x + 5, y - 4, z + 7, soil, 1, 2);
		world.setBlock(x - 5, y - 5, z, soil, 1, 2);
		world.setBlock(x + 5, y - 5, z, soil, 1, 2);
		world.setBlock(x - 5, y - 5, z, soil, 1, 2);
		world.setBlock(x + 5, y - 5, z, soil, 1, 2);
		world.setBlock(x - 5, y - 5, z - 1, soil, 1, 2);
		world.setBlock(x + 5, y - 5, z - 1, soil, 1, 2);
		world.setBlock(x - 5, y - 5, z + 1, soil, 1, 2);
		world.setBlock(x + 5, y - 5, z + 1, soil, 1, 2);
		world.setBlock(x - 5, y - 5, z - 2, soil, 1, 2);
		world.setBlock(x + 5, y - 5, z - 2, soil, 1, 2);
		world.setBlock(x - 5, y - 5, z + 2, soil, 1, 2);
		world.setBlock(x + 5, y - 5, z + 2, soil, 1, 2);
		world.setBlock(x - 5, y - 5, z - 3, soil, 1, 2);
		world.setBlock(x + 5, y - 5, z - 3, soil, 1, 2);
		world.setBlock(x - 5, y - 5, z + 3, soil, 1, 2);
		world.setBlock(x + 5, y - 5, z + 3, soil, 1, 2);
		world.setBlock(x - 5, y - 5, z - 4, soil, 1, 2);
		world.setBlock(x + 5, y - 5, z - 4, soil, 1, 2);
		world.setBlock(x - 5, y - 5, z + 4, soil, 1, 2);
		world.setBlock(x + 5, y - 5, z + 4, soil, 1, 2);
		world.setBlock(x - 5, y - 5, z - 5, soil, 1, 2);
		world.setBlock(x + 5, y - 5, z - 5, soil, 1, 2);
		world.setBlock(x - 5, y - 5, z + 5, soil, 1, 2);
		world.setBlock(x + 5, y - 5, z + 5, soil, 1, 2);
		world.setBlock(x + 5, y - 5, z + 6, soil, 1, 2);
		world.setBlock(x - 5, y - 6, z, soil, 1, 2);
		world.setBlock(x + 5, y - 6, z, soil, 1, 2);
		world.setBlock(x - 5, y - 6, z, soil, 1, 2);
		world.setBlock(x + 5, y - 6, z, soil, 1, 2);
		world.setBlock(x + 5, y - 6, z - 1, soil, 1, 2);
		world.setBlock(x - 5, y - 6, z + 1, soil, 1, 2);
		world.setBlock(x + 5, y - 6, z + 1, soil, 1, 2);
		world.setBlock(x + 5, y - 6, z - 2, soil, 1, 2);
		world.setBlock(x - 5, y - 6, z + 2, soil, 1, 2);
		world.setBlock(x + 5, y - 6, z + 2, soil, 1, 2);
		world.setBlock(x + 5, y - 6, z + 3, soil, 1, 2);
		world.setBlock(x + 5, y - 6, z + 4, soil, 1, 2);
		world.setBlock(x + 5, y - 6, z + 5, soil, 1, 2);
		world.setBlock(x - 5, y - 7, z, soil, 1, 2);
		world.setBlock(x + 5, y - 7, z, soil, 1, 2);
		world.setBlock(x - 5, y - 7, z, soil, 1, 2);
		world.setBlock(x + 5, y - 7, z, soil, 1, 2);
		world.setBlock(x + 5, y - 7, z - 1, soil, 1, 2);
		world.setBlock(x - 5, y - 7, z + 1, soil, 1, 2);
		world.setBlock(x + 5, y - 7, z + 1, soil, 1, 2);
		world.setBlock(x + 5, y - 7, z - 2, soil, 1, 2);
		world.setBlock(x + 5, y - 7, z + 2, soil, 1, 2);
		world.setBlock(x + 5, y - 8, z + 1, soil, 1, 2);
		world.setBlock(x + 5, y - 8, z + 2, soil, 1, 2);
		world.setBlock(x + 6, y, z, soil, 0, 2);
		world.setBlock(x - 6, y, z, soil, 0, 2);
		world.setBlock(x + 6, y, z, soil, 0, 2);
		world.setBlock(x - 6, y, z, soil, 0, 2);
		world.setBlock(x + 6, y, z, soil, 0, 2);
		world.setBlock(x - 6, y, z, soil, 0, 2);
		world.setBlock(x + 6, y, z, soil, 0, 2);
		world.setBlock(x - 6, y, z, soil, 0, 2);
		world.setBlock(x + 6, y, z + 1, soil, 0, 2);
		world.setBlock(x - 6, y, z - 1, soil, 0, 2);
		world.setBlock(x + 6, y, z - 1, soil, 0, 2);
		world.setBlock(x - 6, y, z + 1, soil, 0, 2);
		world.setBlock(x + 6, y, z - 1, soil, 0, 2);
		world.setBlock(x - 6, y, z + 1, soil, 0, 2);
		world.setBlock(x + 6, y, z + 1, soil, 0, 2);
		world.setBlock(x - 6, y, z - 1, soil, 0, 2);
		world.setBlock(x + 6, y, z + 2, soil, 0, 2);
		world.setBlock(x - 6, y, z - 2, soil, 0, 2);
		world.setBlock(x + 6, y, z - 2, soil, 0, 2);
		world.setBlock(x - 6, y, z + 2, soil, 0, 2);
		world.setBlock(x + 6, y, z - 2, soil, 0, 2);
		world.setBlock(x - 6, y, z + 2, soil, 0, 2);
		world.setBlock(x + 6, y, z + 2, soil, 0, 2);
		world.setBlock(x - 6, y, z - 2, soil, 0, 2);
		world.setBlock(x + 6, y, z + 3, soil, 0, 2);
		world.setBlock(x - 6, y, z - 3, soil, 0, 2);
		world.setBlock(x + 6, y, z - 3, soil, 0, 2);
		world.setBlock(x - 6, y, z + 3, soil, 0, 2);
		world.setBlock(x + 6, y, z - 3, soil, 0, 2);
		world.setBlock(x - 6, y, z + 3, soil, 0, 2);
		world.setBlock(x + 6, y, z + 3, soil, 0, 2);
		world.setBlock(x - 6, y, z - 3, soil, 0, 2);
		world.setBlock(x + 6, y, z + 4, soil, 0, 2);
		world.setBlock(x - 6, y, z - 4, soil, 0, 2);
		world.setBlock(x + 6, y, z - 4, soil, 0, 2);
		world.setBlock(x - 6, y, z + 4, soil, 0, 2);
		world.setBlock(x + 6, y, z - 4, soil, 0, 2);
		world.setBlock(x - 6, y, z + 4, soil, 0, 2);
		world.setBlock(x + 6, y, z + 4, soil, 0, 2);
		world.setBlock(x - 6, y, z - 4, soil, 0, 2);
		world.setBlock(x + 6, y, z + 5, soil, 0, 2);
		world.setBlock(x - 6, y, z - 5, soil, 0, 2);
		world.setBlock(x + 6, y, z - 5, soil, 0, 2);
		world.setBlock(x - 6, y, z + 5, soil, 0, 2);
		world.setBlock(x + 6, y, z - 5, soil, 0, 2);
		world.setBlock(x - 6, y, z + 5, soil, 0, 2);
		world.setBlock(x + 6, y, z + 5, soil, 0, 2);
		world.setBlock(x - 6, y, z - 5, soil, 0, 2);
		world.setBlock(x - 6, y, z - 6, soil, 0, 2);
		world.setBlock(x + 6, y, z - 6, soil, 0, 2);
		world.setBlock(x - 6, y, z + 6, soil, 0, 2);
		world.setBlock(x + 6, y, z - 6, soil, 0, 2);
		world.setBlock(x - 6, y, z + 6, soil, 0, 2);
		world.setBlock(x - 6, y, z - 6, soil, 0, 2);
		world.setBlock(x + 6, y, z - 7, soil, 0, 2);
		world.setBlock(x - 6, y, z + 7, soil, 0, 2);
		world.setBlock(x + 6, y, z - 7, soil, 0, 2);
		world.setBlock(x - 6, y, z + 7, soil, 0, 2);
		world.setBlock(x - 6, y, z + 8, soil, 0, 2);
		world.setBlock(x - 6, y, z + 8, soil, 0, 2);
		world.setBlock(x - 6, y - 1, z, soil, 1, 2);
		world.setBlock(x + 6, y - 1, z, soil, 1, 2);
		world.setBlock(x - 6, y - 1, z, soil, 1, 2);
		world.setBlock(x + 6, y - 1, z, soil, 1, 2);
		world.setBlock(x - 6, y - 1, z - 1, soil, 1, 2);
		world.setBlock(x + 6, y - 1, z - 1, soil, 1, 2);
		world.setBlock(x - 6, y - 1, z + 1, soil, 1, 2);
		world.setBlock(x + 6, y - 1, z + 1, soil, 1, 2);
		world.setBlock(x - 6, y - 1, z - 2, soil, 1, 2);
		world.setBlock(x + 6, y - 1, z - 2, soil, 1, 2);
		world.setBlock(x - 6, y - 1, z + 2, soil, 1, 2);
		world.setBlock(x + 6, y - 1, z + 2, soil, 1, 2);
		world.setBlock(x - 6, y - 1, z - 3, soil, 1, 2);
		world.setBlock(x + 6, y - 1, z - 3, soil, 1, 2);
		world.setBlock(x - 6, y - 1, z + 3, soil, 1, 2);
		world.setBlock(x + 6, y - 1, z + 3, soil, 1, 2);
		world.setBlock(x - 6, y - 1, z - 4, soil, 1, 2);
		world.setBlock(x + 6, y - 1, z - 4, soil, 1, 2);
		world.setBlock(x - 6, y - 1, z + 4, soil, 1, 2);
		world.setBlock(x + 6, y - 1, z + 4, soil, 1, 2);
		world.setBlock(x - 6, y - 1, z - 5, soil, 1, 2);
		world.setBlock(x + 6, y - 1, z - 5, soil, 1, 2);
		world.setBlock(x - 6, y - 1, z + 5, soil, 1, 2);
		world.setBlock(x + 6, y - 1, z + 5, soil, 1, 2);
		world.setBlock(x - 6, y - 1, z - 6, soil, 1, 2);
		world.setBlock(x + 6, y - 1, z - 6, soil, 1, 2);
		world.setBlock(x - 6, y - 1, z + 6, soil, 1, 2);
		world.setBlock(x + 6, y - 1, z + 6, soil, 0, 2);
		world.setBlock(x - 6, y - 1, z - 7, soil, 0, 2);
		world.setBlock(x + 6, y - 1, z - 7, soil, 1, 2);
		world.setBlock(x - 6, y - 1, z + 7, soil, 1, 2);
		world.setBlock(x + 6, y - 1, z + 7, soil, 0, 2);
		world.setBlock(x - 6, y - 1, z + 8, soil, 1, 2);
		world.setBlock(x - 6, y - 1, z + 9, soil, 0, 2);
		world.setBlock(x - 6, y - 2, z, soil, 1, 2);
		world.setBlock(x + 6, y - 2, z, soil, 1, 2);
		world.setBlock(x - 6, y - 2, z, soil, 1, 2);
		world.setBlock(x + 6, y - 2, z, soil, 1, 2);
		world.setBlock(x - 6, y - 2, z - 1, soil, 1, 2);
		world.setBlock(x + 6, y - 2, z - 1, soil, 1, 2);
		world.setBlock(x - 6, y - 2, z + 1, soil, 1, 2);
		world.setBlock(x + 6, y - 2, z + 1, soil, 1, 2);
		world.setBlock(x - 6, y - 2, z - 2, soil, 1, 2);
		world.setBlock(x + 6, y - 2, z - 2, soil, 1, 2);
		world.setBlock(x - 6, y - 2, z + 2, soil, 1, 2);
		world.setBlock(x + 6, y - 2, z + 2, soil, 1, 2);
		world.setBlock(x - 6, y - 2, z - 3, soil, 1, 2);
		world.setBlock(x + 6, y - 2, z - 3, soil, 1, 2);
		world.setBlock(x - 6, y - 2, z + 3, soil, 1, 2);
		world.setBlock(x + 6, y - 2, z + 3, soil, 1, 2);
		world.setBlock(x - 6, y - 2, z - 4, soil, 1, 2);
		world.setBlock(x + 6, y - 2, z - 4, soil, 1, 2);
		world.setBlock(x - 6, y - 2, z + 4, soil, 1, 2);
		world.setBlock(x + 6, y - 2, z + 4, soil, 1, 2);
		world.setBlock(x - 6, y - 2, z - 5, soil, 1, 2);
		world.setBlock(x + 6, y - 2, z - 5, soil, 1, 2);
		world.setBlock(x - 6, y - 2, z + 5, soil, 1, 2);
		world.setBlock(x + 6, y - 2, z + 5, soil, 1, 2);
		world.setBlock(x - 6, y - 2, z - 6, soil, 1, 2);
		world.setBlock(x + 6, y - 2, z - 6, soil, 1, 2);
		world.setBlock(x - 6, y - 2, z + 6, soil, 1, 2);
		world.setBlock(x + 6, y - 2, z + 6, soil, 1, 2);
		world.setBlock(x - 6, y - 2, z - 7, soil, 1, 2);
		world.setBlock(x - 6, y - 2, z + 7, soil, 1, 2);
		world.setBlock(x + 6, y - 2, z + 7, soil, 1, 2);
		world.setBlock(x - 6, y - 2, z + 8, soil, 1, 2);
		world.setBlock(x + 6, y - 2, z + 8, soil, 0, 2);
		world.setBlock(x - 6, y - 2, z + 9, soil, 1, 2);
		world.setBlock(x - 6, y - 3, z, soil, 1, 2);
		world.setBlock(x + 6, y - 3, z, soil, 1, 2);
		world.setBlock(x - 6, y - 3, z, soil, 1, 2);
		world.setBlock(x + 6, y - 3, z, soil, 1, 2);
		world.setBlock(x - 6, y - 3, z - 1, soil, 1, 2);
		world.setBlock(x + 6, y - 3, z - 1, soil, 1, 2);
		world.setBlock(x - 6, y - 3, z + 1, soil, 1, 2);
		world.setBlock(x + 6, y - 3, z + 1, soil, 1, 2);
		world.setBlock(x - 6, y - 3, z - 2, soil, 1, 2);
		world.setBlock(x + 6, y - 3, z - 2, soil, 1, 2);
		world.setBlock(x - 6, y - 3, z + 2, soil, 1, 2);
		world.setBlock(x + 6, y - 3, z + 2, soil, 1, 2);
		world.setBlock(x - 6, y - 3, z - 3, soil, 1, 2);
		world.setBlock(x + 6, y - 3, z - 3, soil, 1, 2);
		world.setBlock(x - 6, y - 3, z + 3, soil, 1, 2);
		world.setBlock(x + 6, y - 3, z + 3, soil, 1, 2);
		world.setBlock(x - 6, y - 3, z - 4, soil, 1, 2);
		world.setBlock(x + 6, y - 3, z - 4, soil, 1, 2);
		world.setBlock(x - 6, y - 3, z + 4, soil, 1, 2);
		world.setBlock(x + 6, y - 3, z + 4, soil, 1, 2);
		world.setBlock(x - 6, y - 3, z - 5, soil, 1, 2);
		world.setBlock(x + 6, y - 3, z - 5, soil, 1, 2);
		world.setBlock(x - 6, y - 3, z + 5, soil, 1, 2);
		world.setBlock(x + 6, y - 3, z + 5, soil, 1, 2);
		world.setBlock(x - 6, y - 3, z + 6, soil, 1, 2);
		world.setBlock(x + 6, y - 3, z + 6, soil, 1, 2);
		world.setBlock(x - 6, y - 3, z + 7, soil, 1, 2);
		world.setBlock(x + 6, y - 3, z + 7, soil, 1, 2);
		world.setBlock(x + 6, y - 3, z + 8, soil, 1, 2);
		world.setBlock(x - 6, y - 4, z, soil, 1, 2);
		world.setBlock(x + 6, y - 4, z, soil, 1, 2);
		world.setBlock(x - 6, y - 4, z, soil, 1, 2);
		world.setBlock(x + 6, y - 4, z, soil, 1, 2);
		world.setBlock(x - 6, y - 4, z - 1, soil, 1, 2);
		world.setBlock(x + 6, y - 4, z - 1, soil, 1, 2);
		world.setBlock(x - 6, y - 4, z + 1, soil, 1, 2);
		world.setBlock(x + 6, y - 4, z + 1, soil, 1, 2);
		world.setBlock(x - 6, y - 4, z - 2, soil, 1, 2);
		world.setBlock(x + 6, y - 4, z - 2, soil, 1, 2);
		world.setBlock(x - 6, y - 4, z + 2, soil, 1, 2);
		world.setBlock(x + 6, y - 4, z + 2, soil, 1, 2);
		world.setBlock(x - 6, y - 4, z - 3, soil, 1, 2);
		world.setBlock(x + 6, y - 4, z - 3, soil, 1, 2);
		world.setBlock(x - 6, y - 4, z + 3, soil, 1, 2);
		world.setBlock(x + 6, y - 4, z + 3, soil, 1, 2);
		world.setBlock(x + 6, y - 4, z - 4, soil, 1, 2);
		world.setBlock(x - 6, y - 4, z + 4, soil, 1, 2);
		world.setBlock(x + 6, y - 4, z + 4, soil, 1, 2);
		world.setBlock(x + 6, y - 4, z - 5, soil, 1, 2);
		world.setBlock(x - 6, y - 4, z + 5, soil, 1, 2);
		world.setBlock(x + 6, y - 4, z + 5, soil, 1, 2);
		world.setBlock(x + 6, y - 4, z + 6, soil, 1, 2);
		world.setBlock(x + 6, y - 4, z + 7, soil, 1, 2);
		world.setBlock(x - 6, y - 5, z, soil, 1, 2);
		world.setBlock(x + 6, y - 5, z, soil, 1, 2);
		world.setBlock(x - 6, y - 5, z, soil, 1, 2);
		world.setBlock(x + 6, y - 5, z, soil, 1, 2);
		world.setBlock(x - 6, y - 5, z - 1, soil, 1, 2);
		world.setBlock(x + 6, y - 5, z - 1, soil, 1, 2);
		world.setBlock(x - 6, y - 5, z + 1, soil, 1, 2);
		world.setBlock(x + 6, y - 5, z + 1, soil, 1, 2);
		world.setBlock(x - 6, y - 5, z - 2, soil, 1, 2);
		world.setBlock(x + 6, y - 5, z - 2, soil, 1, 2);
		world.setBlock(x - 6, y - 5, z + 2, soil, 1, 2);
		world.setBlock(x + 6, y - 5, z + 2, soil, 1, 2);
		world.setBlock(x + 6, y - 5, z - 3, soil, 1, 2);
		world.setBlock(x - 6, y - 5, z + 3, soil, 1, 2);
		world.setBlock(x + 6, y - 5, z + 3, soil, 1, 2);
		world.setBlock(x + 6, y - 5, z - 4, soil, 1, 2);
		world.setBlock(x - 6, y - 5, z + 4, soil, 1, 2);
		world.setBlock(x + 6, y - 5, z + 4, soil, 1, 2);
		world.setBlock(x + 6, y - 5, z - 5, soil, 1, 2);
		world.setBlock(x + 6, y - 5, z + 5, soil, 1, 2);
		world.setBlock(x + 6, y - 6, z, soil, 1, 2);
		world.setBlock(x + 6, y - 6, z, soil, 1, 2);
		world.setBlock(x - 6, y - 6, z + 1, soil, 1, 2);
		world.setBlock(x + 6, y - 6, z + 1, soil, 1, 2);
		world.setBlock(x - 6, y - 6, z + 2, soil, 1, 2);
		world.setBlock(x + 6, y - 6, z + 2, soil, 1, 2);
		world.setBlock(x - 6, y - 6, z + 3, soil, 1, 2);
		world.setBlock(x + 6, y - 6, z + 3, soil, 1, 2);
		world.setBlock(x + 6, y - 7, z + 1, soil, 1, 2);
		world.setBlock(x + 6, y - 7, z + 2, soil, 1, 2);
		world.setBlock(x + 6, y - 8, z + 1, soil, 1, 2);
		world.setBlock(x + 6, y - 8, z + 2, soil, 1, 2);
		world.setBlock(x + 7, y, z, soil, 0, 2);
		world.setBlock(x - 7, y, z, soil, 0, 2);
		world.setBlock(x + 7, y, z, soil, 0, 2);
		world.setBlock(x - 7, y, z, soil, 0, 2);
		world.setBlock(x + 7, y, z, soil, 0, 2);
		world.setBlock(x - 7, y, z, soil, 0, 2);
		world.setBlock(x + 7, y, z, soil, 0, 2);
		world.setBlock(x - 7, y, z, soil, 0, 2);
		world.setBlock(x + 7, y, z + 1, soil, 0, 2);
		world.setBlock(x - 7, y, z - 1, soil, 0, 2);
		world.setBlock(x + 7, y, z - 1, soil, 0, 2);
		world.setBlock(x - 7, y, z + 1, soil, 0, 2);
		world.setBlock(x + 7, y, z - 1, soil, 0, 2);
		world.setBlock(x - 7, y, z + 1, soil, 0, 2);
		world.setBlock(x + 7, y, z + 1, soil, 0, 2);
		world.setBlock(x - 7, y, z - 1, soil, 0, 2);
		world.setBlock(x + 7, y, z + 2, soil, 0, 2);
		world.setBlock(x - 7, y, z - 2, soil, 0, 2);
		world.setBlock(x + 7, y, z - 2, soil, 0, 2);
		world.setBlock(x - 7, y, z + 2, soil, 0, 2);
		world.setBlock(x + 7, y, z - 2, soil, 0, 2);
		world.setBlock(x - 7, y, z + 2, soil, 0, 2);
		world.setBlock(x + 7, y, z + 2, soil, 0, 2);
		world.setBlock(x - 7, y, z - 2, soil, 0, 2);
		world.setBlock(x + 7, y, z + 3, soil, 0, 2);
		world.setBlock(x - 7, y, z - 3, soil, 0, 2);
		world.setBlock(x + 7, y, z - 3, soil, 0, 2);
		world.setBlock(x - 7, y, z + 3, soil, 0, 2);
		world.setBlock(x + 7, y, z - 3, soil, 0, 2);
		world.setBlock(x - 7, y, z + 3, soil, 0, 2);
		world.setBlock(x + 7, y, z + 3, soil, 0, 2);
		world.setBlock(x - 7, y, z - 3, soil, 0, 2);
		world.setBlock(x + 7, y, z + 4, soil, 0, 2);
		world.setBlock(x - 7, y, z - 4, soil, 0, 2);
		world.setBlock(x + 7, y, z - 4, soil, 0, 2);
		world.setBlock(x - 7, y, z + 4, soil, 0, 2);
		world.setBlock(x + 7, y, z - 4, soil, 0, 2);
		world.setBlock(x - 7, y, z + 4, soil, 0, 2);
		world.setBlock(x + 7, y, z + 4, soil, 0, 2);
		world.setBlock(x - 7, y, z - 4, soil, 0, 2);
		world.setBlock(x + 7, y, z + 5, soil, 0, 2);
		world.setBlock(x + 7, y, z - 5, soil, 0, 2);
		world.setBlock(x - 7, y, z + 5, soil, 0, 2);
		world.setBlock(x + 7, y, z - 5, soil, 0, 2);
		world.setBlock(x - 7, y, z + 5, soil, 0, 2);
		world.setBlock(x + 7, y, z + 5, soil, 0, 2);
		world.setBlock(x + 7, y, z - 6, soil, 0, 2);
		world.setBlock(x - 7, y, z + 6, soil, 0, 2);
		world.setBlock(x + 7, y, z - 6, soil, 0, 2);
		world.setBlock(x - 7, y, z + 6, soil, 0, 2);
		world.setBlock(x + 7, y, z - 7, soil, 0, 2);
		world.setBlock(x - 7, y, z + 7, soil, 0, 2);
		world.setBlock(x + 7, y, z - 7, soil, 0, 2);
		world.setBlock(x - 7, y, z + 7, soil, 0, 2);
		world.setBlock(x - 7, y, z + 8, soil, 0, 2);
		world.setBlock(x - 7, y, z + 8, soil, 0, 2);
		world.setBlock(x - 7, y - 1, z, soil, 1, 2);
		world.setBlock(x + 7, y - 1, z, soil, 1, 2);
		world.setBlock(x - 7, y - 1, z, soil, 1, 2);
		world.setBlock(x + 7, y - 1, z, soil, 1, 2);
		world.setBlock(x - 7, y - 1, z - 1, soil, 1, 2);
		world.setBlock(x + 7, y - 1, z - 1, soil, 1, 2);
		world.setBlock(x - 7, y - 1, z + 1, soil, 1, 2);
		world.setBlock(x + 7, y - 1, z + 1, soil, 1, 2);
		world.setBlock(x - 7, y - 1, z - 2, soil, 1, 2);
		world.setBlock(x + 7, y - 1, z - 2, soil, 1, 2);
		world.setBlock(x - 7, y - 1, z + 2, soil, 1, 2);
		world.setBlock(x + 7, y - 1, z + 2, soil, 1, 2);
		world.setBlock(x - 7, y - 1, z - 3, soil, 1, 2);
		world.setBlock(x + 7, y - 1, z - 3, soil, 1, 2);
		world.setBlock(x - 7, y - 1, z + 3, soil, 1, 2);
		world.setBlock(x + 7, y - 1, z + 3, soil, 1, 2);
		world.setBlock(x - 7, y - 1, z - 4, soil, 1, 2);
		world.setBlock(x + 7, y - 1, z - 4, soil, 1, 2);
		world.setBlock(x - 7, y - 1, z + 4, soil, 1, 2);
		world.setBlock(x + 7, y - 1, z + 4, soil, 1, 2);
		world.setBlock(x - 7, y - 1, z - 5, soil, 0, 2);
		world.setBlock(x + 7, y - 1, z - 5, soil, 1, 2);
		world.setBlock(x - 7, y - 1, z + 5, soil, 1, 2);
		world.setBlock(x + 7, y - 1, z + 5, soil, 1, 2);
		world.setBlock(x - 7, y - 1, z - 6, soil, 0, 2);
		world.setBlock(x + 7, y - 1, z - 6, soil, 1, 2);
		world.setBlock(x - 7, y - 1, z + 6, soil, 1, 2);
		world.setBlock(x + 7, y - 1, z + 6, soil, 0, 2);
		world.setBlock(x - 7, y - 1, z - 7, soil, 0, 2);
		world.setBlock(x + 7, y - 1, z - 7, soil, 1, 2);
		world.setBlock(x - 7, y - 1, z + 7, soil, 1, 2);
		world.setBlock(x + 7, y - 1, z + 7, soil, 0, 2);
		world.setBlock(x - 7, y - 1, z + 8, soil, 1, 2);
		world.setBlock(x - 7, y - 2, z, soil, 1, 2);
		world.setBlock(x + 7, y - 2, z, soil, 1, 2);
		world.setBlock(x - 7, y - 2, z, soil, 1, 2);
		world.setBlock(x + 7, y - 2, z, soil, 1, 2);
		world.setBlock(x - 7, y - 2, z - 1, soil, 1, 2);
		world.setBlock(x + 7, y - 2, z - 1, soil, 1, 2);
		world.setBlock(x - 7, y - 2, z + 1, soil, 1, 2);
		world.setBlock(x + 7, y - 2, z + 1, soil, 1, 2);
		world.setBlock(x - 7, y - 2, z - 2, soil, 1, 2);
		world.setBlock(x + 7, y - 2, z - 2, soil, 1, 2);
		world.setBlock(x - 7, y - 2, z + 2, soil, 1, 2);
		world.setBlock(x + 7, y - 2, z + 2, soil, 1, 2);
		world.setBlock(x - 7, y - 2, z - 3, soil, 1, 2);
		world.setBlock(x + 7, y - 2, z - 3, soil, 1, 2);
		world.setBlock(x - 7, y - 2, z + 3, soil, 1, 2);
		world.setBlock(x + 7, y - 2, z + 3, soil, 1, 2);
		world.setBlock(x - 7, y - 2, z - 4, soil, 1, 2);
		world.setBlock(x + 7, y - 2, z - 4, soil, 1, 2);
		world.setBlock(x - 7, y - 2, z + 4, soil, 1, 2);
		world.setBlock(x + 7, y - 2, z + 4, soil, 1, 2);
		world.setBlock(x - 7, y - 2, z - 5, soil, 1, 2);
		world.setBlock(x + 7, y - 2, z - 5, soil, 1, 2);
		world.setBlock(x - 7, y - 2, z + 5, soil, 1, 2);
		world.setBlock(x + 7, y - 2, z + 5, soil, 1, 2);
		world.setBlock(x - 7, y - 2, z - 6, soil, 1, 2);
		world.setBlock(x + 7, y - 2, z - 6, soil, 1, 2);
		world.setBlock(x - 7, y - 2, z + 6, soil, 1, 2);
		world.setBlock(x + 7, y - 2, z + 6, soil, 1, 2);
		world.setBlock(x - 7, y - 2, z + 7, soil, 1, 2);
		world.setBlock(x + 7, y - 2, z + 7, soil, 1, 2);
		world.setBlock(x - 7, y - 2, z + 8, soil, 1, 2);
		world.setBlock(x - 7, y - 3, z, soil, 1, 2);
		world.setBlock(x + 7, y - 3, z, soil, 1, 2);
		world.setBlock(x - 7, y - 3, z, soil, 1, 2);
		world.setBlock(x + 7, y - 3, z, soil, 1, 2);
		world.setBlock(x - 7, y - 3, z - 1, soil, 1, 2);
		world.setBlock(x + 7, y - 3, z - 1, soil, 1, 2);
		world.setBlock(x - 7, y - 3, z + 1, soil, 1, 2);
		world.setBlock(x + 7, y - 3, z + 1, soil, 1, 2);
		world.setBlock(x - 7, y - 3, z - 2, soil, 1, 2);
		world.setBlock(x + 7, y - 3, z - 2, soil, 1, 2);
		world.setBlock(x - 7, y - 3, z + 2, soil, 1, 2);
		world.setBlock(x + 7, y - 3, z + 2, soil, 1, 2);
		world.setBlock(x - 7, y - 3, z - 3, soil, 1, 2);
		world.setBlock(x + 7, y - 3, z - 3, soil, 1, 2);
		world.setBlock(x - 7, y - 3, z + 3, soil, 1, 2);
		world.setBlock(x + 7, y - 3, z + 3, soil, 1, 2);
		world.setBlock(x + 7, y - 3, z - 4, soil, 1, 2);
		world.setBlock(x - 7, y - 3, z + 4, soil, 1, 2);
		world.setBlock(x + 7, y - 3, z + 4, soil, 1, 2);
		world.setBlock(x + 7, y - 3, z - 5, soil, 1, 2);
		world.setBlock(x - 7, y - 3, z + 5, soil, 1, 2);
		world.setBlock(x + 7, y - 3, z + 5, soil, 1, 2);
		world.setBlock(x - 7, y - 3, z + 6, soil, 1, 2);
		world.setBlock(x + 7, y - 3, z + 6, soil, 1, 2);
		world.setBlock(x - 7, y - 3, z + 7, soil, 1, 2);
		world.setBlock(x + 7, y - 3, z + 7, soil, 1, 2);
		world.setBlock(x - 7, y - 4, z, soil, 1, 2);
		world.setBlock(x + 7, y - 4, z, soil, 1, 2);
		world.setBlock(x - 7, y - 4, z, soil, 1, 2);
		world.setBlock(x + 7, y - 4, z, soil, 1, 2);
		world.setBlock(x - 7, y - 4, z - 1, soil, 1, 2);
		world.setBlock(x + 7, y - 4, z - 1, soil, 1, 2);
		world.setBlock(x - 7, y - 4, z + 1, soil, 1, 2);
		world.setBlock(x + 7, y - 4, z + 1, soil, 1, 2);
		world.setBlock(x - 7, y - 4, z - 2, soil, 1, 2);
		world.setBlock(x + 7, y - 4, z - 2, soil, 1, 2);
		world.setBlock(x - 7, y - 4, z + 2, soil, 1, 2);
		world.setBlock(x + 7, y - 4, z + 2, soil, 1, 2);
		world.setBlock(x - 7, y - 4, z - 3, soil, 1, 2);
		world.setBlock(x + 7, y - 4, z - 3, soil, 1, 2);
		world.setBlock(x - 7, y - 4, z + 3, soil, 1, 2);
		world.setBlock(x + 7, y - 4, z + 3, soil, 1, 2);
		world.setBlock(x + 7, y - 4, z - 4, soil, 1, 2);
		world.setBlock(x - 7, y - 4, z + 4, soil, 1, 2);
		world.setBlock(x + 7, y - 4, z + 4, soil, 1, 2);
		world.setBlock(x - 7, y - 4, z + 5, soil, 1, 2);
		world.setBlock(x + 7, y - 4, z + 5, soil, 1, 2);
		world.setBlock(x - 7, y - 5, z, soil, 1, 2);
		world.setBlock(x + 7, y - 5, z, soil, 1, 2);
		world.setBlock(x - 7, y - 5, z, soil, 1, 2);
		world.setBlock(x + 7, y - 5, z, soil, 1, 2);
		world.setBlock(x + 7, y - 5, z - 1, soil, 1, 2);
		world.setBlock(x - 7, y - 5, z + 1, soil, 1, 2);
		world.setBlock(x + 7, y - 5, z + 1, soil, 1, 2);
		world.setBlock(x + 7, y - 5, z - 2, soil, 1, 2);
		world.setBlock(x - 7, y - 5, z + 2, soil, 1, 2);
		world.setBlock(x + 7, y - 5, z + 2, soil, 1, 2);
		world.setBlock(x + 7, y - 5, z - 3, soil, 1, 2);
		world.setBlock(x - 7, y - 5, z + 3, soil, 1, 2);
		world.setBlock(x + 7, y - 5, z + 3, soil, 1, 2);
		world.setBlock(x - 7, y - 5, z + 4, soil, 1, 2);
		world.setBlock(x + 7, y - 5, z + 4, soil, 1, 2);
		world.setBlock(x + 7, y - 5, z + 5, soil, 1, 2);
		world.setBlock(x + 7, y - 6, z, soil, 1, 2);
		world.setBlock(x + 7, y - 6, z, soil, 1, 2);
		world.setBlock(x - 7, y - 6, z + 1, soil, 1, 2);
		world.setBlock(x + 7, y - 6, z + 1, soil, 1, 2);
		world.setBlock(x - 7, y - 6, z + 2, soil, 1, 2);
		world.setBlock(x + 7, y - 6, z + 2, soil, 1, 2);
		world.setBlock(x - 7, y - 6, z + 3, soil, 1, 2);
		world.setBlock(x + 7, y - 6, z + 3, soil, 1, 2);
		world.setBlock(x + 7, y - 7, z + 1, soil, 1, 2);
		world.setBlock(x + 7, y - 7, z + 2, soil, 1, 2);
		world.setBlock(x + 7, y - 8, z + 1, soil, 1, 2);
		world.setBlock(x + 7, y - 8, z + 2, soil, 1, 2);
		world.setBlock(x + 8, y, z, soil, 0, 2);
		world.setBlock(x - 8, y, z, soil, 0, 2);
		world.setBlock(x + 8, y, z, soil, 0, 2);
		world.setBlock(x - 8, y, z, soil, 0, 2);
		world.setBlock(x + 8, y, z, soil, 0, 2);
		world.setBlock(x - 8, y, z, soil, 0, 2);
		world.setBlock(x + 8, y, z, soil, 0, 2);
		world.setBlock(x - 8, y, z, soil, 0, 2);
		world.setBlock(x + 8, y, z + 1, soil, 0, 2);
		world.setBlock(x - 8, y, z - 1, soil, 0, 2);
		world.setBlock(x + 8, y, z - 1, soil, 0, 2);
		world.setBlock(x - 8, y, z + 1, soil, 0, 2);
		world.setBlock(x + 8, y, z - 1, soil, 0, 2);
		world.setBlock(x - 8, y, z + 1, soil, 0, 2);
		world.setBlock(x + 8, y, z + 1, soil, 0, 2);
		world.setBlock(x - 8, y, z - 1, soil, 0, 2);
		world.setBlock(x + 8, y, z + 2, soil, 0, 2);
		world.setBlock(x - 8, y, z - 2, soil, 0, 2);
		world.setBlock(x + 8, y, z - 2, soil, 0, 2);
		world.setBlock(x - 8, y, z + 2, soil, 0, 2);
		world.setBlock(x + 8, y, z - 2, soil, 0, 2);
		world.setBlock(x - 8, y, z + 2, soil, 0, 2);
		world.setBlock(x + 8, y, z + 2, soil, 0, 2);
		world.setBlock(x - 8, y, z - 2, soil, 0, 2);
		world.setBlock(x + 8, y, z + 3, soil, 0, 2);
